Workbook

Sheet README
A1: PATENT PORTFOLIO BUNDLING TEMPLATE
A2: A technical-attribute-based framework for grouping patents into sellable bundles
A4: PURPOSE
A5: Score each patent across technical attributes, then auto-route patents into one or more sellable bundle types based on logical rules. The framework is purely technical — no valuation, no pricing.
A7: SHEETS IN THIS WORKBOOK
A8: 1. README — This page. Overview and instructions.
A9: 2. Attribute Dictionary — Definitions and scoring scales for every attribute.
A10: 3. Patent Portfolio — Master data sheet. One row per patent. Fill this in.
A11: 4. Bundle Rules — The 21 bundle types and the routing rule that qualifies a patent for each.
A12: 5. Bundle Assignment — Auto-computed: which bundles each patent qualifies for.
A13: 6. Bundle Quality Scorecard — Auto-computed: quality indicators per bundle.
A14: 7. Sample Bundles — Worked examples showing how three bundles look in practice.
... A61: Use this sheet as the long-form reference. Keep using the Attribute Dictionary for quick scale/values lookups while entering data on the Patent Portfolio sheet.

Sheet Configuration
A1: CONFIGURATION
A2: Pick a preset, or switch to Edit Mode to override individual values. All Bundle Assignment and Scorecard formulas read from this sheet.
A4: Active Preset: | B4: All ON (default) | E4: ← Pick from Presets sheet. Changing this updates all Active Values below.
A5: Edit Mode: | B5: No | E5: ← Yes = use Manual Override column. No = use selected preset.
A6: Summary: | B6: ="Bundles active: "&COUNTIF(C10:C42,"Yes")&" of 33 | Gates active: "&COUNTIF(C63:C67,"Yes")&" of 5 | "&IF($B$5="Yes","EDIT MODE — using Manual Override values","Using preset: "&$B$4) -> Bundles active: 33 of 33 | Gates active: 5 of 5 | Using preset: All ON (default)
A8: Parameter | B8: Description | C8: Active Value (use this in formulas) | D8: From Preset | E8: Manual Override
A9: BUNDLE TOGGLES (Yes = bundle is active in this analysis)
A10: B1_enabled | B10: Bundle 1 — Tech Domain | C10: =IF($B$5="Yes",E10,D10) -> Yes | D10: =INDEX(Presets!$C$4:$L$4,MATCH($B$4,Presets!$C$1:$L$1,0)) -> Yes | E10: Yes
A11: B2_enabled | B11: Bundle 2 — SEP | C11: =IF($B$5="Yes",E11,D11) -> Yes | D11: =INDEX(Presets!$C$5:$L$5,MATCH($B$4,Presets!$C$1:$L$1,0)) -> Yes | E11: Yes
A12: B3_enabled | B12: Bundle 3 — Product Architecture | C12: =IF($B$5="Yes",E12,D12) -> Yes | D12: =INDEX(Presets!$C$6:$L$6,MATCH($B$4,Presets!$C$1:$L$1,0)) -> Yes | E12: Yes
A13: B4_enabled | B13: Bundle 4 — Stack Layer | C13: =IF($B$5="Yes",E13,D13) -> Yes | D13: =INDEX(Presets!$C$7:$L$7,MATCH($B$4,Presets!$C$1:$L$1,0)) -> Yes | E13: Yes
A14: B5_enabled | B14: Bundle 5 — Use-Case | C14: =IF($B$5="Yes",E14,D14) -> Yes | D14: =INDEX(Presets!$C$8:$L$8,MATCH($B$4,Presets!$C$1:$L$1,0)) -> Yes | E14: Yes
A15: B6_enabled | B15: Bundle 6 — Manufacturing / Process | C15: =IF($B$5="Yes",E15,D15) -> Yes | D15: =INDEX(Presets!$C$9:$L$9,MATCH($B$4,Presets!$C$1:$L$1,0)) -> Yes | E15: Yes
A16: B7_enabled | B16: Bundle 7 — Materials & Chemistry | C16: =IF($B$5="Yes",E16,D16) -> Yes | D16: =INDEX(Presets!$C$10:$L$10,MATCH($B$4,Presets!$C$1:$L$1,0)) -> Yes | E16: Yes
A17: B8_enabled | B17: Bundle 8 — Algorithm / Software | C17: =IF($B$5="Yes",E17,D17) -> Yes | D17: =INDEX(Presets!$C$11:$L$11,MATCH($B$4,Presets!$C$1:$L$1,0)) -> Yes | E17: Yes
A18: B9_enabled | B18: Bundle 9 — Interoperability | C18: =IF($B$5="Yes",E18,D18) -> Yes | D18: =INDEX(Presets!$C$12:$L$12,MATCH($B$4,Presets!$C$1:$L$1,0)) -> Yes | E18: Yes
A19: B10_enabled | B19: Bundle 10 — Generational Roadmap | C19: =IF($B$5="Yes",E19,D19) -> Yes | D19: =INDEX(Presets!$C$13:$L$13,MATCH($B$4,Presets!$C$1:$L$1,0)) -> Yes | E19: Yes
A20: B11_enabled | B20: Bundle 11 — Claim-Type | C20: =IF($B$5="Yes",E20,D20) -> Yes | D20: =INDEX(Presets!$C$14:$L$14,MATCH($B$4,Presets!$C$1:$L$1,0)) -> Yes | E20: Yes
A21: B12_enabled | B21: Bundle 12 — Detectability | C21: =IF($B$5="Yes",E21,D21) -> Yes | D21: =INDEX(Presets!$C$15:$L$15,MATCH($B$4,Presets!$C$1:$L$1,0)) -> Yes | E21: Yes
A22: B13_enabled | B22: Bundle 13 — Geographic | C22: =IF($B$5="Yes",E22,D22) -> Yes | D22: =INDEX(Presets!$C$16:$L$16,MATCH($B$4,Presets!$C$1:$L$1,0)) -> Yes | E22: Yes
A23: B14_enabled | B23: Bundle 14 — Family-Tree | C23: =IF($B$5="Yes",E23,D23) -> Yes | D23: =INDEX(Presets!$C$17:$L$17,MATCH($B$4,Presets!$C$1:$L$1,0)) -> Yes | E23: Yes
A24: B15_enabled | B24: Bundle 15 — Lifecycle / Term | C24: =IF($B$5="Yes",E24,D24) -> Yes | D24: =INDEX(Presets!$C$18:$L$18,MATCH($B$4,Presets!$C$1:$L$1,0)) -> Yes | E24: Yes
A25: B16_enabled | B25: Bundle 16 — Foundational + Improvement | C25: =IF($B$5="Yes",E25,D25) -> Yes | D25: =INDEX(Presets!$C$19:$L$19,MATCH($B$4,Presets!$C$1:$L$1,0)) -> Yes | E25: Yes
A26: B17_enabled | B26: Bundle 17 — Cross-Industry | C26: =IF($B$5="Yes",E26,D26) -> Yes | D26: =INDEX(Presets!$C$20:$L$20,MATCH($B$4,Presets!$C$1:$L$1,0)) -> Yes | E26: Yes
A27: B18_enabled | B27: Bundle 18 — Convergent Theme | C27: =IF($B$5="Yes",E27,D27) -> Yes | D27: =INDEX(Presets!$C$21:$L$21,MATCH($B$4,Presets!$C$1:$L$1,0)) -> Yes | E27: Yes
A28: B19_enabled | B28: Bundle 19 — Defensive / Counter-Assert. | C28: =IF($B$5="Yes",E28,D28) -> Yes | D28: =INDEX(Presets!$C$22:$L$22,MATCH($B$4,Presets!$C$1:$L$1,0)) -> Yes | E28: Yes
A29: B20_enabled | B29: Bundle 20 — Whitespace / Design-Around | C29: =IF($B$5="Yes",E29,D29) -> Yes | D29: =INDEX(Presets!$C$23:$L$23,MATCH($B$4,Presets!$C$1:$L$1,0)) -> Yes | E29: Yes
A30: B21_enabled | B30: Bundle 21 — Prosecution-Status | C30: =IF($B$5="Yes",E30,D30) -> Yes | D30: =INDEX(Presets!$C$24:$L$24,MATCH($B$4,Presets!$C$1:$L$1,0)) -> Yes | E30: Yes
A31: B22_enabled | B31: Bundle 22 — Anchor-and-Halo | C31: =IF($B$5="Yes",E31,D31) -> Yes | D31: =INDEX(Presets!$C$25:$L$25,MATCH($B$4,Presets!$C$1:$L$1,0)) -> Yes | E31: Yes
A32: B23_enabled | B32: Bundle 23 — Picket-Fence | C32: =IF($B$5="Yes",E32,D32) -> Yes | D32: =INDEX(Presets!$C$26:$L$26,MATCH($B$4,Presets!$C$1:$L$1,0)) -> Yes | E32: Yes
A33: B24_enabled | B33: Bundle 24 — Strong-Core + Tail | C33: =IF($B$5="Yes",E33,D33) -> Yes | D33: =INDEX(Presets!$C$27:$L$27,MATCH($B$4,Presets!$C$1:$L$1,0)) -> Yes | E33: Yes
A34: B25_enabled | B34: Bundle 25 — Continuation-Live | C34: =IF($B$5="Yes",E34,D34) -> Yes | D34: =INDEX(Presets!$C$28:$L$28,MATCH($B$4,Presets!$C$1:$L$1,0)) -> Yes | E34: Yes
A35: B26_enabled | B35: Bundle 26 — EoU-Backed | C35: =IF($B$5="Yes",E35,D35) -> Yes | D35: =INDEX(Presets!$C$29:$L$29,MATCH($B$4,Presets!$C$1:$L$1,0)) -> Yes | E35: Yes
A36: B27_enabled | B36: Bundle 27 — Battle-Tested | C36: =IF($B$5="Yes",E36,D36) -> Yes | D36: =INDEX(Presets!$C$30:$L$30,MATCH($B$4,Presets!$C$1:$L$1,0)) -> Yes | E36: Yes
A37: B28_enabled | B37: Bundle 28 — Clean-Title | C37: =IF($B$5="Yes",E37,D37) -> Yes | D37: =INDEX(Presets!$C$31:$L$31,MATCH($B$4,Presets!$C$1:$L$1,0)) -> Yes | E37: Yes
A38: B29_enabled | B38: Bundle 29 — High-Citation | C38: =IF($B$5="Yes",E38,D38) -> Yes | D38: =INDEX(Presets!$C$32:$L$32,MATCH($B$4,Presets!$C$1:$L$1,0)) -> Yes | E38: Yes
A39: B30_enabled | B39: Bundle 30 — Adjacent Re-Read | C39: =IF($B$5="Yes",E39,D39) -> Yes | D39: =INDEX(Presets!$C$33:$L$33,MATCH($B$4,Presets!$C$1:$L$1,0)) -> Yes | E39: Yes
A40: B31_enabled | B40: Bundle 31 — Salvage / Volume Lot | C40: =IF($B$5="Yes",E40,D40) -> Yes | D40: =INDEX(Presets!$C$34:$L$34,MATCH($B$4,Presets!$C$1:$L$1,0)) -> Yes | E40: Yes
A41: B32_enabled | B41: Bundle 32 — Pre-Expiry | C41: =IF($B$5="Yes",E41,D41) -> Yes | D41: =INDEX(Presets!$C$35:$L$35,MATCH($B$4,Presets!$C$1:$L$1,0)) -> Yes | E41: Yes
A42: B33_enabled | B42: Bundle 33 — Provenance-Coherent | C42: =IF($B$5="Yes",E42,D42) -> Yes | D42: =INDEX(Presets!$C$36:$L$36,MATCH($B$4,Presets!$C$1:$L$1,0)) -> Yes | E42: Yes
...

Sheet Presets
A1: Parameter | B1: Description | C1: All ON (default) | D1: NPE / Counter-Assertion | E1: Operating Company / FTO | F1: Defensive Aggregator | G1: Standards Licensee | H1: EV Powertrain Sale | I1: Custom Preset 1 | J1: Custom Preset 2 | K1: Custom Preset 3 | L1: Custom Preset 4
A2: _description | B2: Short description of the preset | C2: Every bundle and gate enabled, all thresholds at default. Baseline view. | D2: Focus on assertion-ready assets: detectability, EoU, survived challenges, defensive reads, salvage lots. | E2: Focus on subsystem coverage, interfaces, claim breadth, continuation optionality. Skips litigation-focused bundles. | F2: Volume-driven: salvage, geographic breadth, claim-type variety, prosecution mix. | G2: Tight focus on standards-essential, interoperability, generational, geographic, battle-tested assets. | H2: EV-focused: subsystems, materials, manufacturing, thermal, generational. Skips wireless/SEP/AI bundles. | I2: (empty — overwrite this column with your own configuration) | J2: (empty — overwrite this column with your own configuration) | K2: (empty — overwrite this column with your own configuration) | L2: (empty — overwrite this column with your own configuration)
A3: BUNDLE TOGGLES (Yes = enabled, No = disabled)
A4: B1_enabled | B4: Bundle 1 — Tech Domain | C4: Yes | D4: No | E4: Yes | F4: Yes | G4: No | H4: Yes | I4: Yes | J4: Yes | K4: Yes | L4: Yes
A5: B2_enabled | B5: Bundle 2 — SEP | C5: Yes | D5: Yes | E5: No | F5: No | G5: Yes | H5: No | I5: Yes | J5: Yes | K5: Yes | L5: Yes
A6: B3_enabled | B6: Bundle 3 — Product Architecture | C6: Yes | D6: No | E6: Yes | F6: No | G6: No | H6: Yes | I6: Yes | J6: Yes | K6: Yes | L6: Yes
A7: B4_enabled | B7: Bundle 4 — Stack Layer | C7: Yes | D7: No | E7: Yes | F7: Yes | G7: No | H7: Yes | I7: Yes | J7: Yes | K7: Yes | L7: Yes
A8: B5_enabled | B8: Bundle 5 — Use-Case | C8: Yes | D8: Yes | E8: Yes | F8: No | G8: No | H8: Yes | I8: Yes | J8: Yes | K8: Yes | L8: Yes
A9: B6_enabled | B9: Bundle 6 — Manufacturing / Process | C9: Yes | D9: No | E9: Yes | F9: No | G9: No | H9: Yes | I9: Yes | J9: Yes | K9: Yes | L9: Yes
A10: B7_enabled | B10: Bundle 7 — Materials & Chemistry | C10: Yes | D10: No | E10: Yes | F10: No | G10: No | H10: Yes | I10: Yes | J10: Yes | K10: Yes | L10: Yes
A11: B8_enabled | B11: Bundle 8 — Algorithm / Software | C11: Yes | D11: No | E11: Yes | F11: No | G11: No | H11: No | I11: Yes | J11: Yes | K11: Yes | L11: Yes
A12: B9_enabled | B12: Bundle 9 — Interoperability | C12: Yes | D12: Yes | E12: Yes | F12: No | G12: Yes | H12: No | I12: Yes | J12: Yes | K12: Yes | L12: Yes
A13: B10_enabled | B13: Bundle 10 — Generational Roadmap | C13: Yes | D13: No | E13: No | F13: Yes | G13: Yes | H13: Yes | I13: Yes | J13: Yes | K13: Yes | L13: Yes
A14: B11_enabled | B14: Bundle 11 — Claim-Type | C14: Yes | D14: Yes | E14: No | F14: Yes | G14: No | H14: No | I14: Yes | J14: Yes | K14: Yes | L14: Yes
A15: B12_enabled | B15: Bundle 12 — Detectability | C15: Yes | D15: Yes | E15: No | F15: No | G15: Yes | H15: No | I15: Yes | J15: Yes | K15: Yes | L15: Yes
... A36: B33_enabled | B36: Bundle 33 — Provenance-Coherent | C36: Yes | D36: No | E36: Yes | F36: No | G36: No | H36: Yes | I36: Yes | J36: Yes | K36: Yes | L36: Yes
A37: THRESHOLDS (numeric values used in routing rules)
A38: SEP_B1_cutoff | B38: B2 SEP bundle: minimum B1 SEP potential (default 2) | C38: 2 | D38: 2 | E38: 2 | F38: 2 | G38: 2 | H38: 2 | I38: 2 | J38: 2 | K38: 2 | L38: 2
A39: Interface_B3_cutoff | B39: B9 Interop bundle: minimum B3 interface role (default 2) | C39: 2 | D39: 2 | E39: 2 | F39: 2 | G39: 2 | H39: 2 | I39: 2 | J39: 2 | K39: 2 | L39: 2
A40: Detect_D1_cutoff | B40: B12 Detectability: D1 external-detect cutoff (default 2) | C40: 2 | D40: 2 | E40: 2 | F40: 2 | G40: 2 | H40: 2 | I40: 2 | J40: 2 | K40: 2 | L40: 2
A41: Detect_D2_cutoff | B41: B12 Detectability: D2 teardown cutoff (default 2) | C41: 2 | D41: 2 | E41: 2 | F41: 2 | G41: 2 | H41: 2 | I41: 2 | J41: 2 | K41: 2 | L41: 2
A42: Family_E1_min | B42: B14 Family bundle: minimum E1 family size (default 2) | C42: 2 | D42: 2 | E42: 3 | F42: 2 | G42: 2 | H42: 2 | I42: 2 | J42: 2 | K42: 2 | L42: 2
A43: CrossIndustry_G3_cutoff | B43: B17 Cross-Industry: minimum G3 cross-industry score (default 2) | C43: 2 | D43: 2 | E43: 2 | F43: 2 | G43: 2 | H43: 2 | I43: 2 | J43: 2 | K43: 2 | L43: 2
A44: Defensive_D3_cutoff | B44: B19 Defensive: minimum D3 reads-on-products (default 2) | C44: 2 | D44: 2 | E44: 2 | F44: 2 | G44: 2 | H44: 2 | I44: 2 | J44: 2 | K44: 2 | L44: 2
A45: Whitespace_C4_cutoff | B45: B20 Whitespace: minimum C4 design-around difficulty (default 2) | C45: 2 | D45: 2 | E45: 2 | F45: 2 | G45: 2 | H45: 2 | I45: 2 | J45: 2 | K45: 2 | L45: 2
A46: Anchor_H1_cutoff | B46: B22 Anchor+Halo: minimum H1 claim strength for anchor (default 2) | C46: 2 | D46: 2 | E46: 2 | F46: 2 | G46: 2 | H46: 2 | I46: 2 | J46: 2 | K46: 2 | L46: 2
A47: HighCitation_H5_min | B47: B29 High-Citation: minimum H5 forward citations (default 15) | C47: 15 | D47: 10 | E47: 15 | F47: 15 | G47: 15 | H47: 15 | I47: 15 | J47: 15 | K47: 15 | L47: 15
A48: PreExpiry_min_years | B48: B32 Pre-Expiry: minimum remaining term in years (default 1) | C48: 1 | D48: 1 | E48: 1 | F48: 1 | G48: 1 | H48: 1 | I48: 1 | J48: 1 | K48: 1 | L48: 1
A49: PreExpiry_max_years | B49: B32 Pre-Expiry: maximum remaining term in years (default 4) | C49: 4 | D49: 4 | E49: 4 | F49: 4 | G49: 4 | H49: 4 | I49: 4 | J49: 4 | K49: 4 | L49: 4
... A55: Strength_term_min | B55: Scorecard STRONG flag: minimum avg remaining term (default 10) | C55: 10 | D55: 10 | E55: 10 | F55: 10 | G55: 10 | H55: 10 | I55: 10 | J55: 10 | K55: 10 | L55: 10
A56: QUALITY GATES (Yes = column shown on Scorecard, No = column blanked)
A57: Gate_WeakestH1 | B57: Show "Weakest H1 in bundle" column | C57: Yes | D57: Yes | E57: Yes | F57: No | G57: Yes | H57: Yes | I57: Yes | J57: Yes | K57: Yes | L57: Yes
A58: Gate_InvalidityExposure | B58: Show "Invalidity exposure %" column | C58: Yes | D58: Yes | E58: Yes | F58: Yes | G58: Yes | H58: Yes | I58: Yes | J58: Yes | K58: Yes | L58: Yes
A59: Gate_EoUReady | B59: Show "EoU-ready %" column | C59: Yes | D59: Yes | E59: No | F59: No | G59: Yes | H59: No | I59: Yes | J59: Yes | K59: Yes | L59: Yes
A60: Gate_Survived | B60: Show "Survived %" column | C60: Yes | D60: Yes | E60: No | F60: No | G60: Yes | H60: No | I60: Yes | J60: Yes | K60: Yes | L60: Yes
A61: Gate_ContOptionality | B61: Show "Continuation-optionality %" column | C61: Yes | D61: No | E61: Yes | F61: No | G61: Yes | H61: Yes | I61: Yes | J61: Yes | K61: Yes | L61: Yes
A64: HOW TO USE THE PRESETS SHEET
A65: • The "Active Preset" dropdown on the Configuration sheet picks one column from this sheet.
A66: • Columns C-H are starter presets — useful as-is or as templates.
A67: • Columns I-L are empty "Custom Preset" slots — overwrite their values to define your own.
...

Sheet Attribute Dictionary
A1: Group | B1: Code | C1: Attribute | D1: Description | E1: Scale / Values | F1: Example
A2: A. Technology Classification | B2: A1 | C2: Primary technology domain | D2: Main CPC/IPC classification or internal taxonomy tag. | E2: Categorical text | F2: Wireless PHY
A3: A. Technology Classification | B3: A2 | C3: Secondary domains | D3: Cross-applicable technical areas the patent also touches. | E3: Comma-separated tags | F3: Beamforming, MIMO
A4: A. Technology Classification | B4: A3 | C4: Stack layer | D4: Horizontal layer of the technology stack. | E4: Hardware / Firmware / OS / Middleware / App / Cloud / UI | F4: Hardware
A5: A. Technology Classification | B5: A4 | C5: Product subsystem | D5: Which subsystem(s) of an end-product it covers. | E5: Free-text / list | F5: Battery management
A6: A. Technology Classification | B6: A5 | C6: Use-case | D6: Real-world problem(s) it solves. | E6: Free-text / list | F6: Indoor positioning
A7: B. Standards & Ecosystem | B7: B1 | C7: SEP potential | D7: Standard-essential potential. | E7: 0 (none) → 3 (declared/strong mapping) | F7: 3
A8: B. Standards & Ecosystem | B8: B2 | C8: Standard tagged | D8: Specific standard(s) the patent maps to. | E8: Categorical text | F8: 3GPP 5G NR
A9: B. Standards & Ecosystem | B9: B3 | C9: Interface role | D9: Role as an interoperability/interface technology. | E9: 0 (internal only) → 3 (mandatory interface) | F9: 2
A10: C. Claim & Scope | B10: C1 | C10: Claim type | D10: Dominant claim type. | E10: Apparatus / Method / System / CRM / Design | F10: Method
A11: C. Claim & Scope | B11: C2 | C11: Claim breadth | D11: How broad/foundational the independent claims are. | E11: 0 (narrow) → 3 (foundational/pioneer) | F11: 2
A12: C. Claim & Scope | B12: C3 | C12: Independent claim count | D12: Number of independent claims. | E12: Integer | F12: 3
... A41: I. Market/Buyer Signals | B41: I4 | C41: Workaround complexity | D41: Engineering effort needed for a competitor to design around the claims. | E41: 0 (trivial) → 3 (deep redesign) | F41: 3

Sheet Attribute Procedure
A1: ATTRIBUTE DERIVATION PROCEDURE
A2: A field-by-field procedure for populating the 40-attribute scoring model from raw patent data. Sits alongside the Attribute Dictionary as the long-form reference.
A3: TYPE LEGEND
A4: Direct lookup | B4: Pull the value straight from a patent document field or database; no judgment required.
A5: Computed | B5: Apply an arithmetic formula or boolean rule to other already-collected fields.
A6: Derived (rubric) | B6: Apply a scoring rubric to claim text or specification language. Requires reading and judgment.
A7: Derived (rubric + SME) | B7: Rubric-based but should be cross-checked with a domain expert or patent counsel.
A9: RECOMMENDED WORKFLOW — 10 steps (run in order; steps 1-3 mostly automatable, steps 4-10 require reading & judgment)
A10: # | B10: Step | C10: What to do | F10: Fields populated
A11: 1 | B11: Pull bibliographic & family data | C11: For each patent: get the front page, claims, abstract, family tree, citations, assignments, and prosecution status. Use Google Patents + Espacenet + USPTO Patent Center. | F11: A1, A2, C1, C3, E1–E5, F1, H5, H6, H8
A12: 2 | B12: Read claims and specification | C12: Read the first independent claim of each patent + the Background / Field-of-Invention. This is the irreplaceable manual step. | F12: A3, A4, A5, C2, C4, B3
A13: 3 | B13: Check SEP declarations | C13: For wireless / video / connectivity patents: check ETSI IPR, IEEE-SA, ITU declarations against the family. | F13: B1, B2
A14: 4 | B14: Score detectability | C14: For each claim, judge external vs. teardown detectability with the rubric. Cross-check teardowns where available. | F14: D1, D2
A15: 5 | B15: Map to products | C15: Identify which commercial products read on each patent. Build a quick read-on list. This is the highest-leverage step for buyer value. | F15: D3, I1
A16: 6 | B16: Compute geography | C16: From the family list, derive trilateral flag and major-market score. | F16: F2, F3 (auto from F1)
A17: 7 | B17: Tag themes and generations | C17: Apply your convergence-theme dictionary and generation labels. | F17: G1, G2, G3
A18: 8 | B18: Quality & vulnerability review | C18: Patent-counsel-grade review: claim strength, prior-art exposure, prosecution estoppel, divided-infringement, litigation history. Most labor-intensive but most decisive for buyer due diligence. | F18: H1, H2, H3, H4, H7
A19: 9 | B19: EoU & encumbrance audit | C19: Check internal claim-chart library; check encumbrance records. | F19: H9, H10
A20: 10 | B20: Market signals review | C20: Implementation maturity (was it productized?), adjacent re-read potential, workaround complexity. SME-driven. | F20: I2, I3, I4
A23: MASTER ATTRIBUTE PROCEDURE TABLE — one row per attribute (40 attributes total)
A24: Grp | B24: Code | C24: Attribute | D24: Type | E24: Where to find | F24: How to derive / compute | G24: Best data source
A25: A | B25: A1 | C25: Primary technology domain | D25: Direct lookup | E25: Front page of the patent: CPC main classification (most specific subgroup), or IPC. Also check the title and abstract for confirmation. | F25: Take the CPC main code and translate it to a human-readable domain tag using a fixed taxonomy (e.g., CPC H04W → "Wireless networking"; CPC H01M → "Battery cells"). Maintain a CPC→tag mapping spreadsheet so values stay consistent across the portfolio. | G25: Google Patents, USPTO PatentsView, Espacenet, EPO Open Patent Services, Lens.org. CPC scheme reference: cpc.uspto.gov
A26: A | B26: A2 | C26: Secondary domains | D26: Direct lookup | E26: CPC classifications other than the main one (front page lists multiple). Also pull keywords from the abstract and the first independent claim. | F26: List every additional CPC subgroup beyond A1. Optionally enrich with 2-3 keyword tags drawn from the abstract (e.g., "MIMO", "beamforming", "edge inference"). | G26: Google Patents, Espacenet, Lens.org. For keyword extraction at scale: use a simple TF-IDF over the abstract against the rest of your portfolio.
A27: A | B27: A3 | C27: Stack layer | D27: Derived (rubric) | E27: Read the first independent claim and the "Field of the Invention" / "Background" section. | F27: Apply a 7-bucket rubric. Hardware: physical device, circuit, or material composition. Firmware: low-level code embedded in hardware. OS: kernel/driver level. Middleware: protocol stacks, libraries, frameworks. App: end-user application logic. Cloud: server-side service or backend. UI: visual interface or interaction pattern. Pick the dominant layer; if the claim mixes layers, pick where the novelty lives. | G27: Patent specification. No external database — judgment-based against the rubric.
A28: A | B28: A4 | C28: Product subsystem | D28: Derived (rubric) | E28: Read the first independent claim, the "Detailed Description" preamble, and any "Embodiments" section listing real-world products. | F28: Map the claim subject matter to a subsystem of an identifiable end product. Example: for an EV — "battery cell", "battery pack", "BMS", "traction inverter", "thermal mgmt", "charging port", "motor", "regen brake controller". Maintain a per-industry subsystem dictionary so tags are consistent. | G28: Patent specification + product architecture knowledge (engineering team / SME input).
A29: A | B29: A5 | C29: Use-case | D29: Derived (rubric) | E29: "Field of the Invention", "Background", and the "Detailed Description" — look for problem statements ("there is a need to...", "addresses the problem of..."). | F29: Phrase the use-case as a customer-facing problem (e.g., "indoor positioning", "battery fast-charging", "fraud detection in payments", "low-latency video streaming"). Maintain a portfolio-wide use-case dictionary; reuse tags rather than coining new ones for each patent. | G29: Patent specification. Use natural-language extraction from the Background section. Cross-check against market reports if needed.
A30: B | B30: B1 | C30: SEP potential | D30: Derived (rubric) | E30: Check (a) SEP databases for any declaration on this family, (b) the claim language for standards-spec phrasing, (c) any prior 3GPP / IEEE / ITU letters of assurance. | F30: Score 0-3. 3: declared SEP in an SSO database, OR claim language directly mirrors a normative spec section. 2: claim reads on a specific clause of a known standard but no formal declaration. 1: standard-adjacent but normative essentiality is debatable. 0: no standard tie. For 5G/Wi-Fi/Bluetooth/USB-C/H.26x patents, always run a claim-vs-spec mapping before assigning ≥2. | G30: ETSI IPR Online Database (search.ipr.etsi.org), IEEE-SA, ITU, IETF declarations, Unified Patents SEP database, IPlytics, Amplified.ai. Pair with claim-charts where available.
A31: B | B31: B2 | C31: Standard tagged | D31: Direct lookup | E31: Same sources as B1. Read the actual SSO declaration if one exists. | F31: Record the exact standard identifier (e.g., "3GPP TS 38.211 (5G NR PHY)", "IEEE 802.11be (Wi-Fi 7)", "USB PD 3.1", "ITU-T H.266/VVC"). If multiple standards are implicated, list all. Blank if B1 = 0. | G31: ETSI IPR database (full declaration text usually names the spec). Otherwise infer from claim text + standards expert review.
A32: B | B32: B3 | C32: Interface role | D32: Derived (rubric) | E32: Read the first independent claim. Look for protocol/handshake/format/connector language. | F32: Score 0-3. 3: claim sits at a mandatory interface between two systems (e.g., wire protocol, connector pinout, RPC format). 2: claim covers a widely-used interoperability mechanism that is not technically mandatory but is de-facto standard. 1: claim involves an interface but the interface is internal to one product. 0: no interface dimension. | G32: Patent specification + SME interpretation. Cross-check whether the interface is named in any public spec.
A33: C | B33: C1 | C33: Claim type | D33: Direct lookup | E33: Read the preamble of each independent claim. | F33: Classify the dominant independent claim type. Apparatus: "an apparatus comprising…", "a device comprising…". Method: "a method comprising the steps of…". System: "a system for X comprising…". CRM: "a non-transitory computer-readable medium storing instructions that, when executed…". Design: design patents (D-numbered, drawings only). If mixed, pick the most enforceable type given the product target. | G33: Patent claims section (always front-of-patent in granted patents).
A34: C | B34: C2 | C34: Claim breadth | D34: Derived (rubric) | E34: Read each independent claim. Count words, count specific limitations, look for "wherein" clauses. | F34: Score 0-3. 3 (pioneer/foundational): few elements, abstract/general language, no narrowing wherein clauses, broad genus. 2 (broad): moderate element count, some structural narrowing. 1 (narrow): many specific element constraints, specific value ranges, named structural features. 0 (very narrow/picture claim): tied to one specific implementation. Rule of thumb: shorter independent claims with fewer limitations are usually broader. | G34: Patent claims + judgment. Tools like ClaimMaster, LexisNexis PatentAdvisor, or simple word-count heuristics can prefilter.
A35: C | B35: C3 | C35: Independent claim count | D35: Direct lookup (count) | E35: Claims section. Independent claims are those that do not refer to another claim ("a method comprising…" rather than "the method of claim 1, wherein…"). | F35: Simple count. Look for claims whose first word is not "The" referring back to a prior claim. | G35: Patent claims section. Most patent APIs (PatentsView, EPO OPS) return claim text in structured form.
... A64: I | B64: I4 | C64: Workaround complexity | D64: Derived (rubric + engineering SME) | E64: Read the claim. Ask an engineer: "If a competitor needed to ship a competing product without infringing, how much redesign is needed?" | F64: Score 0-3. 3: deep redesign — claim covers the natural/efficient approach; alternatives are expensive or technically inferior. 2: significant redesign — alternatives exist but are commercially undesirable. 1: minor redesign — straightforward alternative is available. 0: trivial workaround — designers can easily substitute. Strongly correlates with C4 design-around difficulty but considered separately because C4 is about claim language whereas I4 is about commercial impact. | G64: Patent claims + engineering SME review. The most reliable answer comes from an engineer who has actually shipped products in the space.
A67: DATA SOURCE REFERENCE — free and paid sources used across the procedure
A68: Tier | B68: Source | C68: URL | E68: What it gives you
A69: Free | B69: Google Patents | C69: patents.google.com | E69: Bibliographic, family, citations, claims, full text. Best free starting point.
A70: Free | B70: Espacenet | C70: worldwide.espacenet.com | E70: EPO's global patent search; best for family view (INPADOC).
A71: Free | B71: USPTO Patent Center | C71: patentcenter.uspto.gov | E71: US file wrapper, prosecution history, maintenance fees, assignments.
A72: Free | B72: PatentsView | C72: patentsview.org | E72: USPTO bulk data API. Excellent for programmatic scoring across a portfolio.
A73: Free | B73: Lens.org | C73: lens.org | E73: Free patent + scholarly search; good for forward-citation analysis.
...

Sheet Patent Portfolio
A1: Identification | C1: A. Technology Classification | H1: B. Standards | K1: C. Claim & Scope | O1: D. Detectability | R1: E. Family & Lifecycle | W1: F. Geographic | Z1: G. Strategic | AC1: H. Patent Quality & Vulnerability | AM1: I. Market/Buyer Signals
A2: Patent ID | B2: Title | C2: A1 Primary domain | D2: A2 Secondary domains | E2: A3 Stack layer | F2: A4 Subsystem | G2: A5 Use-case | H2: B1 SEP potential (0-3) | I2: B2 Standard | J2: B3 Interface role (0-3) | K2: C1 Claim type | L2: C2 Claim breadth (0-3) | M2: C3 Indep. claim count | N2: C4 Design-around diff. (0-3) | O2: D1 External detect. (0-3) | P2: D2 Teardown detect. (0-3) | Q2: D3 Reads-on-products (0-3) | R2: E1 Family size | S2: E2 Prosecution | T2: E3 Continuation | U2: E4 Remaining term (yrs) | V2: E5 Maint. status | W2: F1 Jurisdictions | X2: F2 Trilateral (Y/N) | Y2: F3 Major-market score (0-3) | Z2: G1 Convergence theme | AA2: G2 Generation | AB2: G3 Cross-industry (0-3) | AC2: H1 Claim strength (0-3) | AD2: H2 Prior-art exposure (0-3) | AE2: H3 Prosecution risk (0-3) | AF2: H4 Divided-infrgmnt (0-3) | AG2: H5 Fwd citations | AH2: H6 Bwd citations | AI2: H7 Lit/PTAB history | AJ2: H8 Chain-of-title | AK2: H9 EoU available | AL2: H10 Encumbrance | AM2: I1 Product-map conf. (0-3) | AN2: I2 Impl. maturity | AO2: I3 Adjacent re-read (0-3) | AP2: I4 Workaround complex. (0-3)
A3: P-001 | B3: Beamforming pilot signaling for 5G NR | C3: Wireless PHY | D3: MIMO, beamforming | E3: Hardware | F3: Radio frontend | G3: Cellular comms | H3: 3 | I3: 3GPP 5G NR | J3: 3 | K3: Method | L3: 2 | M3: 3 | N3: 3 | O3: 1 | P3: 3 | Q3: 3 | R3: 8 | S3: Granted | T3: Yes | U3: 14 | V3: Active | W3: US, EP, CN, JP, KR | X3: Yes | Y3: 3 | AA3: Current | AB3: 1 | AC3: 3 | AD3: 3 | AE3: 2 | AF3: 3 | AG3: 28 | AH3: 42 | AI3: Survived | AJ3: Clean | AK3: Full | AL3: None | AM3: 3 | AN3: Productized | AO3: 1 | AP3: 3
A4: P-002 | B4: Polar code decoder architecture | C4: Wireless PHY | D4: Error correction | E4: Hardware | F4: Baseband processor | G4: Cellular comms | H4: 3 | I4: 3GPP 5G NR | J4: 2 | K4: Apparatus | L4: 2 | M4: 2 | N4: 2 | O4: 0 | P4: 3 | Q4: 3 | R4: 5 | S4: Granted | T4: No | U4: 13 | V4: Active | W4: US, EP, CN, KR | X4: Yes | Y4: 3 | AA4: Current | AB4: 1 | AC4: 2 | AD4: 2 | AE4: 2 | AF4: 3 | AG4: 18 | AH4: 31 | AI4: None | AJ4: Clean | AK4: Partial | AL4: None | AM4: 3 | AN4: Productized | AO4: 1 | AP4: 2
A5: P-003 | B5: Adaptive Wi-Fi 7 channel sounding | C5: Wireless PHY | D5: OFDMA | E5: Firmware | F5: WLAN module | G5: Indoor connectivity | H5: 2 | I5: IEEE 802.11be | J5: 3 | K5: Method | L5: 1 | M5: 2 | N5: 2 | O5: 1 | P5: 2 | Q5: 2 | R5: 4 | S5: Mixed | T5: Yes | U5: 17 | V5: Active | W5: US, EP, CN | X5: Yes | Y5: 2 | AA5: Next-gen | AB5: 2 | AC5: 2 | AD5: 3 | AE5: 3 | AF5: 2 | AG5: 4 | AH5: 22 | AI5: None | AJ5: Clean | AK5: None | AL5: None | AM5: 2 | AN5: Prototyped | AO5: 2 | AP5: 2
A6: P-004 | B6: Solid-state electrolyte composition for EV batteries | C6: Battery materials | D6: Solid-state, ionics | E6: Hardware | F6: Battery cell | G6: EV propulsion | H6: 0 | J6: 0 | K6: Apparatus | L6: 3 | M6: 4 | N6: 3 | O6: 0 | P6: 3 | Q6: 2 | R6: 6 | S6: Granted | T6: Yes | U6: 17 | V6: Active | W6: US, EP, CN, JP, KR | X6: Yes | Y6: 3 | AA6: Next-gen | AB6: 2 | AC6: 3 | AD6: 3 | AE6: 3 | AF6: 3 | AG6: 35 | AH6: 48 | AI6: None | AJ6: Clean | AK6: Partial | AL6: None | AM6: 2 | AN6: Prototyped | AO6: 3 | AP6: 3
A7: P-005 | B7: Battery thermal management with phase-change material | C7: Thermal mgmt | D7: BMS, materials | E7: Hardware | F7: Battery pack | G7: EV propulsion | H7: 0 | J7: 1 | K7: System | L7: 2 | M7: 3 | N7: 2 | O7: 1 | P7: 3 | Q7: 2 | R7: 3 | S7: Granted | T7: No | U7: 11 | V7: Active | W7: US, EP, CN | X7: Yes | Y7: 2 | AA7: Current | AB7: 2 | AC7: 2 | AD7: 2 | AE7: 2 | AF7: 3 | AG7: 14 | AH7: 27 | AI7: None | AJ7: Clean | AK7: None | AL7: Non-exclusive licensed | AM7: 2 | AN7: Productized | AO7: 2 | AP7: 2
A8: P-006 | B8: SiC MOSFET inverter control method | C8: Power electronics | D8: Wide-bandgap | E8: Firmware | F8: Traction inverter | G8: EV propulsion | H8: 0 | J8: 1 | K8: Method | L8: 2 | M8: 2 | N8: 2 | O8: 1 | P8: 3 | Q8: 3 | R8: 4 | S8: Granted | T8: No | U8: 12 | V8: Active | W8: US, EP, CN, JP | X8: Yes | Y8: 3 | AA8: Current | AB8: 2 | AC8: 2 | AD8: 2 | AE8: 2 | AF8: 3 | AG8: 16 | AH8: 33 | AI8: None | AJ8: Minor gaps | AK8: Partial | AL8: None | AM8: 3 | AN8: Productized | AO8: 2 | AP8: 2
A9: P-007 | B9: On-device CNN quantization for low-power inference | C9: CV algorithm | D9: Edge AI, ML | E9: App | F9: Vision pipeline | G9: Smart cameras | H9: 0 | J9: 0 | K9: CRM | L9: 2 | M9: 3 | N9: 2 | O9: 2 | P9: 1 | Q9: 2 | R9: 5 | S9: Granted | T9: Yes | U9: 15 | V9: Active | W9: US, EP, CN | X9: Yes | Y9: 2 | Z9: Edge AI | AA9: Current | AB9: 3 | AC9: 2 | AD9: 1 | AE9: 2 | AF9: 2 | AG9: 47 | AH9: 26 | AI9: Pending | AJ9: Clean | AK9: Partial | AL9: None | AM9: 2 | AN9: Productized | AO9: 3 | AP9: 2
A10: P-008 | B10: Transformer attention pruning for vision models | C10: CV algorithm | D10: AI optimization | E10: App | F10: Inference engine | G10: Visual analytics | H10: 0 | J10: 0 | K10: Method | L10: 1 | M10: 2 | N10: 1 | O10: 2 | P10: 0 | Q10: 2 | R10: 3 | S10: Pending | T10: Yes | U10: 19 | V10: Active | W10: US, EP | X10: No | Y10: 1 | Z10: Edge AI, AI+health | AA10: Next-gen | AB10: 3 | AC10: 1 | AD10: 1 | AE10: 1 | AF10: 1 | AG10: 8 | AH10: 19 | AI10: None | AJ10: Clean | AK10: None | AL10: None | AM10: 1 | AN10: Idea-only | AO10: 3 | AP10: 1
A11: P-009 | B11: Visual SLAM for indoor robot navigation | C11: Robotics SW | D11: SLAM, CV | E11: Middleware | F11: Navigation stack | G11: Indoor positioning | H11: 0 | J11: 1 | K11: System | L11: 2 | M11: 2 | N11: 2 | O11: 2 | P11: 1 | Q11: 2 | R11: 4 | S11: Granted | T11: No | U11: 10 | V11: Active | W11: US, EP, JP | X11: Yes | Y11: 2 | Z11: Robotics, edge AI | AA11: Current | AB11: 3 | AC11: 2 | AD11: 2 | AE11: 2 | AF11: 2 | AG11: 22 | AH11: 34 | AI11: None | AJ11: Clean | AK11: Partial | AL11: None | AM11: 2 | AN11: Prototyped | AO11: 2 | AP11: 2
A12: P-010 | B12: USB-C power delivery handshake extension | C12: Interconnect | D12: Power delivery | E12: Firmware | F12: Charging interface | G12: Universal charging | H12: 2 | I12: USB PD 3.x | J12: 3 | K12: Method | L12: 1 | M12: 2 | N12: 2 | O12: 3 | P12: 3 | Q12: 3 | R12: 5 | S12: Granted | T12: No | U12: 9 | V12: Active | W12: US, EP, CN, JP, KR | X12: Yes | Y12: 3 | AA12: Current | AB12: 3 | AC12: 2 | AD12: 3 | AE12: 2 | AF12: 3 | AG12: 25 | AH12: 39 | AI12: Survived | AJ12: Clean | AK12: Full | AL12: None | AM12: 3 | AN12: Productized | AO12: 2 | AP12: 2
A13: P-011 | B13: Atomic layer deposition recipe for high-k dielectric | C13: Semiconductor process | D13: ALD, fab | E13: Hardware | F13: Front-end-of-line | G13: IC manufacturing | H13: 0 | J13: 1 | K13: Method | L13: 2 | M13: 3 | N13: 3 | O13: 0 | P13: 1 | Q13: 1 | R13: 6 | S13: Granted | T13: Yes | U13: 13 | V13: Active | W13: US, EP, CN, JP, KR, TW | X13: Yes | Y13: 3 | AA13: Current | AB13: 1 | AC13: 3 | AD13: 2 | AE13: 3 | AF13: 3 | AG13: 19 | AH13: 41 | AI13: None | AJ13: Clean | AK13: None | AL13: None | AM13: 1 | AN13: Productized | AO13: 1 | AP13: 3
A14: P-012 | B14: Predictive maintenance ML for industrial pumps | C14: Industrial AI | D14: Predictive analytics | E14: Cloud | F14: Asset monitoring | G14: Predictive maintenance | H14: 0 | J14: 1 | K14: CRM | L14: 1 | M14: 2 | N14: 1 | O14: 2 | P14: 0 | Q14: 1 | R14: 2 | S14: Granted | T14: No | U14: 8 | V14: Active | W14: US, EP | X14: No | Y14: 1 | Z14: AI+industrial | AA14: Current | AB14: 3 | AC14: 1 | AD14: 1 | AE14: 2 | AF14: 1 | AG14: 5 | AH14: 12 | AI14: None | AJ14: Minor gaps | AK14: None | AL14: None | AM14: 1 | AN14: Idea-only | AO14: 2 | AP14: 1

Sheet Bundle Rules
A1: # | B1: Bundle Type | C1: Value Proposition | D1: Routing Rule (technical qualification) | E1: Primary attributes used
A2: 1 | B2: Technology Domain | C2: Concentrated coverage in one technical field; useful for entering or fortifying a domain position. | D2: Patents share the same A1 (primary domain) tag. | E2: A1
A3: 2 | B3: Standard-Essential (SEP) | C3: Bundle of assets every implementer of the standard must license or design around. | D3: B1 ≥ 2 AND share same B2 standard. | E3: B1, B2
A4: 3 | B4: Product Architecture | C4: "Build a product" kit — full vertical coverage across subsystems of one end-product. | D4: Collectively span ≥ 3 distinct A4 subsystems of one product family. | E4: A4
A5: 4 | B5: Stack Layer | C5: Targets buyers operating at a specific layer of the technology stack. | D5: Patents share the same A3 (stack layer). | E5: A3
A6: 5 | B6: Use-Case / Application | C6: All tools to address one customer problem, even if underlying tech is heterogeneous. | D6: Patents share at least one A5 (use-case) tag. | E6: A5
A7: 6 | B7: Manufacturing / Process | C7: Targets fabs, contract manufacturers, equipment makers needing freedom to operate on production methods. | D7: A1 is a "process" / manufacturing domain (e.g., contains "process" or "fab") AND C1 = Method. | E7: A1, C1
A8: 7 | B8: Materials & Chemistry | C8: Focused IP shield around composition, synthesis, and use of a material system. | D8: A1 is a materials/chemistry domain AND C1 ∈ {Apparatus, Method}. | E8: A1, C1
A9: 8 | B9: Algorithm / Software Method | C9: Implementation-agnostic methods deployable across many products. | D9: A3 ∈ {App, Middleware, Cloud} AND C1 ∈ {Method, CRM}. | E9: A3, C1
A10: 9 | B10: Interoperability / Interface | C10: Critical chokepoints for any player whose product must talk to others. | D10: B3 ≥ 2. | E10: B3
A11: 10 | B11: Generational Roadmap | C11: Buyer picks legacy (cheap defensive) or next-gen (forward-looking offensive). | D11: Group by G2 (Legacy / Current / Next-gen). | E11: G2
A12: 11 | B12: Claim-Type | C12: Different enforcement profiles; buyers pick by litigation/licensing strategy. | D12: Group by C1. | E12: C1
A13: 12 | B13: Detectability | C13: Litigation-ready bundle — infringement is easy to spot. | D13: D1 ≥ 2 OR D2 ≥ 2. | E13: D1, D2
... A34: 33 | B34: Provenance-Coherent | C34: Patents originating from the same R&D program, inventor group, or acquired sub-business. Shared specifications and consistent terminology reduce claim-construction risk. | D34: Patents share A1 AND share A4 (proxy for common provenance in this template). | E34: A1, A4

Sheet Bundle Assignment
A1: Patent | C1: Bundle Qualification (TRUE = patent qualifies for this bundle) | AJ1: Total
A2: Patent ID | B2: Title | C2: =IF(Configuration!$C$10="No","[DISABLED] B1 Tech Domain","B1 Tech Domain") -> B1 Tech Domain | D2: =IF(Configuration!$C$11="No","[DISABLED] B2 SEP","B2 SEP") -> B2 SEP | E2: =IF(Configuration!$C$12="No","[DISABLED] B3 Product Arch","B3 Product Arch") -> B3 Product Arch | F2: =IF(Configuration!$C$13="No","[DISABLED] B4 Stack Layer","B4 Stack Layer") -> B4 Stack Layer | G2: =IF(Configuration!$C$14="No","[DISABLED] B5 Use-Case","B5 Use-Case") -> B5 Use-Case | H2: =IF(Configuration!$C$15="No","[DISABLED] B6 Mfg/Process","B6 Mfg/Process") -> B6 Mfg/Process | I2: =IF(Configuration!$C$16="No","[DISABLED] B7 Materials","B7 Materials") -> B7 Materials | J2: =IF(Configuration!$C$17="No","[DISABLED] B8 Algorithm","B8 Algorithm") -> B8 Algorithm | K2: =IF(Configuration!$C$18="No","[DISABLED] B9 Interop","B9 Interop") -> B9 Interop | L2: =IF(Configuration!$C$19="No","[DISABLED] B10 Generational","B10 Generational") -> B10 Generational | M2: =IF(Configuration!$C$20="No","[DISABLED] B11 Claim-Type","B11 Claim-Type") -> B11 Claim-Type | N2: =IF(Configuration!$C$21="No","[DISABLED] B12 Detectable","B12 Detectable") -> B12 Detectable | O2: =IF(Configuration!$C$22="No","[DISABLED] B13 Geographic","B13 Geographic") -> B13 Geographic | P2: =IF(Configuration!$C$23="No","[DISABLED] B14 Family","B14 Family") -> B14 Family | Q2: =IF(Configuration!$C$24="No","[DISABLED] B15 Lifecycle","B15 Lifecycle") -> B15 Lifecycle | R2: =IF(Configuration!$C$25="No","[DISABLED] B16 Foundational+Improv.","B16 Foundational+Improv.") -> B16 Foundational+Improv. | S2: =IF(Configuration!$C$26="No","[DISABLED] B17 Cross-Industry","B17 Cross-Industry") -> B17 Cross-Industry | T2: =IF(Configuration!$C$27="No","[DISABLED] B18 Convergent Theme","B18 Convergent Theme") -> B18 Convergent Theme | U2: =IF(Configuration!$C$28="No","[DISABLED] B19 Defensive","B19 Defensive") -> B19 Defensive | V2: =IF(Configuration!$C$29="No","[DISABLED] B20 Whitespace","B20 Whitespace") -> B20 Whitespace | W2: =IF(Configuration!$C$30="No","[DISABLED] B21 Prosecution-Status","B21 Prosecution-Status") -> B21 Prosecution-Status | X2: =IF(Configuration!$C$31="No","[DISABLED] B22 Anchor+Halo","B22 Anchor+Halo") -> B22 Anchor+Halo | Y2: =IF(Configuration!$C$32="No","[DISABLED] B23 Picket-Fence","B23 Picket-Fence") -> B23 Picket-Fence | Z2: =IF(Configuration!$C$33="No","[DISABLED] B24 Strong+Tail","B24 Strong+Tail") -> B24 Strong+Tail | AA2: =IF(Configuration!$C$34="No","[DISABLED] B25 Continuation-Live","B25 Continuation-Live") -> B25 Continuation-Live | AB2: =IF(Configuration!$C$35="No","[DISABLED] B26 EoU-Backed","B26 EoU-Backed") -> B26 EoU-Backed | AC2: =IF(Configuration!$C$36="No","[DISABLED] B27 Battle-Tested","B27 Battle-Tested") -> B27 Battle-Tested | AD2: =IF(Configuration!$C$37="No","[DISABLED] B28 Clean-Title","B28 Clean-Title") -> B28 Clean-Title | AE2: =IF(Configuration!$C$38="No","[DISABLED] B29 High-Citation","B29 High-Citation") -> B29 High-Citation | AF2: =IF(Configuration!$C$39="No","[DISABLED] B30 Adjacent Re-Read","B30 Adjacent Re-Read") -> B30 Adjacent Re-Read | AG2: =IF(Configuration!$C$40="No","[DISABLED] B31 Salvage-Volume","B31 Salvage-Volume") -> B31 Salvage-Volume | AH2: =IF(Configuration!$C$41="No","[DISABLED] B32 Pre-Expiry","B32 Pre-Expiry") -> B32 Pre-Expiry | AI2: =IF(Configuration!$C$42="No","[DISABLED] B33 Provenance","B33 Provenance") -> B33 Provenance | AJ2: # of bundles
A3: ='Patent Portfolio'!A3 -> P-001 | B3: ='Patent Portfolio'!B3 -> Beamforming pilot signaling for 5G NR | C3: =IF(Configuration!$C$10="No","",IFERROR(IF('Patent Portfolio'!C3<>"",TRUE(),FALSE()),FALSE())) -> TRUE | D3: =IF(Configuration!$C$11="No","",IFERROR(IF(AND(N('Patent Portfolio'!H3)>=Configuration!$C$44,'Patent Portfolio'!I3<>""),TRUE(),FALSE()),FALSE())) -> TRUE | E3: =IF(Configuration!$C$12="No","",IFERROR(IF('Patent Portfolio'!F3<>"",TRUE(),FALSE()),FALSE())) -> TRUE | F3: =IF(Configuration!$C$13="No","",IFERROR(IF('Patent Portfolio'!E3<>"",TRUE(),FALSE()),FALSE())) -> TRUE | G3: =IF(Configuration!$C$14="No","",IFERROR(IF('Patent Portfolio'!G3<>"",TRUE(),FALSE()),FALSE())) -> TRUE | H3: =IF(Configuration!$C$15="No","",IFERROR(IF(AND(OR(ISNUMBER(SEARCH("process",'Patent Portfolio'!C3)),ISNUMBER(SEARCH("fab",'Patent Portfolio'!C3)),ISNUMBER(SEARCH("manufac",'Patent Portfolio'!C3))),'Patent Portfolio'!K3="Method"),TRUE(),FALSE()),FALSE())) -> FALSE | I3: =IF(Configuration!$C$16="No","",IFERROR(IF(AND(OR(ISNUMBER(SEARCH("material",'Patent Portfolio'!C3)),ISNUMBER(SEARCH("chem",'Patent Portfolio'!C3)),ISNUMBER(SEARCH("battery",'Patent Portfolio'!C3)),ISNUMBER(SEARCH("electrolyte",'Patent Portfolio'!C3)),ISNUMBER(SEARCH("polymer",'Patent Portfolio'!C3))),OR('Patent Portfolio'!K3="Apparatus",'Patent Portfolio'!K3="Method")),TRUE(),FALSE()),FALSE())) -> FALSE | J3: =IF(Configuration!$C$17="No","",IFERROR(IF(AND(OR('Patent Portfolio'!E3="App",'Patent Portfolio'!E3="Middleware",'Patent Portfolio'!E3="Cloud"),OR('Patent Portfolio'!K3="Method",'Patent Portfolio'!K3="CRM")),TRUE(),FALSE()),FALSE())) -> FALSE | K3: =IF(Configuration!$C$18="No","",IFERROR(IF(N('Patent Portfolio'!J3)>=Configuration!$C$45,TRUE(),FALSE()),FALSE())) -> TRUE | L3: =IF(Configuration!$C$19="No","",IFERROR(IF('Patent Portfolio'!AA3<>"",TRUE(),FALSE()),FALSE())) -> TRUE | M3: =IF(Configuration!$C$20="No","",IFERROR(IF('Patent Portfolio'!K3<>"",TRUE(),FALSE()),FALSE())) -> TRUE | N3: =IF(Configuration!$C$21="No","",IFERROR(IF(OR(N('Patent Portfolio'!O3)>=Configuration!$C$46,N('Patent Portfolio'!P3)>=Configuration!$C$47),TRUE(),FALSE()),FALSE())) -> TRUE | O3: =IF(Configuration!$C$22="No","",IFERROR(IF('Patent Portfolio'!X3="Yes",TRUE(),FALSE()),FALSE())) -> TRUE | P3: =IF(Configuration!$C$23="No","",IFERROR(IF(N('Patent Portfolio'!R3)>=Configuration!$C$48,TRUE(),FALSE()),FALSE())) -> TRUE | Q3: =IF(Configuration!$C$24="No","",IFERROR(IF(N('Patent Portfolio'!U3)>0,TRUE(),FALSE()),FALSE())) -> TRUE | R3: =IF(Configuration!$C$25="No","",IFERROR(IF(OR(N('Patent Portfolio'!L3)=3,N('Patent Portfolio'!L3)<=1),TRUE(),FALSE()),FALSE())) -> FALSE | S3: =IF(Configuration!$C$26="No","",IFERROR(IF(N('Patent Portfolio'!AB3)>=Configuration!$C$49,TRUE(),FALSE()),FALSE())) -> FALSE | T3: =IF(Configuration!$C$27="No","",IFERROR(IF('Patent Portfolio'!Z3<>"",TRUE(),FALSE()),FALSE())) -> FALSE | U3: =IF(Configuration!$C$28="No","",IFERROR(IF(N('Patent Portfolio'!Q3)>=Configuration!$C$50,TRUE(),FALSE()),FALSE())) -> TRUE | V3: =IF(Configuration!$C$29="No","",IFERROR(IF(AND(N('Patent Portfolio'!N3)>=Configuration!$C$51,'Patent Portfolio'!C3<>""),TRUE(),FALSE()),FALSE())) -> TRUE | W3: =IF(Configuration!$C$30="No","",IFERROR(IF(OR('Patent Portfolio'!S3="Pending",'Patent Portfolio'!T3="Yes"),TRUE(),FALSE()),FALSE())) -> TRUE | X3: =IF(Configuration!$C$31="No","",IFERROR(IF(AND(N('Patent Portfolio'!AC3)>=Configuration!$C$52,N('Patent Portfolio'!L3)>=1),TRUE(),FALSE()),FALSE())) -> TRUE | Y3: =IF(Configuration!$C$32="No","",IFERROR(IF(AND(N('Patent Portfolio'!N3)>=1,OR('Patent Portfolio'!C3<>"",'Patent Portfolio'!I3<>"")),TRUE(),FALSE()),FALSE())) -> TRUE | Z3: =IF(Configuration!$C$33="No","",IFERROR(IF('Patent Portfolio'!C3<>"",TRUE(),FALSE()),FALSE())) -> TRUE | AA3: =IF(Configuration!$C$34="No","",IFERROR(IF('Patent Portfolio'!T3="Yes",TRUE(),FALSE()),FALSE())) -> TRUE | AB3: =IF(Configuration!$C$35="No","",IFERROR(IF(OR('Patent Portfolio'!AK3="Partial",'Patent Portfolio'!AK3="Full"),TRUE(),FALSE()),FALSE())) -> TRUE | AC3: =IF(Configuration!$C$36="No","",IFERROR(IF('Patent Portfolio'!AI3="Survived",TRUE(),FALSE()),FALSE())) -> TRUE | AD3: =IF(Configuration!$C$37="No","",IFERROR(IF(AND('Patent Portfolio'!AJ3="Clean",'Patent Portfolio'!AL3="None"),TRUE(),FALSE()),FALSE())) -> TRUE | AE3: =IF(Configuration!$C$38="No","",IFERROR(IF(N('Patent Portfolio'!AG3)>=Configuration!$C$53,TRUE(),FALSE()),FALSE())) -> TRUE | AF3: =IF(Configuration!$C$39="No","",IFERROR(IF(AND(N('Patent Portfolio'!AO3)>=2,N('Patent Portfolio'!AB3)>=2),TRUE(),FALSE()),FALSE())) -> FALSE | AG3: =IF(Configuration!$C$40="No","",IFERROR(IF(OR(N('Patent Portfolio'!AC3)<=Configuration!$C$56,N('Patent Portfolio'!U3)<Configuration!$C$57,N('Patent Portfolio'!AD3)<=Configuration!$C$58),TRUE(),FALSE()),FALSE())) -> FALSE | AH3: =IF(Configuration!$C$41="No","",IFERROR(IF(AND(N('Patent Portfolio'!U3)>=Configuration!$C$54,N('Patent Portfolio'!U3)<=Configuration!$C$55),TRUE(),FALSE()),FALSE())) -> FALSE | AI3: =IF(Configuration!$C$42="No","",IFERROR(IF(AND('Patent Portfolio'!C3<>"",'Patent Portfolio'!F3<>""),TRUE(),FALSE()),FALSE())) -> TRUE | AJ3: =COUNTIF(C3:AI3,TRUE()) -> 24
A4: ='Patent Portfolio'!A4 -> P-002 | B4: ='Patent Portfolio'!B4 -> Polar code decoder architecture | C4: =IF(Configuration!$C$10="No","",IFERROR(IF('Patent Portfolio'!C4<>"",TRUE(),FALSE()),FALSE())) -> TRUE | D4: =IF(Configuration!$C$11="No","",IFERROR(IF(AND(N('Patent Portfolio'!H4)>=Configuration!$C$44,'Patent Portfolio'!I4<>""),TRUE(),FALSE()),FALSE())) -> TRUE | E4: =IF(Configuration!$C$12="No","",IFERROR(IF('Patent Portfolio'!F4<>"",TRUE(),FALSE()),FALSE())) -> TRUE | F4: =IF(Configuration!$C$13="No","",IFERROR(IF('Patent Portfolio'!E4<>"",TRUE(),FALSE()),FALSE())) -> TRUE | G4: =IF(Configuration!$C$14="No","",IFERROR(IF('Patent Portfolio'!G4<>"",TRUE(),FALSE()),FALSE())) -> TRUE | H4: =IF(Configuration!$C$15="No","",IFERROR(IF(AND(OR(ISNUMBER(SEARCH("process",'Patent Portfolio'!C4)),ISNUMBER(SEARCH("fab",'Patent Portfolio'!C4)),ISNUMBER(SEARCH("manufac",'Patent Portfolio'!C4))),'Patent Portfolio'!K4="Method"),TRUE(),FALSE()),FALSE())) -> FALSE | I4: =IF(Configuration!$C$16="No","",IFERROR(IF(AND(OR(ISNUMBER(SEARCH("material",'Patent Portfolio'!C4)),ISNUMBER(SEARCH("chem",'Patent Portfolio'!C4)),ISNUMBER(SEARCH("battery",'Patent Portfolio'!C4)),ISNUMBER(SEARCH("electrolyte",'Patent Portfolio'!C4)),ISNUMBER(SEARCH("polymer",'Patent Portfolio'!C4))),OR('Patent Portfolio'!K4="Apparatus",'Patent Portfolio'!K4="Method")),TRUE(),FALSE()),FALSE())) -> FALSE | J4: =IF(Configuration!$C$17="No","",IFERROR(IF(AND(OR('Patent Portfolio'!E4="App",'Patent Portfolio'!E4="Middleware",'Patent Portfolio'!E4="Cloud"),OR('Patent Portfolio'!K4="Method",'Patent Portfolio'!K4="CRM")),TRUE(),FALSE()),FALSE())) -> FALSE | K4: =IF(Configuration!$C$18="No","",IFERROR(IF(N('Patent Portfolio'!J4)>=Configuration!$C$45,TRUE(),FALSE()),FALSE())) -> TRUE | L4: =IF(Configuration!$C$19="No","",IFERROR(IF('Patent Portfolio'!AA4<>"",TRUE(),FALSE()),FALSE())) -> TRUE | M4: =IF(Configuration!$C$20="No","",IFERROR(IF('Patent Portfolio'!K4<>"",TRUE(),FALSE()),FALSE())) -> TRUE | N4: =IF(Configuration!$C$21="No","",IFERROR(IF(OR(N('Patent Portfolio'!O4)>=Configuration!$C$46,N('Patent Portfolio'!P4)>=Configuration!$C$47),TRUE(),FALSE()),FALSE())) -> TRUE | O4: =IF(Configuration!$C$22="No","",IFERROR(IF('Patent Portfolio'!X4="Yes",TRUE(),FALSE()),FALSE())) -> TRUE | P4: =IF(Configuration!$C$23="No","",IFERROR(IF(N('Patent Portfolio'!R4)>=Configuration!$C$48,TRUE(),FALSE()),FALSE())) -> TRUE | Q4: =IF(Configuration!$C$24="No","",IFERROR(IF(N('Patent Portfolio'!U4)>0,TRUE(),FALSE()),FALSE())) -> TRUE | R4: =IF(Configuration!$C$25="No","",IFERROR(IF(OR(N('Patent Portfolio'!L4)=3,N('Patent Portfolio'!L4)<=1),TRUE(),FALSE()),FALSE())) -> FALSE | S4: =IF(Configuration!$C$26="No","",IFERROR(IF(N('Patent Portfolio'!AB4)>=Configuration!$C$49,TRUE(),FALSE()),FALSE())) -> FALSE | T4: =IF(Configuration!$C$27="No","",IFERROR(IF('Patent Portfolio'!Z4<>"",TRUE(),FALSE()),FALSE())) -> FALSE | U4: =IF(Configuration!$C$28="No","",IFERROR(IF(N('Patent Portfolio'!Q4)>=Configuration!$C$50,TRUE(),FALSE()),FALSE())) -> TRUE | V4: =IF(Configuration!$C$29="No","",IFERROR(IF(AND(N('Patent Portfolio'!N4)>=Configuration!$C$51,'Patent Portfolio'!C4<>""),TRUE(),FALSE()),FALSE())) -> TRUE | W4: =IF(Configuration!$C$30="No","",IFERROR(IF(OR('Patent Portfolio'!S4="Pending",'Patent Portfolio'!T4="Yes"),TRUE(),FALSE()),FALSE())) -> FALSE | X4: =IF(Configuration!$C$31="No","",IFERROR(IF(AND(N('Patent Portfolio'!AC4)>=Configuration!$C$52,N('Patent Portfolio'!L4)>=1),TRUE(),FALSE()),FALSE())) -> TRUE | Y4: =IF(Configuration!$C$32="No","",IFERROR(IF(AND(N('Patent Portfolio'!N4)>=1,OR('Patent Portfolio'!C4<>"",'Patent Portfolio'!I4<>"")),TRUE(),FALSE()),FALSE())) -> TRUE | Z4: =IF(Configuration!$C$33="No","",IFERROR(IF('Patent Portfolio'!C4<>"",TRUE(),FALSE()),FALSE())) -> TRUE | AA4: =IF(Configuration!$C$34="No","",IFERROR(IF('Patent Portfolio'!T4="Yes",TRUE(),FALSE()),FALSE())) -> FALSE | AB4: =IF(Configuration!$C$35="No","",IFERROR(IF(OR('Patent Portfolio'!AK4="Partial",'Patent Portfolio'!AK4="Full"),TRUE(),FALSE()),FALSE())) -> TRUE | AC4: =IF(Configuration!$C$36="No","",IFERROR(IF('Patent Portfolio'!AI4="Survived",TRUE(),FALSE()),FALSE())) -> FALSE | AD4: =IF(Configuration!$C$37="No","",IFERROR(IF(AND('Patent Portfolio'!AJ4="Clean",'Patent Portfolio'!AL4="None"),TRUE(),FALSE()),FALSE())) -> TRUE | AE4: =IF(Configuration!$C$38="No","",IFERROR(IF(N('Patent Portfolio'!AG4)>=Configuration!$C$53,TRUE(),FALSE()),FALSE())) -> TRUE | AF4: =IF(Configuration!$C$39="No","",IFERROR(IF(AND(N('Patent Portfolio'!AO4)>=2,N('Patent Portfolio'!AB4)>=2),TRUE(),FALSE()),FALSE())) -> FALSE | AG4: =IF(Configuration!$C$40="No","",IFERROR(IF(OR(N('Patent Portfolio'!AC4)<=Configuration!$C$56,N('Patent Portfolio'!U4)<Configuration!$C$57,N('Patent Portfolio'!AD4)<=Configuration!$C$58),TRUE(),FALSE()),FALSE())) -> FALSE | AH4: =IF(Configuration!$C$41="No","",IFERROR(IF(AND(N('Patent Portfolio'!U4)>=Configuration!$C$54,N('Patent Portfolio'!U4)<=Configuration!$C$55),TRUE(),FALSE()),FALSE())) -> FALSE | AI4: =IF(Configuration!$C$42="No","",IFERROR(IF(AND('Patent Portfolio'!C4<>"",'Patent Portfolio'!F4<>""),TRUE(),FALSE()),FALSE())) -> TRUE | AJ4: =COUNTIF(C4:AI4,TRUE()) -> 21
A5: ='Patent Portfolio'!A5 -> P-003 | B5: ='Patent Portfolio'!B5 -> Adaptive Wi-Fi 7 channel sounding | C5: =IF(Configuration!$C$10="No","",IFERROR(IF('Patent Portfolio'!C5<>"",TRUE(),FALSE()),FALSE())) -> TRUE | D5: =IF(Configuration!$C$11="No","",IFERROR(IF(AND(N('Patent Portfolio'!H5)>=Configuration!$C$44,'Patent Portfolio'!I5<>""),TRUE(),FALSE()),FALSE())) -> TRUE | E5: =IF(Configuration!$C$12="No","",IFERROR(IF('Patent Portfolio'!F5<>"",TRUE(),FALSE()),FALSE())) -> TRUE | F5: =IF(Configuration!$C$13="No","",IFERROR(IF('Patent Portfolio'!E5<>"",TRUE(),FALSE()),FALSE())) -> TRUE | G5: =IF(Configuration!$C$14="No","",IFERROR(IF('Patent Portfolio'!G5<>"",TRUE(),FALSE()),FALSE())) -> TRUE | H5: =IF(Configuration!$C$15="No","",IFERROR(IF(AND(OR(ISNUMBER(SEARCH("process",'Patent Portfolio'!C5)),ISNUMBER(SEARCH("fab",'Patent Portfolio'!C5)),ISNUMBER(SEARCH("manufac",'Patent Portfolio'!C5))),'Patent Portfolio'!K5="Method"),TRUE(),FALSE()),FALSE())) -> FALSE | I5: =IF(Configuration!$C$16="No","",IFERROR(IF(AND(OR(ISNUMBER(SEARCH("material",'Patent Portfolio'!C5)),ISNUMBER(SEARCH("chem",'Patent Portfolio'!C5)),ISNUMBER(SEARCH("battery",'Patent Portfolio'!C5)),ISNUMBER(SEARCH("electrolyte",'Patent Portfolio'!C5)),ISNUMBER(SEARCH("polymer",'Patent Portfolio'!C5))),OR('Patent Portfolio'!K5="Apparatus",'Patent Portfolio'!K5="Method")),TRUE(),FALSE()),FALSE())) -> FALSE | J5: =IF(Configuration!$C$17="No","",IFERROR(IF(AND(OR('Patent Portfolio'!E5="App",'Patent Portfolio'!E5="Middleware",'Patent Portfolio'!E5="Cloud"),OR('Patent Portfolio'!K5="Method",'Patent Portfolio'!K5="CRM")),TRUE(),FALSE()),FALSE())) -> FALSE | K5: =IF(Configuration!$C$18="No","",IFERROR(IF(N('Patent Portfolio'!J5)>=Configuration!$C$45,TRUE(),FALSE()),FALSE())) -> TRUE | L5: =IF(Configuration!$C$19="No","",IFERROR(IF('Patent Portfolio'!AA5<>"",TRUE(),FALSE()),FALSE())) -> TRUE | M5: =IF(Configuration!$C$20="No","",IFERROR(IF('Patent Portfolio'!K5<>"",TRUE(),FALSE()),FALSE())) -> TRUE | N5: =IF(Configuration!$C$21="No","",IFERROR(IF(OR(N('Patent Portfolio'!O5)>=Configuration!$C$46,N('Patent Portfolio'!P5)>=Configuration!$C$47),TRUE(),FALSE()),FALSE())) -> TRUE | O5: =IF(Configuration!$C$22="No","",IFERROR(IF('Patent Portfolio'!X5="Yes",TRUE(),FALSE()),FALSE())) -> TRUE | P5: =IF(Configuration!$C$23="No","",IFERROR(IF(N('Patent Portfolio'!R5)>=Configuration!$C$48,TRUE(),FALSE()),FALSE())) -> TRUE | Q5: =IF(Configuration!$C$24="No","",IFERROR(IF(N('Patent Portfolio'!U5)>0,TRUE(),FALSE()),FALSE())) -> TRUE | R5: =IF(Configuration!$C$25="No","",IFERROR(IF(OR(N('Patent Portfolio'!L5)=3,N('Patent Portfolio'!L5)<=1),TRUE(),FALSE()),FALSE())) -> TRUE | S5: =IF(Configuration!$C$26="No","",IFERROR(IF(N('Patent Portfolio'!AB5)>=Configuration!$C$49,TRUE(),FALSE()),FALSE())) -> TRUE | T5: =IF(Configuration!$C$27="No","",IFERROR(IF('Patent Portfolio'!Z5<>"",TRUE(),FALSE()),FALSE())) -> FALSE | U5: =IF(Configuration!$C$28="No","",IFERROR(IF(N('Patent Portfolio'!Q5)>=Configuration!$C$50,TRUE(),FALSE()),FALSE())) -> TRUE | V5: =IF(Configuration!$C$29="No","",IFERROR(IF(AND(N('Patent Portfolio'!N5)>=Configuration!$C$51,'Patent Portfolio'!C5<>""),TRUE(),FALSE()),FALSE())) -> TRUE | W5: =IF(Configuration!$C$30="No","",IFERROR(IF(OR('Patent Portfolio'!S5="Pending",'Patent Portfolio'!T5="Yes"),TRUE(),FALSE()),FALSE())) -> TRUE | X5: =IF(Configuration!$C$31="No","",IFERROR(IF(AND(N('Patent Portfolio'!AC5)>=Configuration!$C$52,N('Patent Portfolio'!L5)>=1),TRUE(),FALSE()),FALSE())) -> TRUE | Y5: =IF(Configuration!$C$32="No","",IFERROR(IF(AND(N('Patent Portfolio'!N5)>=1,OR('Patent Portfolio'!C5<>"",'Patent Portfolio'!I5<>"")),TRUE(),FALSE()),FALSE())) -> TRUE | Z5: =IF(Configuration!$C$33="No","",IFERROR(IF('Patent Portfolio'!C5<>"",TRUE(),FALSE()),FALSE())) -> TRUE | AA5: =IF(Configuration!$C$34="No","",IFERROR(IF('Patent Portfolio'!T5="Yes",TRUE(),FALSE()),FALSE())) -> TRUE | AB5: =IF(Configuration!$C$35="No","",IFERROR(IF(OR('Patent Portfolio'!AK5="Partial",'Patent Portfolio'!AK5="Full"),TRUE(),FALSE()),FALSE())) -> FALSE | AC5: =IF(Configuration!$C$36="No","",IFERROR(IF('Patent Portfolio'!AI5="Survived",TRUE(),FALSE()),FALSE())) -> FALSE | AD5: =IF(Configuration!$C$37="No","",IFERROR(IF(AND('Patent Portfolio'!AJ5="Clean",'Patent Portfolio'!AL5="None"),TRUE(),FALSE()),FALSE())) -> TRUE | AE5: =IF(Configuration!$C$38="No","",IFERROR(IF(N('Patent Portfolio'!AG5)>=Configuration!$C$53,TRUE(),FALSE()),FALSE())) -> FALSE | AF5: =IF(Configuration!$C$39="No","",IFERROR(IF(AND(N('Patent Portfolio'!AO5)>=2,N('Patent Portfolio'!AB5)>=2),TRUE(),FALSE()),FALSE())) -> TRUE | AG5: =IF(Configuration!$C$40="No","",IFERROR(IF(OR(N('Patent Portfolio'!AC5)<=Configuration!$C$56,N('Patent Portfolio'!U5)<Configuration!$C$57,N('Patent Portfolio'!AD5)<=Configuration!$C$58),TRUE(),FALSE()),FALSE())) -> FALSE | AH5: =IF(Configuration!$C$41="No","",IFERROR(IF(AND(N('Patent Portfolio'!U5)>=Configuration!$C$54,N('Patent Portfolio'!U5)<=Configuration!$C$55),TRUE(),FALSE()),FALSE())) -> FALSE | AI5: =IF(Configuration!$C$42="No","",IFERROR(IF(AND('Patent Portfolio'!C5<>"",'Patent Portfolio'!F5<>""),TRUE(),FALSE()),FALSE())) -> TRUE | AJ5: =COUNTIF(C5:AI5,TRUE()) -> 24
