Workbook

Sheet README
A1: PATENT PORTFOLIO BUNDLING TEMPLATE
A2: A technical-attribute-based framework for grouping patents into sellable bundles
A4: PURPOSE
A5: Score each patent across technical attributes, then auto-route patents into one or more sellable bundle types based on logical rules. The framework is purely technical — no valuation, no pricing.
A7: SHEETS IN THIS WORKBOOK
A8: 1. README — This page. Overview and instructions.
A9: 2. Attribute Dictionary — Definitions and scoring scales for every attribute.
A10: 3. Patent Portfolio — Master data sheet. One row per patent. Fill this in.
A11: 4. Bundle Rules — The 21 bundle types and the routing rule that qualifies a patent for each.
A12: 5. Bundle Assignment — Auto-computed: which bundles each patent qualifies for.
A13: 6. Bundle Quality Scorecard — Auto-computed: quality indicators per bundle.
A14: 7. Sample Bundles — Worked examples showing how three bundles look in practice.
... A65: v6 ADDITION — PatSeer Import Sheet • New sheet "PatSeer Import" (second sheet, after README). • Zone 1: Column Mapping Table (rows 7-33): maps 25 PatSeer export column headers to v5 attribute codes with transform rules. Edit col A to match your actual PatSeer headers. • Zone 2: Paste Area (cols F-AE, rows 40+): paste your PatSeer Excel export here directly. Supports up to 200 patents. Cols A-E reserved for manual input helpers (row number, notes, E3 Continuation override, E2 override, E5 override). • Zone 3: Mapped Output + Bundle Results (cols AF onwards): auto-populates 42 v5 attributes via transform formulas. Amber cells = manual/AI scoring required. Completeness % column shows how complete each patent record is (0-42 attributes filled). 33 Bundle columns show TRUE/FALSE qualification respecting the active Configuration preset. Total column counts qualifying bundles per patent. • Conditional formatting: TRUE=green, FALSE=light-red in bundle cols; completeness traffic-light (green ≥60%, amber 30-60%, red <30%). • Workflow: paste PatSeer export → review amber cells → score manually or use AI prompts → copy completed rows to Patent Portfolio sheet for full Scorecard analysis.

Sheet PatSeer Import
A1: PATSEER IMPORT — Paste your PatSeer export, get bundle results instantly
A2: v6 Addition · Companion to PatSeer Standard/Premier/Pro X export · Outright sale context — short lifecycle portfolios
A4: Step 1 | B4: In PatSeer, export your portfolio as Excel/CSV. Select these field groups: Bibliographic + Parties + Classifications + Family + Citations + Other/Scores.
A5: Step 2 | B5: In the Paste Area (rows 40+), paste your PatSeer export starting at the correct column headers (row 39). Column order must match row 39.
A6: Step 3 | B6: The Mapped Output (right of paste area) auto-populates attributes derived from PatSeer. Amber-highlighted cells = manual scoring required.
A7: Step 4 | B7: Bundle Results columns show TRUE/FALSE qualification per bundle, respecting the active Configuration preset. Review and copy useful patents to Patent Portfolio.
A8: Step 5 | B8: The Column Mapping Table (rows 7-36 below) maps each PatSeer field to its v5 attribute. Edit col A if your PatSeer headers differ — all formulas update automatically.
A10: COLUMN MAPPING TABLE — Edit Col A if your PatSeer headers differ. All formulas update automatically.
A11: PatSeer Export Column Header | B11: Maps to v5 Attribute | C11: Transform Rule | D11: Notes / Instructions
A12: Publication Number | B12: Patent ID | C12: direct | D12: Use as Patent ID; or create your own ID in col A
A13: Title | B13: A1 (derived) | C13: direct | D13: Patent title — used as Title in Patent Portfolio
A14: Assignee (Current) | B14: — | C14: direct | D14: Current owner — stored in paste area; not a v5 attribute
A15: Inventor Names | B15: — | C15: direct | D15: Inventors — stored in paste area; not a v5 attribute
A16: Filing Date | B16: — | C16: year_from_date | D16: Filing year — informational only
A17: Publication Date | B17: — | C17: year_from_date | D17: Publication year — informational only
A18: Estimated Expiry Date | B18: E4 (derived) | C18: expiry_to_yrs | D18: Converted to remaining term in years from today
A19: Remaining Life (Years) | B19: E4 | C19: numeric | D19: Direct remaining term — preferred over Expiry Date if available
A20: Legal Status | B20: E2 | C20: legal_status_map | D20: Granted / Pending / Expired → maps to E2 Prosecution field
A21: Maintenance Status | B21: E5 | C21: direct | D21: Active / Lapsed / Abandoned → E5 Maint. status
A22: IPC (Main) | B22: A1 (derived) | C22: direct | D22: Main IPC → used to derive A1 Primary domain via CPC→domain lookup
... A35: Kind Code | B35: E3 (derived) | C35: direct | D35: Kind code (B2 / C2 = granted; A1/A2 = application) → E3 hint
A36: PASTE AREA — Paste your PatSeer Excel export here (row 40 onwards). Header row 39 must match your export column names exactly. | AE36: MAPPED OUTPUT — Auto-populated from Paste Area via Column Mapping. Amber = manual scoring required. Bundle columns respect active Configuration preset.
A37: → How to paste: In PatSeer export Excel, select ALL data including header row 1. Copy. Click cell F40 in this sheet. Paste. Then clear row 40 if it duplicated the header. | AE37: 42 Attributes — PatSeer-derived fields auto-fill; AMBER cells need manual / AI scoring (see AI_Prompts_for_Attribute_Scoring.md) | BU37: Complete-ness | BW37: 33 Bundle Qualifications — TRUE = patent qualifies (respects Configuration sheet preset)
A38: → Paste area supports up to 200 patents (rows 40–239). For more, add rows and extend formulas in the Mapped Output zone. | AE38: ID / Title | AG38: A. Technology | AL38: B. Standards | AO38: C. Claims | AS38: D. Detectability | AV38: E. Family/Life | BA38: F. Geography | BD38: G. Strategic | BG38: H. Quality | BQ38: I. Market
A39: # | B39: Your Notes | C39: E3 Continuation (Yes/No) | D39: E2 Prosecution Override | E39: E5 Maint. Status Override | F39: Publication Number | G39: Title | H39: Assignee (Current) | I39: Inventor Names | J39: Filing Date | K39: Publication Date | L39: Estimated Expiry Date | M39: Remaining Life (Years) | N39: Legal Status | O39: Maintenance Status | P39: IPC (Main) | Q39: IPC (All) | R39: CPC (Main) | S39: CPC (All) | T39: Simple Family Size | U39: Simple Family Members | V39: Extended Family Size | W39: Forward Citation Count | X39: Backward Citation Count | Y39: Independent Claim Count | Z39: Abstract | AA39: Technology Domain | AB39: Technology Sub-Domain | AC39: Kind Code | AD39: Litigation / PTAB Flag | AE39: Patent ID | AF39: Title | AG39: A1 | AH39: A2 | AI39: A3 | AJ39: A4 | AK39: A5 | AL39: B1 | AM39: B2 | AN39: B3 | AO39: C1 | AP39: C2 | AQ39: C3 | AR39: C4 | AS39: D1 | AT39: D2 | AU39: D3 | AV39: E1 | AW39: E2 | AX39: E3 | AY39: E4 | AZ39: E5 | BA39: F1 | BB39: F2 | BC39: F3 | BD39: G1 | BE39: G2 | BF39: G3 | BG39: H1 | BH39: H2 | BI39: H3 | BJ39: H4 | BK39: H5 | BL39: H6 | BM39: H7 | BN39: H8 | BO39: H9 | BP39: H10 | BQ39: I1 | BR39: I2 | BS39: I3 | BT39: I4 | BU39: Completeness % | BW39: B1 Tech Domain | BX39: B2 SEP | BY39: B3 Product Arch | BZ39: B4 Stack Layer | CA39: B5 Use-Case | CB39: B6 Mfg/Process | CC39: B7 Materials | CD39: B8 Algorithm | CE39: B9 Interop | CF39: B10 Generational | CG39: B11 Claim-Type | CH39: B12 Detectable | CI39: B13 Geographic | CJ39: B14 Family | CK39: B15 Lifecycle | CL39: B16 Foundational+Impr | CM39: B17 Cross-Industry | CN39: B18 Convergent Theme | CO39: B19 Defensive | CP39: B20 Whitespace | CQ39: B21 Prosecution-Status | CR39: B22 Anchor+Halo | CS39: B23 Picket-Fence | CT39: B24 Strong+Tail | CU39: B25 Continuation-Live | CV39: B26 EoU-Backed | CW39: B27 Battle-Tested | CX39: B28 Clean-Title | CY39: B29 High-Citation | CZ39: B30 Adjacent Re-Read | DA39: B31 Salvage-Volume | DB39: B32 Pre-Expiry | DC39: B33 Provenance | DD39: # Bundles
A40: 1 | AE40: =IFERROR(IF(F40<>"",F40,""),"") | AF40: =IFERROR(IF(G40<>"",G40,""),"") | AG40: =IFERROR(IF(AA40<>"",AA40,IF(R40<>"",R40,"")),"") | AH40: =IFERROR(IF(AB40<>"",AB40,IF(S40<>"",S40,"")),"") | AQ40: =IFERROR(IF(Y40<>"",VALUE(Y40),""),"") | AV40: =IFERROR(IF(T40<>"",VALUE(T40),""),"") | AW40: =IFERROR(IF(N40="","",IF(OR(ISNUMBER(SEARCH("grant",N40)),ISNUMBER(SEARCH("B",AC40))),"Granted",IF(OR(ISNUMBER(SEARCH("pend",N40)),ISNUMBER(SEARCH("A",AC40))),"Pending",IF(ISNUMBER(SEARCH("expir",N40)),"Expired",N40)))),"") | AY40: =IFERROR(IF(M40<>"",ROUND(VALUE(M40),1),IF(L40<>"",ROUND(MAX(0,(DATEVALUE(TEXT(L40,"YYYY-MM-DD"))-TODAY())/365.25),1),"")),"") | AZ40: =IFERROR(IF(O40<>"",O40,""),"") | BA40: =IFERROR(IF(U40<>"",SUBSTITUTE(SUBSTITUTE(U40,"; ",", "),";",","),""),"") | BK40: =IFERROR(IF(W40<>"",VALUE(W40),""),"") | BL40: =IFERROR(IF(X40<>"",VALUE(X40),""),"") | BM40: =IFERROR(IF(AD40="","None",IF(ISNUMBER(SEARCH("surv",AD40)),"Survived",IF(ISNUMBER(SEARCH("pend",AD40)),"Pending",IF(ISNUMBER(SEARCH("yes",AD40)),"Pending","None")))),"None") -> None | BU40: =IFERROR(COUNTA(AE40:BT40)/42,0) -> 0.30952381 | BW40: =IF(Configuration!$C$10="No","",IFERROR(IF(AG40<>"",TRUE(),FALSE()),FALSE())) -> FALSE | BX40: =IF(Configuration!$C$11="No","",IFERROR(IF(AND(N(AL40)>=Configuration!$C$44,AM40<>""),TRUE(),FALSE()),FALSE())) -> FALSE | BY40: =IF(Configuration!$C$12="No","",IFERROR(IF(AJ40<>"",TRUE(),FALSE()),FALSE())) -> FALSE | BZ40: =IF(Configuration!$C$13="No","",IFERROR(IF(AI40<>"",TRUE(),FALSE()),FALSE())) -> FALSE | CA40: =IF(Configuration!$C$14="No","",IFERROR(IF(AK40<>"",TRUE(),FALSE()),FALSE())) -> FALSE | CB40: =IF(Configuration!$C$15="No","",IFERROR(IF(AND(OR(ISNUMBER(SEARCH("process",AG40)),ISNUMBER(SEARCH("fab",AG40)),ISNUMBER(SEARCH("manufac",AG40))),AO40="Method"),TRUE(),FALSE()),FALSE())) -> FALSE | CC40: =IF(Configuration!$C$16="No","",IFERROR(IF(AND(OR(ISNUMBER(SEARCH("material",AG40)),ISNUMBER(SEARCH("chem",AG40)),ISNUMBER(SEARCH("battery",AG40)),ISNUMBER(SEARCH("electrolyte",AG40)),ISNUMBER(SEARCH("polymer",AG40))),OR(AO40="Apparatus",AO40="Method")),TRUE(),FALSE()),FALSE())) -> FALSE | CD40: =IF(Configuration!$C$17="No","",IFERROR(IF(AND(OR(AI40="App",AI40="Middleware",AI40="Cloud"),OR(AO40="Method",AO40="CRM")),TRUE(),FALSE()),FALSE())) -> FALSE | CE40: =IF(Configuration!$C$18="No","",IFERROR(IF(N(AN40)>=Configuration!$C$45,TRUE(),FALSE()),FALSE())) -> FALSE | CF40: =IF(Configuration!$C$19="No","",IFERROR(IF(BE40<>"",TRUE(),FALSE()),FALSE())) -> FALSE | CG40: =IF(Configuration!$C$20="No","",IFERROR(IF(AO40<>"",TRUE(),FALSE()),FALSE())) -> FALSE | CH40: =IF(Configuration!$C$21="No","",IFERROR(IF(OR(N(AS40)>=Configuration!$C$46,N(AT40)>=Configuration!$C$47),TRUE(),FALSE()),FALSE())) -> FALSE | CI40: =IF(Configuration!$C$22="No","",IFERROR(IF(BB40="Yes",TRUE(),FALSE()),FALSE())) -> FALSE | CJ40: =IF(Configuration!$C$23="No","",IFERROR(IF(N(AV40)>=Configuration!$C$48,TRUE(),FALSE()),FALSE())) -> FALSE | CK40: =IF(Configuration!$C$24="No","",IFERROR(IF(N(AY40)>0,TRUE(),FALSE()),FALSE())) -> FALSE | CL40: =IF(Configuration!$C$25="No","",IFERROR(IF(OR(N(AP40)=3,N(AP40)<=1),TRUE(),FALSE()),FALSE())) -> TRUE | CM40: =IF(Configuration!$C$26="No","",IFERROR(IF(N(BF40)>=Configuration!$C$49,TRUE(),FALSE()),FALSE())) -> FALSE | CN40: =IF(Configuration!$C$27="No","",IFERROR(IF(BD40<>"",TRUE(),FALSE()),FALSE())) -> FALSE | CO40: =IF(Configuration!$C$28="No","",IFERROR(IF(N(AU40)>=Configuration!$C$50,TRUE(),FALSE()),FALSE())) -> FALSE | CP40: =IF(Configuration!$C$29="No","",IFERROR(IF(AND(N(AR40)>=Configuration!$C$51,AG40<>""),TRUE(),FALSE()),FALSE())) -> FALSE | CQ40: =IF(Configuration!$C$30="No","",IFERROR(IF(OR(AW40="Pending",AX40="Yes"),TRUE(),FALSE()),FALSE())) -> FALSE | CR40: =IF(Configuration!$C$31="No","",IFERROR(IF(AND(N(BG40)>=Configuration!$C$52,N(AP40)>=1),TRUE(),FALSE()),FALSE())) -> FALSE | CS40: =IF(Configuration!$C$32="No","",IFERROR(IF(AND(N(AR40)>=1,OR(AG40<>"",AM40<>"")),TRUE(),FALSE()),FALSE())) -> FALSE | CT40: =IF(Configuration!$C$33="No","",IFERROR(IF(AG40<>"",TRUE(),FALSE()),FALSE())) -> FALSE | CU40: =IF(Configuration!$C$34="No","",IFERROR(IF(AX40="Yes",TRUE(),FALSE()),FALSE())) -> FALSE | CV40: =IF(Configuration!$C$35="No","",IFERROR(IF(OR(BO40="Partial",BO40="Full"),TRUE(),FALSE()),FALSE())) -> FALSE | CW40: =IF(Configuration!$C$36="No","",IFERROR(IF(BM40="Survived",TRUE(),FALSE()),FALSE())) -> FALSE | CX40: =IF(Configuration!$C$37="No","",IFERROR(IF(AND(BN40="Clean",BP40="None"),TRUE(),FALSE()),FALSE())) -> FALSE | CY40: =IF(Configuration!$C$38="No","",IFERROR(IF(N(BK40)>=Configuration!$C$53,TRUE(),FALSE()),FALSE())) -> FALSE | CZ40: =IF(Configuration!$C$39="No","",IFERROR(IF(AND(N(BS40)>=2,N(BF40)>=2),TRUE(),FALSE()),FALSE())) -> FALSE | DA40: =IF(Configuration!$C$40="No","",IFERROR(IF(OR(N(BG40)<=Configuration!$C$56,N(AY40)<Configuration!$C$57,N(BH40)<=Configuration!$C$58),TRUE(),FALSE()),FALSE())) -> TRUE | DB40: =IF(Configuration!$C$41="No","",IFERROR(IF(AND(N(AY40)>=Configuration!$C$54,N(AY40)<=Configuration!$C$55),TRUE(),FALSE()),FALSE())) -> FALSE | DC40: =IF(Configuration!$C$42="No","",IFERROR(IF(AND(AG40<>"",AJ40<>""),TRUE(),FALSE()),FALSE())) -> FALSE | DD40: =COUNTIF(BW40:DC40,TRUE()) -> 2
A41: 2 | AE41: =IFERROR(IF(F41<>"",F41,""),"") | AF41: =IFERROR(IF(G41<>"",G41,""),"") | AG41: =IFERROR(IF(AA41<>"",AA41,IF(R41<>"",R41,"")),"") | AH41: =IFERROR(IF(AB41<>"",AB41,IF(S41<>"",S41,"")),"") | AQ41: =IFERROR(IF(Y41<>"",VALUE(Y41),""),"") | AV41: =IFERROR(IF(T41<>"",VALUE(T41),""),"") | AW41: =IFERROR(IF(N41="","",IF(OR(ISNUMBER(SEARCH("grant",N41)),ISNUMBER(SEARCH("B",AC41))),"Granted",IF(OR(ISNUMBER(SEARCH("pend",N41)),ISNUMBER(SEARCH("A",AC41))),"Pending",IF(ISNUMBER(SEARCH("expir",N41)),"Expired",N41)))),"") | AY41: =IFERROR(IF(M41<>"",ROUND(VALUE(M41),1),IF(L41<>"",ROUND(MAX(0,(DATEVALUE(TEXT(L41,"YYYY-MM-DD"))-TODAY())/365.25),1),"")),"") | AZ41: =IFERROR(IF(O41<>"",O41,""),"") | BA41: =IFERROR(IF(U41<>"",SUBSTITUTE(SUBSTITUTE(U41,"; ",", "),";",","),""),"") | BK41: =IFERROR(IF(W41<>"",VALUE(W41),""),"") | BL41: =IFERROR(IF(X41<>"",VALUE(X41),""),"") | BM41: =IFERROR(IF(AD41="","None",IF(ISNUMBER(SEARCH("surv",AD41)),"Survived",IF(ISNUMBER(SEARCH("pend",AD41)),"Pending",IF(ISNUMBER(SEARCH("yes",AD41)),"Pending","None")))),"None") -> None | BU41: =IFERROR(COUNTA(AE41:BT41)/42,0) -> 0.30952381 | BW41: =IF(Configuration!$C$10="No","",IFERROR(IF(AG41<>"",TRUE(),FALSE()),FALSE())) -> FALSE | BX41: =IF(Configuration!$C$11="No","",IFERROR(IF(AND(N(AL41)>=Configuration!$C$44,AM41<>""),TRUE(),FALSE()),FALSE())) -> FALSE | BY41: =IF(Configuration!$C$12="No","",IFERROR(IF(AJ41<>"",TRUE(),FALSE()),FALSE())) -> FALSE | BZ41: =IF(Configuration!$C$13="No","",IFERROR(IF(AI41<>"",TRUE(),FALSE()),FALSE())) -> FALSE | CA41: =IF(Configuration!$C$14="No","",IFERROR(IF(AK41<>"",TRUE(),FALSE()),FALSE())) -> FALSE | CB41: =IF(Configuration!$C$15="No","",IFERROR(IF(AND(OR(ISNUMBER(SEARCH("process",AG41)),ISNUMBER(SEARCH("fab",AG41)),ISNUMBER(SEARCH("manufac",AG41))),AO41="Method"),TRUE(),FALSE()),FALSE())) -> FALSE | CC41: =IF(Configuration!$C$16="No","",IFERROR(IF(AND(OR(ISNUMBER(SEARCH("material",AG41)),ISNUMBER(SEARCH("chem",AG41)),ISNUMBER(SEARCH("battery",AG41)),ISNUMBER(SEARCH("electrolyte",AG41)),ISNUMBER(SEARCH("polymer",AG41))),OR(AO41="Apparatus",AO41="Method")),TRUE(),FALSE()),FALSE())) -> FALSE | CD41: =IF(Configuration!$C$17="No","",IFERROR(IF(AND(OR(AI41="App",AI41="Middleware",AI41="Cloud"),OR(AO41="Method",AO41="CRM")),TRUE(),FALSE()),FALSE())) -> FALSE | CE41: =IF(Configuration!$C$18="No","",IFERROR(IF(N(AN41)>=Configuration!$C$45,TRUE(),FALSE()),FALSE())) -> FALSE | CF41: =IF(Configuration!$C$19="No","",IFERROR(IF(BE41<>"",TRUE(),FALSE()),FALSE())) -> FALSE | CG41: =IF(Configuration!$C$20="No","",IFERROR(IF(AO41<>"",TRUE(),FALSE()),FALSE())) -> FALSE | CH41: =IF(Configuration!$C$21="No","",IFERROR(IF(OR(N(AS41)>=Configuration!$C$46,N(AT41)>=Configuration!$C$47),TRUE(),FALSE()),FALSE())) -> FALSE | CI41: =IF(Configuration!$C$22="No","",IFERROR(IF(BB41="Yes",TRUE(),FALSE()),FALSE())) -> FALSE | CJ41: =IF(Configuration!$C$23="No","",IFERROR(IF(N(AV41)>=Configuration!$C$48,TRUE(),FALSE()),FALSE())) -> FALSE | CK41: =IF(Configuration!$C$24="No","",IFERROR(IF(N(AY41)>0,TRUE(),FALSE()),FALSE())) -> FALSE | CL41: =IF(Configuration!$C$25="No","",IFERROR(IF(OR(N(AP41)=3,N(AP41)<=1),TRUE(),FALSE()),FALSE())) -> TRUE | CM41: =IF(Configuration!$C$26="No","",IFERROR(IF(N(BF41)>=Configuration!$C$49,TRUE(),FALSE()),FALSE())) -> FALSE | CN41: =IF(Configuration!$C$27="No","",IFERROR(IF(BD41<>"",TRUE(),FALSE()),FALSE())) -> FALSE | CO41: =IF(Configuration!$C$28="No","",IFERROR(IF(N(AU41)>=Configuration!$C$50,TRUE(),FALSE()),FALSE())) -> FALSE | CP41: =IF(Configuration!$C$29="No","",IFERROR(IF(AND(N(AR41)>=Configuration!$C$51,AG41<>""),TRUE(),FALSE()),FALSE())) -> FALSE | CQ41: =IF(Configuration!$C$30="No","",IFERROR(IF(OR(AW41="Pending",AX41="Yes"),TRUE(),FALSE()),FALSE())) -> FALSE | CR41: =IF(Configuration!$C$31="No","",IFERROR(IF(AND(N(BG41)>=Configuration!$C$52,N(AP41)>=1),TRUE(),FALSE()),FALSE())) -> FALSE | CS41: =IF(Configuration!$C$32="No","",IFERROR(IF(AND(N(AR41)>=1,OR(AG41<>"",AM41<>"")),TRUE(),FALSE()),FALSE())) -> FALSE | CT41: =IF(Configuration!$C$33="No","",IFERROR(IF(AG41<>"",TRUE(),FALSE()),FALSE())) -> FALSE | CU41: =IF(Configuration!$C$34="No","",IFERROR(IF(AX41="Yes",TRUE(),FALSE()),FALSE())) -> FALSE | CV41: =IF(Configuration!$C$35="No","",IFERROR(IF(OR(BO41="Partial",BO41="Full"),TRUE(),FALSE()),FALSE())) -> FALSE | CW41: =IF(Configuration!$C$36="No","",IFERROR(IF(BM41="Survived",TRUE(),FALSE()),FALSE())) -> FALSE | CX41: =IF(Configuration!$C$37="No","",IFERROR(IF(AND(BN41="Clean",BP41="None"),TRUE(),FALSE()),FALSE())) -> FALSE | CY41: =IF(Configuration!$C$38="No","",IFERROR(IF(N(BK41)>=Configuration!$C$53,TRUE(),FALSE()),FALSE())) -> FALSE | CZ41: =IF(Configuration!$C$39="No","",IFERROR(IF(AND(N(BS41)>=2,N(BF41)>=2),TRUE(),FALSE()),FALSE())) -> FALSE | DA41: =IF(Configuration!$C$40="No","",IFERROR(IF(OR(N(BG41)<=Configuration!$C$56,N(AY41)<Configuration!$C$57,N(BH41)<=Configuration!$C$58),TRUE(),FALSE()),FALSE())) -> TRUE | DB41: =IF(Configuration!$C$41="No","",IFERROR(IF(AND(N(AY41)>=Configuration!$C$54,N(AY41)<=Configuration!$C$55),TRUE(),FALSE()),FALSE())) -> FALSE | DC41: =IF(Configuration!$C$42="No","",IFERROR(IF(AND(AG41<>"",AJ41<>""),TRUE(),FALSE()),FALSE())) -> FALSE | DD41: =COUNTIF(BW41:DC41,TRUE()) -> 2
A42: 3 | AE42: =IFERROR(IF(F42<>"",F42,""),"") | AF42: =IFERROR(IF(G42<>"",G42,""),"") | AG42: =IFERROR(IF(AA42<>"",AA42,IF(R42<>"",R42,"")),"") | AH42: =IFERROR(IF(AB42<>"",AB42,IF(S42<>"",S42,"")),"") | AQ42: =IFERROR(IF(Y42<>"",VALUE(Y42),""),"") | AV42: =IFERROR(IF(T42<>"",VALUE(T42),""),"") | AW42: =IFERROR(IF(N42="","",IF(OR(ISNUMBER(SEARCH("grant",N42)),ISNUMBER(SEARCH("B",AC42))),"Granted",IF(OR(ISNUMBER(SEARCH("pend",N42)),ISNUMBER(SEARCH("A",AC42))),"Pending",IF(ISNUMBER(SEARCH("expir",N42)),"Expired",N42)))),"") | AY42: =IFERROR(IF(M42<>"",ROUND(VALUE(M42),1),IF(L42<>"",ROUND(MAX(0,(DATEVALUE(TEXT(L42,"YYYY-MM-DD"))-TODAY())/365.25),1),"")),"") | AZ42: =IFERROR(IF(O42<>"",O42,""),"") | BA42: =IFERROR(IF(U42<>"",SUBSTITUTE(SUBSTITUTE(U42,"; ",", "),";",","),""),"") | BK42: =IFERROR(IF(W42<>"",VALUE(W42),""),"") | BL42: =IFERROR(IF(X42<>"",VALUE(X42),""),"") | BM42: =IFERROR(IF(AD42="","None",IF(ISNUMBER(SEARCH("surv",AD42)),"Survived",IF(ISNUMBER(SEARCH("pend",AD42)),"Pending",IF(ISNUMBER(SEARCH("yes",AD42)),"Pending","None")))),"None") -> None | BU42: =IFERROR(COUNTA(AE42:BT42)/42,0) -> 0.30952381 | BW42: =IF(Configuration!$C$10="No","",IFERROR(IF(AG42<>"",TRUE(),FALSE()),FALSE())) -> FALSE | BX42: =IF(Configuration!$C$11="No","",IFERROR(IF(AND(N(AL42)>=Configuration!$C$44,AM42<>""),TRUE(),FALSE()),FALSE())) -> FALSE | BY42: =IF(Configuration!$C$12="No","",IFERROR(IF(AJ42<>"",TRUE(),FALSE()),FALSE())) -> FALSE | BZ42: =IF(Configuration!$C$13="No","",IFERROR(IF(AI42<>"",TRUE(),FALSE()),FALSE())) -> FALSE | CA42: =IF(Configuration!$C$14="No","",IFERROR(IF(AK42<>"",TRUE(),FALSE()),FALSE())) -> FALSE | CB42: =IF(Configuration!$C$15="No","",IFERROR(IF(AND(OR(ISNUMBER(SEARCH("process",AG42)),ISNUMBER(SEARCH("fab",AG42)),ISNUMBER(SEARCH("manufac",AG42))),AO42="Method"),TRUE(),FALSE()),FALSE())) -> FALSE | CC42: =IF(Configuration!$C$16="No","",IFERROR(IF(AND(OR(ISNUMBER(SEARCH("material",AG42)),ISNUMBER(SEARCH("chem",AG42)),ISNUMBER(SEARCH("battery",AG42)),ISNUMBER(SEARCH("electrolyte",AG42)),ISNUMBER(SEARCH("polymer",AG42))),OR(AO42="Apparatus",AO42="Method")),TRUE(),FALSE()),FALSE())) -> FALSE | CD42: =IF(Configuration!$C$17="No","",IFERROR(IF(AND(OR(AI42="App",AI42="Middleware",AI42="Cloud"),OR(AO42="Method",AO42="CRM")),TRUE(),FALSE()),FALSE())) -> FALSE | CE42: =IF(Configuration!$C$18="No","",IFERROR(IF(N(AN42)>=Configuration!$C$45,TRUE(),FALSE()),FALSE())) -> FALSE | CF42: =IF(Configuration!$C$19="No","",IFERROR(IF(BE42<>"",TRUE(),FALSE()),FALSE())) -> FALSE | CG42: =IF(Configuration!$C$20="No","",IFERROR(IF(AO42<>"",TRUE(),FALSE()),FALSE())) -> FALSE | CH42: =IF(Configuration!$C$21="No","",IFERROR(IF(OR(N(AS42)>=Configuration!$C$46,N(AT42)>=Configuration!$C$47),TRUE(),FALSE()),FALSE())) -> FALSE | CI42: =IF(Configuration!$C$22="No","",IFERROR(IF(BB42="Yes",TRUE(),FALSE()),FALSE())) -> FALSE | CJ42: =IF(Configuration!$C$23="No","",IFERROR(IF(N(AV42)>=Configuration!$C$48,TRUE(),FALSE()),FALSE())) -> FALSE | CK42: =IF(Configuration!$C$24="No","",IFERROR(IF(N(AY42)>0,TRUE(),FALSE()),FALSE())) -> FALSE | CL42: =IF(Configuration!$C$25="No","",IFERROR(IF(OR(N(AP42)=3,N(AP42)<=1),TRUE(),FALSE()),FALSE())) -> TRUE | CM42: =IF(Configuration!$C$26="No","",IFERROR(IF(N(BF42)>=Configuration!$C$49,TRUE(),FALSE()),FALSE())) -> FALSE | CN42: =IF(Configuration!$C$27="No","",IFERROR(IF(BD42<>"",TRUE(),FALSE()),FALSE())) -> FALSE | CO42: =IF(Configuration!$C$28="No","",IFERROR(IF(N(AU42)>=Configuration!$C$50,TRUE(),FALSE()),FALSE())) -> FALSE | CP42: =IF(Configuration!$C$29="No","",IFERROR(IF(AND(N(AR42)>=Configuration!$C$51,AG42<>""),TRUE(),FALSE()),FALSE())) -> FALSE | CQ42: =IF(Configuration!$C$30="No","",IFERROR(IF(OR(AW42="Pending",AX42="Yes"),TRUE(),FALSE()),FALSE())) -> FALSE | CR42: =IF(Configuration!$C$31="No","",IFERROR(IF(AND(N(BG42)>=Configuration!$C$52,N(AP42)>=1),TRUE(),FALSE()),FALSE())) -> FALSE | CS42: =IF(Configuration!$C$32="No","",IFERROR(IF(AND(N(AR42)>=1,OR(AG42<>"",AM42<>"")),TRUE(),FALSE()),FALSE())) -> FALSE | CT42: =IF(Configuration!$C$33="No","",IFERROR(IF(AG42<>"",TRUE(),FALSE()),FALSE())) -> FALSE | CU42: =IF(Configuration!$C$34="No","",IFERROR(IF(AX42="Yes",TRUE(),FALSE()),FALSE())) -> FALSE | CV42: =IF(Configuration!$C$35="No","",IFERROR(IF(OR(BO42="Partial",BO42="Full"),TRUE(),FALSE()),FALSE())) -> FALSE | CW42: =IF(Configuration!$C$36="No","",IFERROR(IF(BM42="Survived",TRUE(),FALSE()),FALSE())) -> FALSE | CX42: =IF(Configuration!$C$37="No","",IFERROR(IF(AND(BN42="Clean",BP42="None"),TRUE(),FALSE()),FALSE())) -> FALSE | CY42: =IF(Configuration!$C$38="No","",IFERROR(IF(N(BK42)>=Configuration!$C$53,TRUE(),FALSE()),FALSE())) -> FALSE | CZ42: =IF(Configuration!$C$39="No","",IFERROR(IF(AND(N(BS42)>=2,N(BF42)>=2),TRUE(),FALSE()),FALSE())) -> FALSE | DA42: =IF(Configuration!$C$40="No","",IFERROR(IF(OR(N(BG42)<=Configuration!$C$56,N(AY42)<Configuration!$C$57,N(BH42)<=Configuration!$C$58),TRUE(),FALSE()),FALSE())) -> TRUE | DB42: =IF(Configuration!$C$41="No","",IFERROR(IF(AND(N(AY42)>=Configuration!$C$54,N(AY42)<=Configuration!$C$55),TRUE(),FALSE()),FALSE())) -> FALSE | DC42: =IF(Configuration!$C$42="No","",IFERROR(IF(AND(AG42<>"",AJ42<>""),TRUE(),FALSE()),FALSE())) -> FALSE | DD42: =COUNTIF(BW42:DC42,TRUE()) -> 2
A43: 4 | AE43: =IFERROR(IF(F43<>"",F43,""),"") | AF43: =IFERROR(IF(G43<>"",G43,""),"") | AG43: =IFERROR(IF(AA43<>"",AA43,IF(R43<>"",R43,"")),"") | AH43: =IFERROR(IF(AB43<>"",AB43,IF(S43<>"",S43,"")),"") | AQ43: =IFERROR(IF(Y43<>"",VALUE(Y43),""),"") | AV43: =IFERROR(IF(T43<>"",VALUE(T43),""),"") | AW43: =IFERROR(IF(N43="","",IF(OR(ISNUMBER(SEARCH("grant",N43)),ISNUMBER(SEARCH("B",AC43))),"Granted",IF(OR(ISNUMBER(SEARCH("pend",N43)),ISNUMBER(SEARCH("A",AC43))),"Pending",IF(ISNUMBER(SEARCH("expir",N43)),"Expired",N43)))),"") | AY43: =IFERROR(IF(M43<>"",ROUND(VALUE(M43),1),IF(L43<>"",ROUND(MAX(0,(DATEVALUE(TEXT(L43,"YYYY-MM-DD"))-TODAY())/365.25),1),"")),"") | AZ43: =IFERROR(IF(O43<>"",O43,""),"") | BA43: =IFERROR(IF(U43<>"",SUBSTITUTE(SUBSTITUTE(U43,"; ",", "),";",","),""),"") | BK43: =IFERROR(IF(W43<>"",VALUE(W43),""),"") | BL43: =IFERROR(IF(X43<>"",VALUE(X43),""),"") | BM43: =IFERROR(IF(AD43="","None",IF(ISNUMBER(SEARCH("surv",AD43)),"Survived",IF(ISNUMBER(SEARCH("pend",AD43)),"Pending",IF(ISNUMBER(SEARCH("yes",AD43)),"Pending","None")))),"None") -> None | BU43: =IFERROR(COUNTA(AE43:BT43)/42,0) -> 0.30952381 | BW43: =IF(Configuration!$C$10="No","",IFERROR(IF(AG43<>"",TRUE(),FALSE()),FALSE())) -> FALSE | BX43: =IF(Configuration!$C$11="No","",IFERROR(IF(AND(N(AL43)>=Configuration!$C$44,AM43<>""),TRUE(),FALSE()),FALSE())) -> FALSE | BY43: =IF(Configuration!$C$12="No","",IFERROR(IF(AJ43<>"",TRUE(),FALSE()),FALSE())) -> FALSE | BZ43: =IF(Configuration!$C$13="No","",IFERROR(IF(AI43<>"",TRUE(),FALSE()),FALSE())) -> FALSE | CA43: =IF(Configuration!$C$14="No","",IFERROR(IF(AK43<>"",TRUE(),FALSE()),FALSE())) -> FALSE | CB43: =IF(Configuration!$C$15="No","",IFERROR(IF(AND(OR(ISNUMBER(SEARCH("process",AG43)),ISNUMBER(SEARCH("fab",AG43)),ISNUMBER(SEARCH("manufac",AG43))),AO43="Method"),TRUE(),FALSE()),FALSE())) -> FALSE | CC43: =IF(Configuration!$C$16="No","",IFERROR(IF(AND(OR(ISNUMBER(SEARCH("material",AG43)),ISNUMBER(SEARCH("chem",AG43)),ISNUMBER(SEARCH("battery",AG43)),ISNUMBER(SEARCH("electrolyte",AG43)),ISNUMBER(SEARCH("polymer",AG43))),OR(AO43="Apparatus",AO43="Method")),TRUE(),FALSE()),FALSE())) -> FALSE | CD43: =IF(Configuration!$C$17="No","",IFERROR(IF(AND(OR(AI43="App",AI43="Middleware",AI43="Cloud"),OR(AO43="Method",AO43="CRM")),TRUE(),FALSE()),FALSE())) -> FALSE | CE43: =IF(Configuration!$C$18="No","",IFERROR(IF(N(AN43)>=Configuration!$C$45,TRUE(),FALSE()),FALSE())) -> FALSE | CF43: =IF(Configuration!$C$19="No","",IFERROR(IF(BE43<>"",TRUE(),FALSE()),FALSE())) -> FALSE | CG43: =IF(Configuration!$C$20="No","",IFERROR(IF(AO43<>"",TRUE(),FALSE()),FALSE())) -> FALSE | CH43: =IF(Configuration!$C$21="No","",IFERROR(IF(OR(N(AS43)>=Configuration!$C$46,N(AT43)>=Configuration!$C$47),TRUE(),FALSE()),FALSE())) -> FALSE | CI43: =IF(Configuration!$C$22="No","",IFERROR(IF(BB43="Yes",TRUE(),FALSE()),FALSE())) -> FALSE | CJ43: =IF(Configuration!$C$23="No","",IFERROR(IF(N(AV43)>=Configuration!$C$48,TRUE(),FALSE()),FALSE())) -> FALSE | CK43: =IF(Configuration!$C$24="No","",IFERROR(IF(N(AY43)>0,TRUE(),FALSE()),FALSE())) -> FALSE | CL43: =IF(Configuration!$C$25="No","",IFERROR(IF(OR(N(AP43)=3,N(AP43)<=1),TRUE(),FALSE()),FALSE())) -> TRUE | CM43: =IF(Configuration!$C$26="No","",IFERROR(IF(N(BF43)>=Configuration!$C$49,TRUE(),FALSE()),FALSE())) -> FALSE | CN43: =IF(Configuration!$C$27="No","",IFERROR(IF(BD43<>"",TRUE(),FALSE()),FALSE())) -> FALSE | CO43: =IF(Configuration!$C$28="No","",IFERROR(IF(N(AU43)>=Configuration!$C$50,TRUE(),FALSE()),FALSE())) -> FALSE | CP43: =IF(Configuration!$C$29="No","",IFERROR(IF(AND(N(AR43)>=Configuration!$C$51,AG43<>""),TRUE(),FALSE()),FALSE())) -> FALSE | CQ43: =IF(Configuration!$C$30="No","",IFERROR(IF(OR(AW43="Pending",AX43="Yes"),TRUE(),FALSE()),FALSE())) -> FALSE | CR43: =IF(Configuration!$C$31="No","",IFERROR(IF(AND(N(BG43)>=Configuration!$C$52,N(AP43)>=1),TRUE(),FALSE()),FALSE())) -> FALSE | CS43: =IF(Configuration!$C$32="No","",IFERROR(IF(AND(N(AR43)>=1,OR(AG43<>"",AM43<>"")),TRUE(),FALSE()),FALSE())) -> FALSE | CT43: =IF(Configuration!$C$33="No","",IFERROR(IF(AG43<>"",TRUE(),FALSE()),FALSE())) -> FALSE | CU43: =IF(Configuration!$C$34="No","",IFERROR(IF(AX43="Yes",TRUE(),FALSE()),FALSE())) -> FALSE | CV43: =IF(Configuration!$C$35="No","",IFERROR(IF(OR(BO43="Partial",BO43="Full"),TRUE(),FALSE()),FALSE())) -> FALSE | CW43: =IF(Configuration!$C$36="No","",IFERROR(IF(BM43="Survived",TRUE(),FALSE()),FALSE())) -> FALSE | CX43: =IF(Configuration!$C$37="No","",IFERROR(IF(AND(BN43="Clean",BP43="None"),TRUE(),FALSE()),FALSE())) -> FALSE | CY43: =IF(Configuration!$C$38="No","",IFERROR(IF(N(BK43)>=Configuration!$C$53,TRUE(),FALSE()),FALSE())) -> FALSE | CZ43: =IF(Configuration!$C$39="No","",IFERROR(IF(AND(N(BS43)>=2,N(BF43)>=2),TRUE(),FALSE()),FALSE())) -> FALSE | DA43: =IF(Configuration!$C$40="No","",IFERROR(IF(OR(N(BG43)<=Configuration!$C$56,N(AY43)<Configuration!$C$57,N(BH43)<=Configuration!$C$58),TRUE(),FALSE()),FALSE())) -> TRUE | DB43: =IF(Configuration!$C$41="No","",IFERROR(IF(AND(N(AY43)>=Configuration!$C$54,N(AY43)<=Configuration!$C$55),TRUE(),FALSE()),FALSE())) -> FALSE | DC43: =IF(Configuration!$C$42="No","",IFERROR(IF(AND(AG43<>"",AJ43<>""),TRUE(),FALSE()),FALSE())) -> FALSE | DD43: =COUNTIF(BW43:DC43,TRUE()) -> 2
A44: 5 | AE44: =IFERROR(IF(F44<>"",F44,""),"") | AF44: =IFERROR(IF(G44<>"",G44,""),"") | AG44: =IFERROR(IF(AA44<>"",AA44,IF(R44<>"",R44,"")),"") | AH44: =IFERROR(IF(AB44<>"",AB44,IF(S44<>"",S44,"")),"") | AQ44: =IFERROR(IF(Y44<>"",VALUE(Y44),""),"") | AV44: =IFERROR(IF(T44<>"",VALUE(T44),""),"") | AW44: =IFERROR(IF(N44="","",IF(OR(ISNUMBER(SEARCH("grant",N44)),ISNUMBER(SEARCH("B",AC44))),"Granted",IF(OR(ISNUMBER(SEARCH("pend",N44)),ISNUMBER(SEARCH("A",AC44))),"Pending",IF(ISNUMBER(SEARCH("expir",N44)),"Expired",N44)))),"") | AY44: =IFERROR(IF(M44<>"",ROUND(VALUE(M44),1),IF(L44<>"",ROUND(MAX(0,(DATEVALUE(TEXT(L44,"YYYY-MM-DD"))-TODAY())/365.25),1),"")),"") | AZ44: =IFERROR(IF(O44<>"",O44,""),"") | BA44: =IFERROR(IF(U44<>"",SUBSTITUTE(SUBSTITUTE(U44,"; ",", "),";",","),""),"") | BK44: =IFERROR(IF(W44<>"",VALUE(W44),""),"") | BL44: =IFERROR(IF(X44<>"",VALUE(X44),""),"") | BM44: =IFERROR(IF(AD44="","None",IF(ISNUMBER(SEARCH("surv",AD44)),"Survived",IF(ISNUMBER(SEARCH("pend",AD44)),"Pending",IF(ISNUMBER(SEARCH("yes",AD44)),"Pending","None")))),"None") -> None | BU44: =IFERROR(COUNTA(AE44:BT44)/42,0) -> 0.30952381 | BW44: =IF(Configuration!$C$10="No","",IFERROR(IF(AG44<>"",TRUE(),FALSE()),FALSE())) -> FALSE | BX44: =IF(Configuration!$C$11="No","",IFERROR(IF(AND(N(AL44)>=Configuration!$C$44,AM44<>""),TRUE(),FALSE()),FALSE())) -> FALSE | BY44: =IF(Configuration!$C$12="No","",IFERROR(IF(AJ44<>"",TRUE(),FALSE()),FALSE())) -> FALSE | BZ44: =IF(Configuration!$C$13="No","",IFERROR(IF(AI44<>"",TRUE(),FALSE()),FALSE())) -> FALSE | CA44: =IF(Configuration!$C$14="No","",IFERROR(IF(AK44<>"",TRUE(),FALSE()),FALSE())) -> FALSE | CB44: =IF(Configuration!$C$15="No","",IFERROR(IF(AND(OR(ISNUMBER(SEARCH("process",AG44)),ISNUMBER(SEARCH("fab",AG44)),ISNUMBER(SEARCH("manufac",AG44))),AO44="Method"),TRUE(),FALSE()),FALSE())) -> FALSE | CC44: =IF(Configuration!$C$16="No","",IFERROR(IF(AND(OR(ISNUMBER(SEARCH("material",AG44)),ISNUMBER(SEARCH("chem",AG44)),ISNUMBER(SEARCH("battery",AG44)),ISNUMBER(SEARCH("electrolyte",AG44)),ISNUMBER(SEARCH("polymer",AG44))),OR(AO44="Apparatus",AO44="Method")),TRUE(),FALSE()),FALSE())) -> FALSE | CD44: =IF(Configuration!$C$17="No","",IFERROR(IF(AND(OR(AI44="App",AI44="Middleware",AI44="Cloud"),OR(AO44="Method",AO44="CRM")),TRUE(),FALSE()),FALSE())) -> FALSE | CE44: =IF(Configuration!$C$18="No","",IFERROR(IF(N(AN44)>=Configuration!$C$45,TRUE(),FALSE()),FALSE())) -> FALSE | CF44: =IF(Configuration!$C$19="No","",IFERROR(IF(BE44<>"",TRUE(),FALSE()),FALSE())) -> FALSE | CG44: =IF(Configuration!$C$20="No","",IFERROR(IF(AO44<>"",TRUE(),FALSE()),FALSE())) -> FALSE | CH44: =IF(Configuration!$C$21="No","",IFERROR(IF(OR(N(AS44)>=Configuration!$C$46,N(AT44)>=Configuration!$C$47),TRUE(),FALSE()),FALSE())) -> FALSE | CI44: =IF(Configuration!$C$22="No","",IFERROR(IF(BB44="Yes",TRUE(),FALSE()),FALSE())) -> FALSE | CJ44: =IF(Configuration!$C$23="No","",IFERROR(IF(N(AV44)>=Configuration!$C$48,TRUE(),FALSE()),FALSE())) -> FALSE | CK44: =IF(Configuration!$C$24="No","",IFERROR(IF(N(AY44)>0,TRUE(),FALSE()),FALSE())) -> FALSE | CL44: =IF(Configuration!$C$25="No","",IFERROR(IF(OR(N(AP44)=3,N(AP44)<=1),TRUE(),FALSE()),FALSE())) -> TRUE | CM44: =IF(Configuration!$C$26="No","",IFERROR(IF(N(BF44)>=Configuration!$C$49,TRUE(),FALSE()),FALSE())) -> FALSE | CN44: =IF(Configuration!$C$27="No","",IFERROR(IF(BD44<>"",TRUE(),FALSE()),FALSE())) -> FALSE | CO44: =IF(Configuration!$C$28="No","",IFERROR(IF(N(AU44)>=Configuration!$C$50,TRUE(),FALSE()),FALSE())) -> FALSE | CP44: =IF(Configuration!$C$29="No","",IFERROR(IF(AND(N(AR44)>=Configuration!$C$51,AG44<>""),TRUE(),FALSE()),FALSE())) -> FALSE | CQ44: =IF(Configuration!$C$30="No","",IFERROR(IF(OR(AW44="Pending",AX44="Yes"),TRUE(),FALSE()),FALSE())) -> FALSE | CR44: =IF(Configuration!$C$31="No","",IFERROR(IF(AND(N(BG44)>=Configuration!$C$52,N(AP44)>=1),TRUE(),FALSE()),FALSE())) -> FALSE | CS44: =IF(Configuration!$C$32="No","",IFERROR(IF(AND(N(AR44)>=1,OR(AG44<>"",AM44<>"")),TRUE(),FALSE()),FALSE())) -> FALSE | CT44: =IF(Configuration!$C$33="No","",IFERROR(IF(AG44<>"",TRUE(),FALSE()),FALSE())) -> FALSE | CU44: =IF(Configuration!$C$34="No","",IFERROR(IF(AX44="Yes",TRUE(),FALSE()),FALSE())) -> FALSE | CV44: =IF(Configuration!$C$35="No","",IFERROR(IF(OR(BO44="Partial",BO44="Full"),TRUE(),FALSE()),FALSE())) -> FALSE | CW44: =IF(Configuration!$C$36="No","",IFERROR(IF(BM44="Survived",TRUE(),FALSE()),FALSE())) -> FALSE | CX44: =IF(Configuration!$C$37="No","",IFERROR(IF(AND(BN44="Clean",BP44="None"),TRUE(),FALSE()),FALSE())) -> FALSE | CY44: =IF(Configuration!$C$38="No","",IFERROR(IF(N(BK44)>=Configuration!$C$53,TRUE(),FALSE()),FALSE())) -> FALSE | CZ44: =IF(Configuration!$C$39="No","",IFERROR(IF(AND(N(BS44)>=2,N(BF44)>=2),TRUE(),FALSE()),FALSE())) -> FALSE | DA44: =IF(Configuration!$C$40="No","",IFERROR(IF(OR(N(BG44)<=Configuration!$C$56,N(AY44)<Configuration!$C$57,N(BH44)<=Configuration!$C$58),TRUE(),FALSE()),FALSE())) -> TRUE | DB44: =IF(Configuration!$C$41="No","",IFERROR(IF(AND(N(AY44)>=Configuration!$C$54,N(AY44)<=Configuration!$C$55),TRUE(),FALSE()),FALSE())) -> FALSE | DC44: =IF(Configuration!$C$42="No","",IFERROR(IF(AND(AG44<>"",AJ44<>""),TRUE(),FALSE()),FALSE())) -> FALSE | DD44: =COUNTIF(BW44:DC44,TRUE()) -> 2
A45: 6 | AE45: =IFERROR(IF(F45<>"",F45,""),"") | AF45: =IFERROR(IF(G45<>"",G45,""),"") | AG45: =IFERROR(IF(AA45<>"",AA45,IF(R45<>"",R45,"")),"") | AH45: =IFERROR(IF(AB45<>"",AB45,IF(S45<>"",S45,"")),"") | AQ45: =IFERROR(IF(Y45<>"",VALUE(Y45),""),"") | AV45: =IFERROR(IF(T45<>"",VALUE(T45),""),"") | AW45: =IFERROR(IF(N45="","",IF(OR(ISNUMBER(SEARCH("grant",N45)),ISNUMBER(SEARCH("B",AC45))),"Granted",IF(OR(ISNUMBER(SEARCH("pend",N45)),ISNUMBER(SEARCH("A",AC45))),"Pending",IF(ISNUMBER(SEARCH("expir",N45)),"Expired",N45)))),"") | AY45: =IFERROR(IF(M45<>"",ROUND(VALUE(M45),1),IF(L45<>"",ROUND(MAX(0,(DATEVALUE(TEXT(L45,"YYYY-MM-DD"))-TODAY())/365.25),1),"")),"") | AZ45: =IFERROR(IF(O45<>"",O45,""),"") | BA45: =IFERROR(IF(U45<>"",SUBSTITUTE(SUBSTITUTE(U45,"; ",", "),";",","),""),"") | BK45: =IFERROR(IF(W45<>"",VALUE(W45),""),"") | BL45: =IFERROR(IF(X45<>"",VALUE(X45),""),"") | BM45: =IFERROR(IF(AD45="","None",IF(ISNUMBER(SEARCH("surv",AD45)),"Survived",IF(ISNUMBER(SEARCH("pend",AD45)),"Pending",IF(ISNUMBER(SEARCH("yes",AD45)),"Pending","None")))),"None") -> None | BU45: =IFERROR(COUNTA(AE45:BT45)/42,0) -> 0.30952381 | BW45: =IF(Configuration!$C$10="No","",IFERROR(IF(AG45<>"",TRUE(),FALSE()),FALSE())) -> FALSE | BX45: =IF(Configuration!$C$11="No","",IFERROR(IF(AND(N(AL45)>=Configuration!$C$44,AM45<>""),TRUE(),FALSE()),FALSE())) -> FALSE | BY45: =IF(Configuration!$C$12="No","",IFERROR(IF(AJ45<>"",TRUE(),FALSE()),FALSE())) -> FALSE | BZ45: =IF(Configuration!$C$13="No","",IFERROR(IF(AI45<>"",TRUE(),FALSE()),FALSE())) -> FALSE | CA45: =IF(Configuration!$C$14="No","",IFERROR(IF(AK45<>"",TRUE(),FALSE()),FALSE())) -> FALSE | CB45: =IF(Configuration!$C$15="No","",IFERROR(IF(AND(OR(ISNUMBER(SEARCH("process",AG45)),ISNUMBER(SEARCH("fab",AG45)),ISNUMBER(SEARCH("manufac",AG45))),AO45="Method"),TRUE(),FALSE()),FALSE())) -> FALSE | CC45: =IF(Configuration!$C$16="No","",IFERROR(IF(AND(OR(ISNUMBER(SEARCH("material",AG45)),ISNUMBER(SEARCH("chem",AG45)),ISNUMBER(SEARCH("battery",AG45)),ISNUMBER(SEARCH("electrolyte",AG45)),ISNUMBER(SEARCH("polymer",AG45))),OR(AO45="Apparatus",AO45="Method")),TRUE(),FALSE()),FALSE())) -> FALSE | CD45: =IF(Configuration!$C$17="No","",IFERROR(IF(AND(OR(AI45="App",AI45="Middleware",AI45="Cloud"),OR(AO45="Method",AO45="CRM")),TRUE(),FALSE()),FALSE())) -> FALSE | CE45: =IF(Configuration!$C$18="No","",IFERROR(IF(N(AN45)>=Configuration!$C$45,TRUE(),FALSE()),FALSE())) -> FALSE | CF45: =IF(Configuration!$C$19="No","",IFERROR(IF(BE45<>"",TRUE(),FALSE()),FALSE())) -> FALSE | CG45: =IF(Configuration!$C$20="No","",IFERROR(IF(AO45<>"",TRUE(),FALSE()),FALSE())) -> FALSE | CH45: =IF(Configuration!$C$21="No","",IFERROR(IF(OR(N(AS45)>=Configuration!$C$46,N(AT45)>=Configuration!$C$47),TRUE(),FALSE()),FALSE())) -> FALSE | CI45: =IF(Configuration!$C$22="No","",IFERROR(IF(BB45="Yes",TRUE(),FALSE()),FALSE())) -> FALSE | CJ45: =IF(Configuration!$C$23="No","",IFERROR(IF(N(AV45)>=Configuration!$C$48,TRUE(),FALSE()),FALSE())) -> FALSE | CK45: =IF(Configuration!$C$24="No","",IFERROR(IF(N(AY45)>0,TRUE(),FALSE()),FALSE())) -> FALSE | CL45: =IF(Configuration!$C$25="No","",IFERROR(IF(OR(N(AP45)=3,N(AP45)<=1),TRUE(),FALSE()),FALSE())) -> TRUE | CM45: =IF(Configuration!$C$26="No","",IFERROR(IF(N(BF45)>=Configuration!$C$49,TRUE(),FALSE()),FALSE())) -> FALSE | CN45: =IF(Configuration!$C$27="No","",IFERROR(IF(BD45<>"",TRUE(),FALSE()),FALSE())) -> FALSE | CO45: =IF(Configuration!$C$28="No","",IFERROR(IF(N(AU45)>=Configuration!$C$50,TRUE(),FALSE()),FALSE())) -> FALSE | CP45: =IF(Configuration!$C$29="No","",IFERROR(IF(AND(N(AR45)>=Configuration!$C$51,AG45<>""),TRUE(),FALSE()),FALSE())) -> FALSE | CQ45: =IF(Configuration!$C$30="No","",IFERROR(IF(OR(AW45="Pending",AX45="Yes"),TRUE(),FALSE()),FALSE())) -> FALSE | CR45: =IF(Configuration!$C$31="No","",IFERROR(IF(AND(N(BG45)>=Configuration!$C$52,N(AP45)>=1),TRUE(),FALSE()),FALSE())) -> FALSE | CS45: =IF(Configuration!$C$32="No","",IFERROR(IF(AND(N(AR45)>=1,OR(AG45<>"",AM45<>"")),TRUE(),FALSE()),FALSE())) -> FALSE | CT45: =IF(Configuration!$C$33="No","",IFERROR(IF(AG45<>"",TRUE(),FALSE()),FALSE())) -> FALSE | CU45: =IF(Configuration!$C$34="No","",IFERROR(IF(AX45="Yes",TRUE(),FALSE()),FALSE())) -> FALSE | CV45: =IF(Configuration!$C$35="No","",IFERROR(IF(OR(BO45="Partial",BO45="Full"),TRUE(),FALSE()),FALSE())) -> FALSE | CW45: =IF(Configuration!$C$36="No","",IFERROR(IF(BM45="Survived",TRUE(),FALSE()),FALSE())) -> FALSE | CX45: =IF(Configuration!$C$37="No","",IFERROR(IF(AND(BN45="Clean",BP45="None"),TRUE(),FALSE()),FALSE())) -> FALSE | CY45: =IF(Configuration!$C$38="No","",IFERROR(IF(N(BK45)>=Configuration!$C$53,TRUE(),FALSE()),FALSE())) -> FALSE | CZ45: =IF(Configuration!$C$39="No","",IFERROR(IF(AND(N(BS45)>=2,N(BF45)>=2),TRUE(),FALSE()),FALSE())) -> FALSE | DA45: =IF(Configuration!$C$40="No","",IFERROR(IF(OR(N(BG45)<=Configuration!$C$56,N(AY45)<Configuration!$C$57,N(BH45)<=Configuration!$C$58),TRUE(),FALSE()),FALSE())) -> TRUE | DB45: =IF(Configuration!$C$41="No","",IFERROR(IF(AND(N(AY45)>=Configuration!$C$54,N(AY45)<=Configuration!$C$55),TRUE(),FALSE()),FALSE())) -> FALSE | DC45: =IF(Configuration!$C$42="No","",IFERROR(IF(AND(AG45<>"",AJ45<>""),TRUE(),FALSE()),FALSE())) -> FALSE | DD45: =COUNTIF(BW45:DC45,TRUE()) -> 2
A46: 7 | AE46: =IFERROR(IF(F46<>"",F46,""),"") | AF46: =IFERROR(IF(G46<>"",G46,""),"") | AG46: =IFERROR(IF(AA46<>"",AA46,IF(R46<>"",R46,"")),"") | AH46: =IFERROR(IF(AB46<>"",AB46,IF(S46<>"",S46,"")),"") | AQ46: =IFERROR(IF(Y46<>"",VALUE(Y46),""),"") | AV46: =IFERROR(IF(T46<>"",VALUE(T46),""),"") | AW46: =IFERROR(IF(N46="","",IF(OR(ISNUMBER(SEARCH("grant",N46)),ISNUMBER(SEARCH("B",AC46))),"Granted",IF(OR(ISNUMBER(SEARCH("pend",N46)),ISNUMBER(SEARCH("A",AC46))),"Pending",IF(ISNUMBER(SEARCH("expir",N46)),"Expired",N46)))),"") | AY46: =IFERROR(IF(M46<>"",ROUND(VALUE(M46),1),IF(L46<>"",ROUND(MAX(0,(DATEVALUE(TEXT(L46,"YYYY-MM-DD"))-TODAY())/365.25),1),"")),"") | AZ46: =IFERROR(IF(O46<>"",O46,""),"") | BA46: =IFERROR(IF(U46<>"",SUBSTITUTE(SUBSTITUTE(U46,"; ",", "),";",","),""),"") | BK46: =IFERROR(IF(W46<>"",VALUE(W46),""),"") | BL46: =IFERROR(IF(X46<>"",VALUE(X46),""),"") | BM46: =IFERROR(IF(AD46="","None",IF(ISNUMBER(SEARCH("surv",AD46)),"Survived",IF(ISNUMBER(SEARCH("pend",AD46)),"Pending",IF(ISNUMBER(SEARCH("yes",AD46)),"Pending","None")))),"None") -> None | BU46: =IFERROR(COUNTA(AE46:BT46)/42,0) -> 0.30952381 | BW46: =IF(Configuration!$C$10="No","",IFERROR(IF(AG46<>"",TRUE(),FALSE()),FALSE())) -> FALSE | BX46: =IF(Configuration!$C$11="No","",IFERROR(IF(AND(N(AL46)>=Configuration!$C$44,AM46<>""),TRUE(),FALSE()),FALSE())) -> FALSE | BY46: =IF(Configuration!$C$12="No","",IFERROR(IF(AJ46<>"",TRUE(),FALSE()),FALSE())) -> FALSE | BZ46: =IF(Configuration!$C$13="No","",IFERROR(IF(AI46<>"",TRUE(),FALSE()),FALSE())) -> FALSE | CA46: =IF(Configuration!$C$14="No","",IFERROR(IF(AK46<>"",TRUE(),FALSE()),FALSE())) -> FALSE | CB46: =IF(Configuration!$C$15="No","",IFERROR(IF(AND(OR(ISNUMBER(SEARCH("process",AG46)),ISNUMBER(SEARCH("fab",AG46)),ISNUMBER(SEARCH("manufac",AG46))),AO46="Method"),TRUE(),FALSE()),FALSE())) -> FALSE | CC46: =IF(Configuration!$C$16="No","",IFERROR(IF(AND(OR(ISNUMBER(SEARCH("material",AG46)),ISNUMBER(SEARCH("chem",AG46)),ISNUMBER(SEARCH("battery",AG46)),ISNUMBER(SEARCH("electrolyte",AG46)),ISNUMBER(SEARCH("polymer",AG46))),OR(AO46="Apparatus",AO46="Method")),TRUE(),FALSE()),FALSE())) -> FALSE | CD46: =IF(Configuration!$C$17="No","",IFERROR(IF(AND(OR(AI46="App",AI46="Middleware",AI46="Cloud"),OR(AO46="Method",AO46="CRM")),TRUE(),FALSE()),FALSE())) -> FALSE | CE46: =IF(Configuration!$C$18="No","",IFERROR(IF(N(AN46)>=Configuration!$C$45,TRUE(),FALSE()),FALSE())) -> FALSE | CF46: =IF(Configuration!$C$19="No","",IFERROR(IF(BE46<>"",TRUE(),FALSE()),FALSE())) -> FALSE | CG46: =IF(Configuration!$C$20="No","",IFERROR(IF(AO46<>"",TRUE(),FALSE()),FALSE())) -> FALSE | CH46: =IF(Configuration!$C$21="No","",IFERROR(IF(OR(N(AS46)>=Configuration!$C$46,N(AT46)>=Configuration!$C$47),TRUE(),FALSE()),FALSE())) -> FALSE | CI46: =IF(Configuration!$C$22="No","",IFERROR(IF(BB46="Yes",TRUE(),FALSE()),FALSE())) -> FALSE | CJ46: =IF(Configuration!$C$23="No","",IFERROR(IF(N(AV46)>=Configuration!$C$48,TRUE(),FALSE()),FALSE())) -> FALSE | CK46: =IF(Configuration!$C$24="No","",IFERROR(IF(N(AY46)>0,TRUE(),FALSE()),FALSE())) -> FALSE | CL46: =IF(Configuration!$C$25="No","",IFERROR(IF(OR(N(AP46)=3,N(AP46)<=1),TRUE(),FALSE()),FALSE())) -> TRUE | CM46: =IF(Configuration!$C$26="No","",IFERROR(IF(N(BF46)>=Configuration!$C$49,TRUE(),FALSE()),FALSE())) -> FALSE | CN46: =IF(Configuration!$C$27="No","",IFERROR(IF(BD46<>"",TRUE(),FALSE()),FALSE())) -> FALSE | CO46: =IF(Configuration!$C$28="No","",IFERROR(IF(N(AU46)>=Configuration!$C$50,TRUE(),FALSE()),FALSE())) -> FALSE | CP46: =IF(Configuration!$C$29="No","",IFERROR(IF(AND(N(AR46)>=Configuration!$C$51,AG46<>""),TRUE(),FALSE()),FALSE())) -> FALSE | CQ46: =IF(Configuration!$C$30="No","",IFERROR(IF(OR(AW46="Pending",AX46="Yes"),TRUE(),FALSE()),FALSE())) -> FALSE | CR46: =IF(Configuration!$C$31="No","",IFERROR(IF(AND(N(BG46)>=Configuration!$C$52,N(AP46)>=1),TRUE(),FALSE()),FALSE())) -> FALSE | CS46: =IF(Configuration!$C$32="No","",IFERROR(IF(AND(N(AR46)>=1,OR(AG46<>"",AM46<>"")),TRUE(),FALSE()),FALSE())) -> FALSE | CT46: =IF(Configuration!$C$33="No","",IFERROR(IF(AG46<>"",TRUE(),FALSE()),FALSE())) -> FALSE | CU46: =IF(Configuration!$C$34="No","",IFERROR(IF(AX46="Yes",TRUE(),FALSE()),FALSE())) -> FALSE | CV46: =IF(Configuration!$C$35="No","",IFERROR(IF(OR(BO46="Partial",BO46="Full"),TRUE(),FALSE()),FALSE())) -> FALSE | CW46: =IF(Configuration!$C$36="No","",IFERROR(IF(BM46="Survived",TRUE(),FALSE()),FALSE())) -> FALSE | CX46: =IF(Configuration!$C$37="No","",IFERROR(IF(AND(BN46="Clean",BP46="None"),TRUE(),FALSE()),FALSE())) -> FALSE | CY46: =IF(Configuration!$C$38="No","",IFERROR(IF(N(BK46)>=Configuration!$C$53,TRUE(),FALSE()),FALSE())) -> FALSE | CZ46: =IF(Configuration!$C$39="No","",IFERROR(IF(AND(N(BS46)>=2,N(BF46)>=2),TRUE(),FALSE()),FALSE())) -> FALSE | DA46: =IF(Configuration!$C$40="No","",IFERROR(IF(OR(N(BG46)<=Configuration!$C$56,N(AY46)<Configuration!$C$57,N(BH46)<=Configuration!$C$58),TRUE(),FALSE()),FALSE())) -> TRUE | DB46: =IF(Configuration!$C$41="No","",IFERROR(IF(AND(N(AY46)>=Configuration!$C$54,N(AY46)<=Configuration!$C$55),TRUE(),FALSE()),FALSE())) -> FALSE | DC46: =IF(Configuration!$C$42="No","",IFERROR(IF(AND(AG46<>"",AJ46<>""),TRUE(),FALSE()),FALSE())) -> FALSE | DD46: =COUNTIF(BW46:DC46,TRUE()) -> 2
A47: 8 | AE47: =IFERROR(IF(F47<>"",F47,""),"") | AF47: =IFERROR(IF(G47<>"",G47,""),"") | AG47: =IFERROR(IF(AA47<>"",AA47,IF(R47<>"",R47,"")),"") | AH47: =IFERROR(IF(AB47<>"",AB47,IF(S47<>"",S47,"")),"") | AQ47: =IFERROR(IF(Y47<>"",VALUE(Y47),""),"") | AV47: =IFERROR(IF(T47<>"",VALUE(T47),""),"") | AW47: =IFERROR(IF(N47="","",IF(OR(ISNUMBER(SEARCH("grant",N47)),ISNUMBER(SEARCH("B",AC47))),"Granted",IF(OR(ISNUMBER(SEARCH("pend",N47)),ISNUMBER(SEARCH("A",AC47))),"Pending",IF(ISNUMBER(SEARCH("expir",N47)),"Expired",N47)))),"") | AY47: =IFERROR(IF(M47<>"",ROUND(VALUE(M47),1),IF(L47<>"",ROUND(MAX(0,(DATEVALUE(TEXT(L47,"YYYY-MM-DD"))-TODAY())/365.25),1),"")),"") | AZ47: =IFERROR(IF(O47<>"",O47,""),"") | BA47: =IFERROR(IF(U47<>"",SUBSTITUTE(SUBSTITUTE(U47,"; ",", "),";",","),""),"") | BK47: =IFERROR(IF(W47<>"",VALUE(W47),""),"") | BL47: =IFERROR(IF(X47<>"",VALUE(X47),""),"") | BM47: =IFERROR(IF(AD47="","None",IF(ISNUMBER(SEARCH("surv",AD47)),"Survived",IF(ISNUMBER(SEARCH("pend",AD47)),"Pending",IF(ISNUMBER(SEARCH("yes",AD47)),"Pending","None")))),"None") -> None | BU47: =IFERROR(COUNTA(AE47:BT47)/42,0) -> 0.30952381 | BW47: =IF(Configuration!$C$10="No","",IFERROR(IF(AG47<>"",TRUE(),FALSE()),FALSE())) -> FALSE | BX47: =IF(Configuration!$C$11="No","",IFERROR(IF(AND(N(AL47)>=Configuration!$C$44,AM47<>""),TRUE(),FALSE()),FALSE())) -> FALSE | BY47: =IF(Configuration!$C$12="No","",IFERROR(IF(AJ47<>"",TRUE(),FALSE()),FALSE())) -> FALSE | BZ47: =IF(Configuration!$C$13="No","",IFERROR(IF(AI47<>"",TRUE(),FALSE()),FALSE())) -> FALSE | CA47: =IF(Configuration!$C$14="No","",IFERROR(IF(AK47<>"",TRUE(),FALSE()),FALSE())) -> FALSE | CB47: =IF(Configuration!$C$15="No","",IFERROR(IF(AND(OR(ISNUMBER(SEARCH("process",AG47)),ISNUMBER(SEARCH("fab",AG47)),ISNUMBER(SEARCH("manufac",AG47))),AO47="Method"),TRUE(),FALSE()),FALSE())) -> FALSE | CC47: =IF(Configuration!$C$16="No","",IFERROR(IF(AND(OR(ISNUMBER(SEARCH("material",AG47)),ISNUMBER(SEARCH("chem",AG47)),ISNUMBER(SEARCH("battery",AG47)),ISNUMBER(SEARCH("electrolyte",AG47)),ISNUMBER(SEARCH("polymer",AG47))),OR(AO47="Apparatus",AO47="Method")),TRUE(),FALSE()),FALSE())) -> FALSE | CD47: =IF(Configuration!$C$17="No","",IFERROR(IF(AND(OR(AI47="App",AI47="Middleware",AI47="Cloud"),OR(AO47="Method",AO47="CRM")),TRUE(),FALSE()),FALSE())) -> FALSE | CE47: =IF(Configuration!$C$18="No","",IFERROR(IF(N(AN47)>=Configuration!$C$45,TRUE(),FALSE()),FALSE())) -> FALSE | CF47: =IF(Configuration!$C$19="No","",IFERROR(IF(BE47<>"",TRUE(),FALSE()),FALSE())) -> FALSE | CG47: =IF(Configuration!$C$20="No","",IFERROR(IF(AO47<>"",TRUE(),FALSE()),FALSE())) -> FALSE | CH47: =IF(Configuration!$C$21="No","",IFERROR(IF(OR(N(AS47)>=Configuration!$C$46,N(AT47)>=Configuration!$C$47),TRUE(),FALSE()),FALSE())) -> FALSE | CI47: =IF(Configuration!$C$22="No","",IFERROR(IF(BB47="Yes",TRUE(),FALSE()),FALSE())) -> FALSE | CJ47: =IF(Configuration!$C$23="No","",IFERROR(IF(N(AV47)>=Configuration!$C$48,TRUE(),FALSE()),FALSE())) -> FALSE | CK47: =IF(Configuration!$C$24="No","",IFERROR(IF(N(AY47)>0,TRUE(),FALSE()),FALSE())) -> FALSE | CL47: =IF(Configuration!$C$25="No","",IFERROR(IF(OR(N(AP47)=3,N(AP47)<=1),TRUE(),FALSE()),FALSE())) -> TRUE | CM47: =IF(Configuration!$C$26="No","",IFERROR(IF(N(BF47)>=Configuration!$C$49,TRUE(),FALSE()),FALSE())) -> FALSE | CN47: =IF(Configuration!$C$27="No","",IFERROR(IF(BD47<>"",TRUE(),FALSE()),FALSE())) -> FALSE | CO47: =IF(Configuration!$C$28="No","",IFERROR(IF(N(AU47)>=Configuration!$C$50,TRUE(),FALSE()),FALSE())) -> FALSE | CP47: =IF(Configuration!$C$29="No","",IFERROR(IF(AND(N(AR47)>=Configuration!$C$51,AG47<>""),TRUE(),FALSE()),FALSE())) -> FALSE | CQ47: =IF(Configuration!$C$30="No","",IFERROR(IF(OR(AW47="Pending",AX47="Yes"),TRUE(),FALSE()),FALSE())) -> FALSE | CR47: =IF(Configuration!$C$31="No","",IFERROR(IF(AND(N(BG47)>=Configuration!$C$52,N(AP47)>=1),TRUE(),FALSE()),FALSE())) -> FALSE | CS47: =IF(Configuration!$C$32="No","",IFERROR(IF(AND(N(AR47)>=1,OR(AG47<>"",AM47<>"")),TRUE(),FALSE()),FALSE())) -> FALSE | CT47: =IF(Configuration!$C$33="No","",IFERROR(IF(AG47<>"",TRUE(),FALSE()),FALSE())) -> FALSE | CU47: =IF(Configuration!$C$34="No","",IFERROR(IF(AX47="Yes",TRUE(),FALSE()),FALSE())) -> FALSE | CV47: =IF(Configuration!$C$35="No","",IFERROR(IF(OR(BO47="Partial",BO47="Full"),TRUE(),FALSE()),FALSE())) -> FALSE | CW47: =IF(Configuration!$C$36="No","",IFERROR(IF(BM47="Survived",TRUE(),FALSE()),FALSE())) -> FALSE | CX47: =IF(Configuration!$C$37="No","",IFERROR(IF(AND(BN47="Clean",BP47="None"),TRUE(),FALSE()),FALSE())) -> FALSE | CY47: =IF(Configuration!$C$38="No","",IFERROR(IF(N(BK47)>=Configuration!$C$53,TRUE(),FALSE()),FALSE())) -> FALSE | CZ47: =IF(Configuration!$C$39="No","",IFERROR(IF(AND(N(BS47)>=2,N(BF47)>=2),TRUE(),FALSE()),FALSE())) -> FALSE | DA47: =IF(Configuration!$C$40="No","",IFERROR(IF(OR(N(BG47)<=Configuration!$C$56,N(AY47)<Configuration!$C$57,N(BH47)<=Configuration!$C$58),TRUE(),FALSE()),FALSE())) -> TRUE | DB47: =IF(Configuration!$C$41="No","",IFERROR(IF(AND(N(AY47)>=Configuration!$C$54,N(AY47)<=Configuration!$C$55),TRUE(),FALSE()),FALSE())) -> FALSE | DC47: =IF(Configuration!$C$42="No","",IFERROR(IF(AND(AG47<>"",AJ47<>""),TRUE(),FALSE()),FALSE())) -> FALSE | DD47: =COUNTIF(BW47:DC47,TRUE()) -> 2
A48: 9 | AE48: =IFERROR(IF(F48<>"",F48,""),"") | AF48: =IFERROR(IF(G48<>"",G48,""),"") | AG48: =IFERROR(IF(AA48<>"",AA48,IF(R48<>"",R48,"")),"") | AH48: =IFERROR(IF(AB48<>"",AB48,IF(S48<>"",S48,"")),"") | AQ48: =IFERROR(IF(Y48<>"",VALUE(Y48),""),"") | AV48: =IFERROR(IF(T48<>"",VALUE(T48),""),"") | AW48: =IFERROR(IF(N48="","",IF(OR(ISNUMBER(SEARCH("grant",N48)),ISNUMBER(SEARCH("B",AC48))),"Granted",IF(OR(ISNUMBER(SEARCH("pend",N48)),ISNUMBER(SEARCH("A",AC48))),"Pending",IF(ISNUMBER(SEARCH("expir",N48)),"Expired",N48)))),"") | AY48: =IFERROR(IF(M48<>"",ROUND(VALUE(M48),1),IF(L48<>"",ROUND(MAX(0,(DATEVALUE(TEXT(L48,"YYYY-MM-DD"))-TODAY())/365.25),1),"")),"") | AZ48: =IFERROR(IF(O48<>"",O48,""),"") | BA48: =IFERROR(IF(U48<>"",SUBSTITUTE(SUBSTITUTE(U48,"; ",", "),";",","),""),"") | BK48: =IFERROR(IF(W48<>"",VALUE(W48),""),"") | BL48: =IFERROR(IF(X48<>"",VALUE(X48),""),"") | BM48: =IFERROR(IF(AD48="","None",IF(ISNUMBER(SEARCH("surv",AD48)),"Survived",IF(ISNUMBER(SEARCH("pend",AD48)),"Pending",IF(ISNUMBER(SEARCH("yes",AD48)),"Pending","None")))),"None") -> None | BU48: =IFERROR(COUNTA(AE48:BT48)/42,0) -> 0.30952381 | BW48: =IF(Configuration!$C$10="No","",IFERROR(IF(AG48<>"",TRUE(),FALSE()),FALSE())) -> FALSE | BX48: =IF(Configuration!$C$11="No","",IFERROR(IF(AND(N(AL48)>=Configuration!$C$44,AM48<>""),TRUE(),FALSE()),FALSE())) -> FALSE | BY48: =IF(Configuration!$C$12="No","",IFERROR(IF(AJ48<>"",TRUE(),FALSE()),FALSE())) -> FALSE | BZ48: =IF(Configuration!$C$13="No","",IFERROR(IF(AI48<>"",TRUE(),FALSE()),FALSE())) -> FALSE | CA48: =IF(Configuration!$C$14="No","",IFERROR(IF(AK48<>"",TRUE(),FALSE()),FALSE())) -> FALSE | CB48: =IF(Configuration!$C$15="No","",IFERROR(IF(AND(OR(ISNUMBER(SEARCH("process",AG48)),ISNUMBER(SEARCH("fab",AG48)),ISNUMBER(SEARCH("manufac",AG48))),AO48="Method"),TRUE(),FALSE()),FALSE())) -> FALSE | CC48: =IF(Configuration!$C$16="No","",IFERROR(IF(AND(OR(ISNUMBER(SEARCH("material",AG48)),ISNUMBER(SEARCH("chem",AG48)),ISNUMBER(SEARCH("battery",AG48)),ISNUMBER(SEARCH("electrolyte",AG48)),ISNUMBER(SEARCH("polymer",AG48))),OR(AO48="Apparatus",AO48="Method")),TRUE(),FALSE()),FALSE())) -> FALSE | CD48: =IF(Configuration!$C$17="No","",IFERROR(IF(AND(OR(AI48="App",AI48="Middleware",AI48="Cloud"),OR(AO48="Method",AO48="CRM")),TRUE(),FALSE()),FALSE())) -> FALSE | CE48: =IF(Configuration!$C$18="No","",IFERROR(IF(N(AN48)>=Configuration!$C$45,TRUE(),FALSE()),FALSE())) -> FALSE | CF48: =IF(Configuration!$C$19="No","",IFERROR(IF(BE48<>"",TRUE(),FALSE()),FALSE())) -> FALSE | CG48: =IF(Configuration!$C$20="No","",IFERROR(IF(AO48<>"",TRUE(),FALSE()),FALSE())) -> FALSE | CH48: =IF(Configuration!$C$21="No","",IFERROR(IF(OR(N(AS48)>=Configuration!$C$46,N(AT48)>=Configuration!$C$47),TRUE(),FALSE()),FALSE())) -> FALSE | CI48: =IF(Configuration!$C$22="No","",IFERROR(IF(BB48="Yes",TRUE(),FALSE()),FALSE())) -> FALSE | CJ48: =IF(Configuration!$C$23="No","",IFERROR(IF(N(AV48)>=Configuration!$C$48,TRUE(),FALSE()),FALSE())) -> FALSE | CK48: =IF(Configuration!$C$24="No","",IFERROR(IF(N(AY48)>0,TRUE(),FALSE()),FALSE())) -> FALSE | CL48: =IF(Configuration!$C$25="No","",IFERROR(IF(OR(N(AP48)=3,N(AP48)<=1),TRUE(),FALSE()),FALSE())) -> TRUE | CM48: =IF(Configuration!$C$26="No","",IFERROR(IF(N(BF48)>=Configuration!$C$49,TRUE(),FALSE()),FALSE())) -> FALSE | CN48: =IF(Configuration!$C$27="No","",IFERROR(IF(BD48<>"",TRUE(),FALSE()),FALSE())) -> FALSE | CO48: =IF(Configuration!$C$28="No","",IFERROR(IF(N(AU48)>=Configuration!$C$50,TRUE(),FALSE()),FALSE())) -> FALSE | CP48: =IF(Configuration!$C$29="No","",IFERROR(IF(AND(N(AR48)>=Configuration!$C$51,AG48<>""),TRUE(),FALSE()),FALSE())) -> FALSE | CQ48: =IF(Configuration!$C$30="No","",IFERROR(IF(OR(AW48="Pending",AX48="Yes"),TRUE(),FALSE()),FALSE())) -> FALSE | CR48: =IF(Configuration!$C$31="No","",IFERROR(IF(AND(N(BG48)>=Configuration!$C$52,N(AP48)>=1),TRUE(),FALSE()),FALSE())) -> FALSE | CS48: =IF(Configuration!$C$32="No","",IFERROR(IF(AND(N(AR48)>=1,OR(AG48<>"",AM48<>"")),TRUE(),FALSE()),FALSE())) -> FALSE | CT48: =IF(Configuration!$C$33="No","",IFERROR(IF(AG48<>"",TRUE(),FALSE()),FALSE())) -> FALSE | CU48: =IF(Configuration!$C$34="No","",IFERROR(IF(AX48="Yes",TRUE(),FALSE()),FALSE())) -> FALSE | CV48: =IF(Configuration!$C$35="No","",IFERROR(IF(OR(BO48="Partial",BO48="Full"),TRUE(),FALSE()),FALSE())) -> FALSE | CW48: =IF(Configuration!$C$36="No","",IFERROR(IF(BM48="Survived",TRUE(),FALSE()),FALSE())) -> FALSE | CX48: =IF(Configuration!$C$37="No","",IFERROR(IF(AND(BN48="Clean",BP48="None"),TRUE(),FALSE()),FALSE())) -> FALSE | CY48: =IF(Configuration!$C$38="No","",IFERROR(IF(N(BK48)>=Configuration!$C$53,TRUE(),FALSE()),FALSE())) -> FALSE | CZ48: =IF(Configuration!$C$39="No","",IFERROR(IF(AND(N(BS48)>=2,N(BF48)>=2),TRUE(),FALSE()),FALSE())) -> FALSE | DA48: =IF(Configuration!$C$40="No","",IFERROR(IF(OR(N(BG48)<=Configuration!$C$56,N(AY48)<Configuration!$C$57,N(BH48)<=Configuration!$C$58),TRUE(),FALSE()),FALSE())) -> TRUE | DB48: =IF(Configuration!$C$41="No","",IFERROR(IF(AND(N(AY48)>=Configuration!$C$54,N(AY48)<=Configuration!$C$55),TRUE(),FALSE()),FALSE())) -> FALSE | DC48: =IF(Configuration!$C$42="No","",IFERROR(IF(AND(AG48<>"",AJ48<>""),TRUE(),FALSE()),FALSE())) -> FALSE | DD48: =COUNTIF(BW48:DC48,TRUE()) -> 2
