Workbook

Sheet README
A1: PATENT PORTFOLIO BUNDLING TEMPLATE
A2: A technical-attribute-based framework for grouping patents into sellable bundles
A4: PURPOSE
A5: Score each patent across technical attributes, then auto-route patents into one or more sellable bundle types based on logical rules. The framework is purely technical — no valuation, no pricing.
A7: SHEETS IN THIS WORKBOOK
A8: 1. README — This page. Overview and instructions.
A9: 2. Attribute Dictionary — Definitions and scoring scales for every attribute.
A10: 3. Patent Portfolio — Master data sheet. One row per patent. Fill this in.
A11: 4. Bundle Rules — The 21 bundle types and the routing rule that qualifies a patent for each.
A12: 5. Bundle Assignment — Auto-computed: which bundles each patent qualifies for.
A13: 6. Bundle Quality Scorecard — Auto-computed: quality indicators per bundle.
A14: 7. Sample Bundles — Worked examples showing how three bundles look in practice.
... A42: New "Bundle Composition Strategy" sheet — tiered structure, anchor-first, storyline, complementary-weakness, modular, carve-in/out, reserve, buyer-profile, continuation-optionality overlays.

Sheet Attribute Dictionary
A1: Group | B1: Code | C1: Attribute | D1: Description | E1: Scale / Values | F1: Example
A2: A. Technology Classification | B2: A1 | C2: Primary technology domain | D2: Main CPC/IPC classification or internal taxonomy tag. | E2: Categorical text | F2: Wireless PHY
A3: A. Technology Classification | B3: A2 | C3: Secondary domains | D3: Cross-applicable technical areas the patent also touches. | E3: Comma-separated tags | F3: Beamforming, MIMO
A4: A. Technology Classification | B4: A3 | C4: Stack layer | D4: Horizontal layer of the technology stack. | E4: Hardware / Firmware / OS / Middleware / App / Cloud / UI | F4: Hardware
A5: A. Technology Classification | B5: A4 | C5: Product subsystem | D5: Which subsystem(s) of an end-product it covers. | E5: Free-text / list | F5: Battery management
A6: A. Technology Classification | B6: A5 | C6: Use-case | D6: Real-world problem(s) it solves. | E6: Free-text / list | F6: Indoor positioning
A7: B. Standards & Ecosystem | B7: B1 | C7: SEP potential | D7: Standard-essential potential. | E7: 0 (none) → 3 (declared/strong mapping) | F7: 3
A8: B. Standards & Ecosystem | B8: B2 | C8: Standard tagged | D8: Specific standard(s) the patent maps to. | E8: Categorical text | F8: 3GPP 5G NR
A9: B. Standards & Ecosystem | B9: B3 | C9: Interface role | D9: Role as an interoperability/interface technology. | E9: 0 (internal only) → 3 (mandatory interface) | F9: 2
A10: C. Claim & Scope | B10: C1 | C10: Claim type | D10: Dominant claim type. | E10: Apparatus / Method / System / CRM / Design | F10: Method
A11: C. Claim & Scope | B11: C2 | C11: Claim breadth | D11: How broad/foundational the independent claims are. | E11: 0 (narrow) → 3 (foundational/pioneer) | F11: 2
A12: C. Claim & Scope | B12: C3 | C12: Independent claim count | D12: Number of independent claims. | E12: Integer | F12: 3
... A41: I. Market/Buyer Signals | B41: I4 | C41: Workaround complexity | D41: Engineering effort needed for a competitor to design around the claims. | E41: 0 (trivial) → 3 (deep redesign) | F41: 3

Sheet Patent Portfolio
A1: Identification | C1: A. Technology Classification | H1: B. Standards | K1: C. Claim & Scope | O1: D. Detectability | R1: E. Family & Lifecycle | W1: F. Geographic | Z1: G. Strategic | AC1: H. Patent Quality & Vulnerability | AM1: I. Market/Buyer Signals
A2: Patent ID | B2: Title | C2: A1 Primary domain | D2: A2 Secondary domains | E2: A3 Stack layer | F2: A4 Subsystem | G2: A5 Use-case | H2: B1 SEP potential (0-3) | I2: B2 Standard | J2: B3 Interface role (0-3) | K2: C1 Claim type | L2: C2 Claim breadth (0-3) | M2: C3 Indep. claim count | N2: C4 Design-around diff. (0-3) | O2: D1 External detect. (0-3) | P2: D2 Teardown detect. (0-3) | Q2: D3 Reads-on-products (0-3) | R2: E1 Family size | S2: E2 Prosecution | T2: E3 Continuation | U2: E4 Remaining term (yrs) | V2: E5 Maint. status | W2: F1 Jurisdictions | X2: F2 Trilateral (Y/N) | Y2: F3 Major-market score (0-3) | Z2: G1 Convergence theme | AA2: G2 Generation | AB2: G3 Cross-industry (0-3) | AC2: H1 Claim strength (0-3) | AD2: H2 Prior-art exposure (0-3) | AE2: H3 Prosecution risk (0-3) | AF2: H4 Divided-infrgmnt (0-3) | AG2: H5 Fwd citations | AH2: H6 Bwd citations | AI2: H7 Lit/PTAB history | AJ2: H8 Chain-of-title | AK2: H9 EoU available | AL2: H10 Encumbrance | AM2: I1 Product-map conf. (0-3) | AN2: I2 Impl. maturity | AO2: I3 Adjacent re-read (0-3) | AP2: I4 Workaround complex. (0-3)
A3: P-001 | B3: Beamforming pilot signaling for 5G NR | C3: Wireless PHY | D3: MIMO, beamforming | E3: Hardware | F3: Radio frontend | G3: Cellular comms | H3: 3 | I3: 3GPP 5G NR | J3: 3 | K3: Method | L3: 2 | M3: 3 | N3: 3 | O3: 1 | P3: 3 | Q3: 3 | R3: 8 | S3: Granted | T3: Yes | U3: 14 | V3: Active | W3: US, EP, CN, JP, KR | X3: Yes | Y3: 3 | AA3: Current | AB3: 1 | AC3: 3 | AD3: 3 | AE3: 2 | AF3: 3 | AG3: 28 | AH3: 42 | AI3: Survived | AJ3: Clean | AK3: Full | AL3: None | AM3: 3 | AN3: Productized | AO3: 1 | AP3: 3
A4: P-002 | B4: Polar code decoder architecture | C4: Wireless PHY | D4: Error correction | E4: Hardware | F4: Baseband processor | G4: Cellular comms | H4: 3 | I4: 3GPP 5G NR | J4: 2 | K4: Apparatus | L4: 2 | M4: 2 | N4: 2 | O4: 0 | P4: 3 | Q4: 3 | R4: 5 | S4: Granted | T4: No | U4: 13 | V4: Active | W4: US, EP, CN, KR | X4: Yes | Y4: 3 | AA4: Current | AB4: 1 | AC4: 2 | AD4: 2 | AE4: 2 | AF4: 3 | AG4: 18 | AH4: 31 | AI4: None | AJ4: Clean | AK4: Partial | AL4: None | AM4: 3 | AN4: Productized | AO4: 1 | AP4: 2
A5: P-003 | B5: Adaptive Wi-Fi 7 channel sounding | C5: Wireless PHY | D5: OFDMA | E5: Firmware | F5: WLAN module | G5: Indoor connectivity | H5: 2 | I5: IEEE 802.11be | J5: 3 | K5: Method | L5: 1 | M5: 2 | N5: 2 | O5: 1 | P5: 2 | Q5: 2 | R5: 4 | S5: Mixed | T5: Yes | U5: 17 | V5: Active | W5: US, EP, CN | X5: Yes | Y5: 2 | AA5: Next-gen | AB5: 2 | AC5: 2 | AD5: 3 | AE5: 3 | AF5: 2 | AG5: 4 | AH5: 22 | AI5: None | AJ5: Clean | AK5: None | AL5: None | AM5: 2 | AN5: Prototyped | AO5: 2 | AP5: 2
A6: P-004 | B6: Solid-state electrolyte composition for EV batteries | C6: Battery materials | D6: Solid-state, ionics | E6: Hardware | F6: Battery cell | G6: EV propulsion | H6: 0 | J6: 0 | K6: Apparatus | L6: 3 | M6: 4 | N6: 3 | O6: 0 | P6: 3 | Q6: 2 | R6: 6 | S6: Granted | T6: Yes | U6: 17 | V6: Active | W6: US, EP, CN, JP, KR | X6: Yes | Y6: 3 | AA6: Next-gen | AB6: 2 | AC6: 3 | AD6: 3 | AE6: 3 | AF6: 3 | AG6: 35 | AH6: 48 | AI6: None | AJ6: Clean | AK6: Partial | AL6: None | AM6: 2 | AN6: Prototyped | AO6: 3 | AP6: 3
A7: P-005 | B7: Battery thermal management with phase-change material | C7: Thermal mgmt | D7: BMS, materials | E7: Hardware | F7: Battery pack | G7: EV propulsion | H7: 0 | J7: 1 | K7: System | L7: 2 | M7: 3 | N7: 2 | O7: 1 | P7: 3 | Q7: 2 | R7: 3 | S7: Granted | T7: No | U7: 11 | V7: Active | W7: US, EP, CN | X7: Yes | Y7: 2 | AA7: Current | AB7: 2 | AC7: 2 | AD7: 2 | AE7: 2 | AF7: 3 | AG7: 14 | AH7: 27 | AI7: None | AJ7: Clean | AK7: None | AL7: Non-exclusive licensed | AM7: 2 | AN7: Productized | AO7: 2 | AP7: 2
A8: P-006 | B8: SiC MOSFET inverter control method | C8: Power electronics | D8: Wide-bandgap | E8: Firmware | F8: Traction inverter | G8: EV propulsion | H8: 0 | J8: 1 | K8: Method | L8: 2 | M8: 2 | N8: 2 | O8: 1 | P8: 3 | Q8: 3 | R8: 4 | S8: Granted | T8: No | U8: 12 | V8: Active | W8: US, EP, CN, JP | X8: Yes | Y8: 3 | AA8: Current | AB8: 2 | AC8: 2 | AD8: 2 | AE8: 2 | AF8: 3 | AG8: 16 | AH8: 33 | AI8: None | AJ8: Minor gaps | AK8: Partial | AL8: None | AM8: 3 | AN8: Productized | AO8: 2 | AP8: 2
A9: P-007 | B9: On-device CNN quantization for low-power inference | C9: CV algorithm | D9: Edge AI, ML | E9: App | F9: Vision pipeline | G9: Smart cameras | H9: 0 | J9: 0 | K9: CRM | L9: 2 | M9: 3 | N9: 2 | O9: 2 | P9: 1 | Q9: 2 | R9: 5 | S9: Granted | T9: Yes | U9: 15 | V9: Active | W9: US, EP, CN | X9: Yes | Y9: 2 | Z9: Edge AI | AA9: Current | AB9: 3 | AC9: 2 | AD9: 1 | AE9: 2 | AF9: 2 | AG9: 47 | AH9: 26 | AI9: Pending | AJ9: Clean | AK9: Partial | AL9: None | AM9: 2 | AN9: Productized | AO9: 3 | AP9: 2
A10: P-008 | B10: Transformer attention pruning for vision models | C10: CV algorithm | D10: AI optimization | E10: App | F10: Inference engine | G10: Visual analytics | H10: 0 | J10: 0 | K10: Method | L10: 1 | M10: 2 | N10: 1 | O10: 2 | P10: 0 | Q10: 2 | R10: 3 | S10: Pending | T10: Yes | U10: 19 | V10: Active | W10: US, EP | X10: No | Y10: 1 | Z10: Edge AI, AI+health | AA10: Next-gen | AB10: 3 | AC10: 1 | AD10: 1 | AE10: 1 | AF10: 1 | AG10: 8 | AH10: 19 | AI10: None | AJ10: Clean | AK10: None | AL10: None | AM10: 1 | AN10: Idea-only | AO10: 3 | AP10: 1
A11: P-009 | B11: Visual SLAM for indoor robot navigation | C11: Robotics SW | D11: SLAM, CV | E11: Middleware | F11: Navigation stack | G11: Indoor positioning | H11: 0 | J11: 1 | K11: System | L11: 2 | M11: 2 | N11: 2 | O11: 2 | P11: 1 | Q11: 2 | R11: 4 | S11: Granted | T11: No | U11: 10 | V11: Active | W11: US, EP, JP | X11: Yes | Y11: 2 | Z11: Robotics, edge AI | AA11: Current | AB11: 3 | AC11: 2 | AD11: 2 | AE11: 2 | AF11: 2 | AG11: 22 | AH11: 34 | AI11: None | AJ11: Clean | AK11: Partial | AL11: None | AM11: 2 | AN11: Prototyped | AO11: 2 | AP11: 2
A12: P-010 | B12: USB-C power delivery handshake extension | C12: Interconnect | D12: Power delivery | E12: Firmware | F12: Charging interface | G12: Universal charging | H12: 2 | I12: USB PD 3.x | J12: 3 | K12: Method | L12: 1 | M12: 2 | N12: 2 | O12: 3 | P12: 3 | Q12: 3 | R12: 5 | S12: Granted | T12: No | U12: 9 | V12: Active | W12: US, EP, CN, JP, KR | X12: Yes | Y12: 3 | AA12: Current | AB12: 3 | AC12: 2 | AD12: 3 | AE12: 2 | AF12: 3 | AG12: 25 | AH12: 39 | AI12: Survived | AJ12: Clean | AK12: Full | AL12: None | AM12: 3 | AN12: Productized | AO12: 2 | AP12: 2
A13: P-011 | B13: Atomic layer deposition recipe for high-k dielectric | C13: Semiconductor process | D13: ALD, fab | E13: Hardware | F13: Front-end-of-line | G13: IC manufacturing | H13: 0 | J13: 1 | K13: Method | L13: 2 | M13: 3 | N13: 3 | O13: 0 | P13: 1 | Q13: 1 | R13: 6 | S13: Granted | T13: Yes | U13: 13 | V13: Active | W13: US, EP, CN, JP, KR, TW | X13: Yes | Y13: 3 | AA13: Current | AB13: 1 | AC13: 3 | AD13: 2 | AE13: 3 | AF13: 3 | AG13: 19 | AH13: 41 | AI13: None | AJ13: Clean | AK13: None | AL13: None | AM13: 1 | AN13: Productized | AO13: 1 | AP13: 3
A14: P-012 | B14: Predictive maintenance ML for industrial pumps | C14: Industrial AI | D14: Predictive analytics | E14: Cloud | F14: Asset monitoring | G14: Predictive maintenance | H14: 0 | J14: 1 | K14: CRM | L14: 1 | M14: 2 | N14: 1 | O14: 2 | P14: 0 | Q14: 1 | R14: 2 | S14: Granted | T14: No | U14: 8 | V14: Active | W14: US, EP | X14: No | Y14: 1 | Z14: AI+industrial | AA14: Current | AB14: 3 | AC14: 1 | AD14: 1 | AE14: 2 | AF14: 1 | AG14: 5 | AH14: 12 | AI14: None | AJ14: Minor gaps | AK14: None | AL14: None | AM14: 1 | AN14: Idea-only | AO14: 2 | AP14: 1

Sheet Bundle Rules
A1: # | B1: Bundle Type | C1: Value Proposition | D1: Routing Rule (technical qualification) | E1: Primary attributes used
A2: 1 | B2: Technology Domain | C2: Concentrated coverage in one technical field; useful for entering or fortifying a domain position. | D2: Patents share the same A1 (primary domain) tag. | E2: A1
A3: 2 | B3: Standard-Essential (SEP) | C3: Bundle of assets every implementer of the standard must license or design around. | D3: B1 ≥ 2 AND share same B2 standard. | E3: B1, B2
A4: 3 | B4: Product Architecture | C4: "Build a product" kit — full vertical coverage across subsystems of one end-product. | D4: Collectively span ≥ 3 distinct A4 subsystems of one product family. | E4: A4
A5: 4 | B5: Stack Layer | C5: Targets buyers operating at a specific layer of the technology stack. | D5: Patents share the same A3 (stack layer). | E5: A3
A6: 5 | B6: Use-Case / Application | C6: All tools to address one customer problem, even if underlying tech is heterogeneous. | D6: Patents share at least one A5 (use-case) tag. | E6: A5
A7: 6 | B7: Manufacturing / Process | C7: Targets fabs, contract manufacturers, equipment makers needing freedom to operate on production methods. | D7: A1 is a "process" / manufacturing domain (e.g., contains "process" or "fab") AND C1 = Method. | E7: A1, C1
A8: 7 | B8: Materials & Chemistry | C8: Focused IP shield around composition, synthesis, and use of a material system. | D8: A1 is a materials/chemistry domain AND C1 ∈ {Apparatus, Method}. | E8: A1, C1
A9: 8 | B9: Algorithm / Software Method | C9: Implementation-agnostic methods deployable across many products. | D9: A3 ∈ {App, Middleware, Cloud} AND C1 ∈ {Method, CRM}. | E9: A3, C1
A10: 9 | B10: Interoperability / Interface | C10: Critical chokepoints for any player whose product must talk to others. | D10: B3 ≥ 2. | E10: B3
A11: 10 | B11: Generational Roadmap | C11: Buyer picks legacy (cheap defensive) or next-gen (forward-looking offensive). | D11: Group by G2 (Legacy / Current / Next-gen). | E11: G2
A12: 11 | B12: Claim-Type | C12: Different enforcement profiles; buyers pick by litigation/licensing strategy. | D12: Group by C1. | E12: C1
A13: 12 | B13: Detectability | C13: Litigation-ready bundle — infringement is easy to spot. | D13: D1 ≥ 2 OR D2 ≥ 2. | E13: D1, D2
... A34: 33 | B34: Provenance-Coherent | C34: Patents originating from the same R&D program, inventor group, or acquired sub-business. Shared specifications and consistent terminology reduce claim-construction risk. | D34: Patents share A1 AND share A4 (proxy for common provenance in this template). | E34: A1, A4

Sheet Bundle Assignment
A1: Patent | C1: Bundle Qualification (TRUE = patent qualifies for this bundle) | AJ1: Total
A2: Patent ID | B2: Title | C2: B1 Tech Domain | D2: B2 SEP | E2: B3 Product Arch | F2: B4 Stack Layer | G2: B5 Use-Case | H2: B6 Mfg/Process | I2: B7 Materials | J2: B8 Algorithm | K2: B9 Interop | L2: B10 Generational | M2: B11 Claim-Type | N2: B12 Detectable | O2: B13 Geographic | P2: B14 Family | Q2: B15 Lifecycle | R2: B16 Foundational+Improvement | S2: B17 Cross-Industry | T2: B18 Convergent Theme | U2: B19 Defensive | V2: B20 Whitespace | W2: B21 Prosecution-Status | X2: B22 Anchor+Halo | Y2: B23 Picket-Fence | Z2: B24 Strong+Tail | AA2: B25 Continuation-Live | AB2: B26 EoU-Backed | AC2: B27 Battle-Tested | AD2: B28 Clean-Title | AE2: B29 High-Citation | AF2: B30 Adjacent Re-Read | AG2: B31 Salvage-Volume | AH2: B32 Pre-Expiry | AI2: B33 Provenance | AJ2: # of bundles
A3: ='Patent Portfolio'!A3 -> P-001 | B3: ='Patent Portfolio'!B3 -> Beamforming pilot signaling for 5G NR | C3: =IFERROR(IF('Patent Portfolio'!C3<>"",TRUE(),FALSE()),FALSE()) -> TRUE | D3: =IFERROR(IF(AND(N('Patent Portfolio'!H3)>=2,'Patent Portfolio'!I3<>""),TRUE(),FALSE()),FALSE()) -> TRUE | E3: =IFERROR(IF('Patent Portfolio'!F3<>"",TRUE(),FALSE()),FALSE()) -> TRUE | F3: =IFERROR(IF('Patent Portfolio'!E3<>"",TRUE(),FALSE()),FALSE()) -> TRUE | G3: =IFERROR(IF('Patent Portfolio'!G3<>"",TRUE(),FALSE()),FALSE()) -> TRUE | H3: =IFERROR(IF(AND(OR(ISNUMBER(SEARCH("process",'Patent Portfolio'!C3)),ISNUMBER(SEARCH("fab",'Patent Portfolio'!C3)),ISNUMBER(SEARCH("manufac",'Patent Portfolio'!C3))),'Patent Portfolio'!K3="Method"),TRUE(),FALSE()),FALSE()) -> FALSE | I3: =IFERROR(IF(AND(OR(ISNUMBER(SEARCH("material",'Patent Portfolio'!C3)),ISNUMBER(SEARCH("chem",'Patent Portfolio'!C3)),ISNUMBER(SEARCH("battery",'Patent Portfolio'!C3)),ISNUMBER(SEARCH("electrolyte",'Patent Portfolio'!C3)),ISNUMBER(SEARCH("polymer",'Patent Portfolio'!C3))),OR('Patent Portfolio'!K3="Apparatus",'Patent Portfolio'!K3="Method")),TRUE(),FALSE()),FALSE()) -> FALSE | J3: =IFERROR(IF(AND(OR('Patent Portfolio'!E3="App",'Patent Portfolio'!E3="Middleware",'Patent Portfolio'!E3="Cloud"),OR('Patent Portfolio'!K3="Method",'Patent Portfolio'!K3="CRM")),TRUE(),FALSE()),FALSE()) -> FALSE | K3: =IFERROR(IF(N('Patent Portfolio'!J3)>=2,TRUE(),FALSE()),FALSE()) -> TRUE | L3: =IFERROR(IF('Patent Portfolio'!AA3<>"",TRUE(),FALSE()),FALSE()) -> TRUE | M3: =IFERROR(IF('Patent Portfolio'!K3<>"",TRUE(),FALSE()),FALSE()) -> TRUE | N3: =IFERROR(IF(OR(N('Patent Portfolio'!O3)>=2,N('Patent Portfolio'!P3)>=2),TRUE(),FALSE()),FALSE()) -> TRUE | O3: =IFERROR(IF('Patent Portfolio'!X3="Yes",TRUE(),FALSE()),FALSE()) -> TRUE | P3: =IFERROR(IF(N('Patent Portfolio'!R3)>=2,TRUE(),FALSE()),FALSE()) -> TRUE | Q3: =IFERROR(IF(N('Patent Portfolio'!U3)>0,TRUE(),FALSE()),FALSE()) -> TRUE | R3: =IFERROR(IF(OR(N('Patent Portfolio'!L3)=3,N('Patent Portfolio'!L3)<=1),TRUE(),FALSE()),FALSE()) -> FALSE | S3: =IFERROR(IF(N('Patent Portfolio'!AB3)>=2,TRUE(),FALSE()),FALSE()) -> FALSE | T3: =IFERROR(IF('Patent Portfolio'!Z3<>"",TRUE(),FALSE()),FALSE()) -> FALSE | U3: =IFERROR(IF(N('Patent Portfolio'!Q3)>=2,TRUE(),FALSE()),FALSE()) -> TRUE | V3: =IFERROR(IF(AND(N('Patent Portfolio'!N3)>=2,'Patent Portfolio'!C3<>""),TRUE(),FALSE()),FALSE()) -> TRUE | W3: =IFERROR(IF(OR('Patent Portfolio'!S3="Pending",'Patent Portfolio'!T3="Yes"),TRUE(),FALSE()),FALSE()) -> TRUE | X3: =IFERROR(IF(AND(N('Patent Portfolio'!AC3)>=2,N('Patent Portfolio'!L3)>=1),TRUE(),FALSE()),FALSE()) -> TRUE | Y3: =IFERROR(IF(AND(N('Patent Portfolio'!N3)>=1,OR('Patent Portfolio'!C3<>"",'Patent Portfolio'!I3<>"")),TRUE(),FALSE()),FALSE()) -> TRUE | Z3: =IFERROR(IF('Patent Portfolio'!C3<>"",TRUE(),FALSE()),FALSE()) -> TRUE | AA3: =IFERROR(IF('Patent Portfolio'!T3="Yes",TRUE(),FALSE()),FALSE()) -> TRUE | AB3: =IFERROR(IF(OR('Patent Portfolio'!AK3="Partial",'Patent Portfolio'!AK3="Full"),TRUE(),FALSE()),FALSE()) -> TRUE | AC3: =IFERROR(IF('Patent Portfolio'!AI3="Survived",TRUE(),FALSE()),FALSE()) -> TRUE | AD3: =IFERROR(IF(AND('Patent Portfolio'!AJ3="Clean",'Patent Portfolio'!AL3="None"),TRUE(),FALSE()),FALSE()) -> TRUE | AE3: =IFERROR(IF(N('Patent Portfolio'!AG3)>=15,TRUE(),FALSE()),FALSE()) -> TRUE | AF3: =IFERROR(IF(AND(N('Patent Portfolio'!AO3)>=2,N('Patent Portfolio'!AB3)>=2),TRUE(),FALSE()),FALSE()) -> FALSE | AG3: =IFERROR(IF(OR(N('Patent Portfolio'!AC3)<=1,N('Patent Portfolio'!U3)<5,N('Patent Portfolio'!AD3)<=1),TRUE(),FALSE()),FALSE()) -> FALSE | AH3: =IFERROR(IF(AND(N('Patent Portfolio'!U3)>=1,N('Patent Portfolio'!U3)<=4),TRUE(),FALSE()),FALSE()) -> FALSE | AI3: =IFERROR(IF(AND('Patent Portfolio'!C3<>"",'Patent Portfolio'!F3<>""),TRUE(),FALSE()),FALSE()) -> TRUE | AJ3: =COUNTIF(C3:AI3,TRUE()) -> 24
A4: ='Patent Portfolio'!A4 -> P-002 | B4: ='Patent Portfolio'!B4 -> Polar code decoder architecture | C4: =IFERROR(IF('Patent Portfolio'!C4<>"",TRUE(),FALSE()),FALSE()) -> TRUE | D4: =IFERROR(IF(AND(N('Patent Portfolio'!H4)>=2,'Patent Portfolio'!I4<>""),TRUE(),FALSE()),FALSE()) -> TRUE | E4: =IFERROR(IF('Patent Portfolio'!F4<>"",TRUE(),FALSE()),FALSE()) -> TRUE | F4: =IFERROR(IF('Patent Portfolio'!E4<>"",TRUE(),FALSE()),FALSE()) -> TRUE | G4: =IFERROR(IF('Patent Portfolio'!G4<>"",TRUE(),FALSE()),FALSE()) -> TRUE | H4: =IFERROR(IF(AND(OR(ISNUMBER(SEARCH("process",'Patent Portfolio'!C4)),ISNUMBER(SEARCH("fab",'Patent Portfolio'!C4)),ISNUMBER(SEARCH("manufac",'Patent Portfolio'!C4))),'Patent Portfolio'!K4="Method"),TRUE(),FALSE()),FALSE()) -> FALSE | I4: =IFERROR(IF(AND(OR(ISNUMBER(SEARCH("material",'Patent Portfolio'!C4)),ISNUMBER(SEARCH("chem",'Patent Portfolio'!C4)),ISNUMBER(SEARCH("battery",'Patent Portfolio'!C4)),ISNUMBER(SEARCH("electrolyte",'Patent Portfolio'!C4)),ISNUMBER(SEARCH("polymer",'Patent Portfolio'!C4))),OR('Patent Portfolio'!K4="Apparatus",'Patent Portfolio'!K4="Method")),TRUE(),FALSE()),FALSE()) -> FALSE | J4: =IFERROR(IF(AND(OR('Patent Portfolio'!E4="App",'Patent Portfolio'!E4="Middleware",'Patent Portfolio'!E4="Cloud"),OR('Patent Portfolio'!K4="Method",'Patent Portfolio'!K4="CRM")),TRUE(),FALSE()),FALSE()) -> FALSE | K4: =IFERROR(IF(N('Patent Portfolio'!J4)>=2,TRUE(),FALSE()),FALSE()) -> TRUE | L4: =IFERROR(IF('Patent Portfolio'!AA4<>"",TRUE(),FALSE()),FALSE()) -> TRUE | M4: =IFERROR(IF('Patent Portfolio'!K4<>"",TRUE(),FALSE()),FALSE()) -> TRUE | N4: =IFERROR(IF(OR(N('Patent Portfolio'!O4)>=2,N('Patent Portfolio'!P4)>=2),TRUE(),FALSE()),FALSE()) -> TRUE | O4: =IFERROR(IF('Patent Portfolio'!X4="Yes",TRUE(),FALSE()),FALSE()) -> TRUE | P4: =IFERROR(IF(N('Patent Portfolio'!R4)>=2,TRUE(),FALSE()),FALSE()) -> TRUE | Q4: =IFERROR(IF(N('Patent Portfolio'!U4)>0,TRUE(),FALSE()),FALSE()) -> TRUE | R4: =IFERROR(IF(OR(N('Patent Portfolio'!L4)=3,N('Patent Portfolio'!L4)<=1),TRUE(),FALSE()),FALSE()) -> FALSE | S4: =IFERROR(IF(N('Patent Portfolio'!AB4)>=2,TRUE(),FALSE()),FALSE()) -> FALSE | T4: =IFERROR(IF('Patent Portfolio'!Z4<>"",TRUE(),FALSE()),FALSE()) -> FALSE | U4: =IFERROR(IF(N('Patent Portfolio'!Q4)>=2,TRUE(),FALSE()),FALSE()) -> TRUE | V4: =IFERROR(IF(AND(N('Patent Portfolio'!N4)>=2,'Patent Portfolio'!C4<>""),TRUE(),FALSE()),FALSE()) -> TRUE | W4: =IFERROR(IF(OR('Patent Portfolio'!S4="Pending",'Patent Portfolio'!T4="Yes"),TRUE(),FALSE()),FALSE()) -> FALSE | X4: =IFERROR(IF(AND(N('Patent Portfolio'!AC4)>=2,N('Patent Portfolio'!L4)>=1),TRUE(),FALSE()),FALSE()) -> TRUE | Y4: =IFERROR(IF(AND(N('Patent Portfolio'!N4)>=1,OR('Patent Portfolio'!C4<>"",'Patent Portfolio'!I4<>"")),TRUE(),FALSE()),FALSE()) -> TRUE | Z4: =IFERROR(IF('Patent Portfolio'!C4<>"",TRUE(),FALSE()),FALSE()) -> TRUE | AA4: =IFERROR(IF('Patent Portfolio'!T4="Yes",TRUE(),FALSE()),FALSE()) -> FALSE | AB4: =IFERROR(IF(OR('Patent Portfolio'!AK4="Partial",'Patent Portfolio'!AK4="Full"),TRUE(),FALSE()),FALSE()) -> TRUE | AC4: =IFERROR(IF('Patent Portfolio'!AI4="Survived",TRUE(),FALSE()),FALSE()) -> FALSE | AD4: =IFERROR(IF(AND('Patent Portfolio'!AJ4="Clean",'Patent Portfolio'!AL4="None"),TRUE(),FALSE()),FALSE()) -> TRUE | AE4: =IFERROR(IF(N('Patent Portfolio'!AG4)>=15,TRUE(),FALSE()),FALSE()) -> TRUE | AF4: =IFERROR(IF(AND(N('Patent Portfolio'!AO4)>=2,N('Patent Portfolio'!AB4)>=2),TRUE(),FALSE()),FALSE()) -> FALSE | AG4: =IFERROR(IF(OR(N('Patent Portfolio'!AC4)<=1,N('Patent Portfolio'!U4)<5,N('Patent Portfolio'!AD4)<=1),TRUE(),FALSE()),FALSE()) -> FALSE | AH4: =IFERROR(IF(AND(N('Patent Portfolio'!U4)>=1,N('Patent Portfolio'!U4)<=4),TRUE(),FALSE()),FALSE()) -> FALSE | AI4: =IFERROR(IF(AND('Patent Portfolio'!C4<>"",'Patent Portfolio'!F4<>""),TRUE(),FALSE()),FALSE()) -> TRUE | AJ4: =COUNTIF(C4:AI4,TRUE()) -> 21
A5: ='Patent Portfolio'!A5 -> P-003 | B5: ='Patent Portfolio'!B5 -> Adaptive Wi-Fi 7 channel sounding | C5: =IFERROR(IF('Patent Portfolio'!C5<>"",TRUE(),FALSE()),FALSE()) -> TRUE | D5: =IFERROR(IF(AND(N('Patent Portfolio'!H5)>=2,'Patent Portfolio'!I5<>""),TRUE(),FALSE()),FALSE()) -> TRUE | E5: =IFERROR(IF('Patent Portfolio'!F5<>"",TRUE(),FALSE()),FALSE()) -> TRUE | F5: =IFERROR(IF('Patent Portfolio'!E5<>"",TRUE(),FALSE()),FALSE()) -> TRUE | G5: =IFERROR(IF('Patent Portfolio'!G5<>"",TRUE(),FALSE()),FALSE()) -> TRUE | H5: =IFERROR(IF(AND(OR(ISNUMBER(SEARCH("process",'Patent Portfolio'!C5)),ISNUMBER(SEARCH("fab",'Patent Portfolio'!C5)),ISNUMBER(SEARCH("manufac",'Patent Portfolio'!C5))),'Patent Portfolio'!K5="Method"),TRUE(),FALSE()),FALSE()) -> FALSE | I5: =IFERROR(IF(AND(OR(ISNUMBER(SEARCH("material",'Patent Portfolio'!C5)),ISNUMBER(SEARCH("chem",'Patent Portfolio'!C5)),ISNUMBER(SEARCH("battery",'Patent Portfolio'!C5)),ISNUMBER(SEARCH("electrolyte",'Patent Portfolio'!C5)),ISNUMBER(SEARCH("polymer",'Patent Portfolio'!C5))),OR('Patent Portfolio'!K5="Apparatus",'Patent Portfolio'!K5="Method")),TRUE(),FALSE()),FALSE()) -> FALSE | J5: =IFERROR(IF(AND(OR('Patent Portfolio'!E5="App",'Patent Portfolio'!E5="Middleware",'Patent Portfolio'!E5="Cloud"),OR('Patent Portfolio'!K5="Method",'Patent Portfolio'!K5="CRM")),TRUE(),FALSE()),FALSE()) -> FALSE | K5: =IFERROR(IF(N('Patent Portfolio'!J5)>=2,TRUE(),FALSE()),FALSE()) -> TRUE | L5: =IFERROR(IF('Patent Portfolio'!AA5<>"",TRUE(),FALSE()),FALSE()) -> TRUE | M5: =IFERROR(IF('Patent Portfolio'!K5<>"",TRUE(),FALSE()),FALSE()) -> TRUE | N5: =IFERROR(IF(OR(N('Patent Portfolio'!O5)>=2,N('Patent Portfolio'!P5)>=2),TRUE(),FALSE()),FALSE()) -> TRUE | O5: =IFERROR(IF('Patent Portfolio'!X5="Yes",TRUE(),FALSE()),FALSE()) -> TRUE | P5: =IFERROR(IF(N('Patent Portfolio'!R5)>=2,TRUE(),FALSE()),FALSE()) -> TRUE | Q5: =IFERROR(IF(N('Patent Portfolio'!U5)>0,TRUE(),FALSE()),FALSE()) -> TRUE | R5: =IFERROR(IF(OR(N('Patent Portfolio'!L5)=3,N('Patent Portfolio'!L5)<=1),TRUE(),FALSE()),FALSE()) -> TRUE | S5: =IFERROR(IF(N('Patent Portfolio'!AB5)>=2,TRUE(),FALSE()),FALSE()) -> TRUE | T5: =IFERROR(IF('Patent Portfolio'!Z5<>"",TRUE(),FALSE()),FALSE()) -> FALSE | U5: =IFERROR(IF(N('Patent Portfolio'!Q5)>=2,TRUE(),FALSE()),FALSE()) -> TRUE | V5: =IFERROR(IF(AND(N('Patent Portfolio'!N5)>=2,'Patent Portfolio'!C5<>""),TRUE(),FALSE()),FALSE()) -> TRUE | W5: =IFERROR(IF(OR('Patent Portfolio'!S5="Pending",'Patent Portfolio'!T5="Yes"),TRUE(),FALSE()),FALSE()) -> TRUE | X5: =IFERROR(IF(AND(N('Patent Portfolio'!AC5)>=2,N('Patent Portfolio'!L5)>=1),TRUE(),FALSE()),FALSE()) -> TRUE | Y5: =IFERROR(IF(AND(N('Patent Portfolio'!N5)>=1,OR('Patent Portfolio'!C5<>"",'Patent Portfolio'!I5<>"")),TRUE(),FALSE()),FALSE()) -> TRUE | Z5: =IFERROR(IF('Patent Portfolio'!C5<>"",TRUE(),FALSE()),FALSE()) -> TRUE | AA5: =IFERROR(IF('Patent Portfolio'!T5="Yes",TRUE(),FALSE()),FALSE()) -> TRUE | AB5: =IFERROR(IF(OR('Patent Portfolio'!AK5="Partial",'Patent Portfolio'!AK5="Full"),TRUE(),FALSE()),FALSE()) -> FALSE | AC5: =IFERROR(IF('Patent Portfolio'!AI5="Survived",TRUE(),FALSE()),FALSE()) -> FALSE | AD5: =IFERROR(IF(AND('Patent Portfolio'!AJ5="Clean",'Patent Portfolio'!AL5="None"),TRUE(),FALSE()),FALSE()) -> TRUE | AE5: =IFERROR(IF(N('Patent Portfolio'!AG5)>=15,TRUE(),FALSE()),FALSE()) -> FALSE | AF5: =IFERROR(IF(AND(N('Patent Portfolio'!AO5)>=2,N('Patent Portfolio'!AB5)>=2),TRUE(),FALSE()),FALSE()) -> TRUE | AG5: =IFERROR(IF(OR(N('Patent Portfolio'!AC5)<=1,N('Patent Portfolio'!U5)<5,N('Patent Portfolio'!AD5)<=1),TRUE(),FALSE()),FALSE()) -> FALSE | AH5: =IFERROR(IF(AND(N('Patent Portfolio'!U5)>=1,N('Patent Portfolio'!U5)<=4),TRUE(),FALSE()),FALSE()) -> FALSE | AI5: =IFERROR(IF(AND('Patent Portfolio'!C5<>"",'Patent Portfolio'!F5<>""),TRUE(),FALSE()),FALSE()) -> TRUE | AJ5: =COUNTIF(C5:AI5,TRUE()) -> 24
A6: ='Patent Portfolio'!A6 -> P-004 | B6: ='Patent Portfolio'!B6 -> Solid-state electrolyte composition for EV batteries | C6: =IFERROR(IF('Patent Portfolio'!C6<>"",TRUE(),FALSE()),FALSE()) -> TRUE | D6: =IFERROR(IF(AND(N('Patent Portfolio'!H6)>=2,'Patent Portfolio'!I6<>""),TRUE(),FALSE()),FALSE()) -> FALSE | E6: =IFERROR(IF('Patent Portfolio'!F6<>"",TRUE(),FALSE()),FALSE()) -> TRUE | F6: =IFERROR(IF('Patent Portfolio'!E6<>"",TRUE(),FALSE()),FALSE()) -> TRUE | G6: =IFERROR(IF('Patent Portfolio'!G6<>"",TRUE(),FALSE()),FALSE()) -> TRUE | H6: =IFERROR(IF(AND(OR(ISNUMBER(SEARCH("process",'Patent Portfolio'!C6)),ISNUMBER(SEARCH("fab",'Patent Portfolio'!C6)),ISNUMBER(SEARCH("manufac",'Patent Portfolio'!C6))),'Patent Portfolio'!K6="Method"),TRUE(),FALSE()),FALSE()) -> FALSE | I6: =IFERROR(IF(AND(OR(ISNUMBER(SEARCH("material",'Patent Portfolio'!C6)),ISNUMBER(SEARCH("chem",'Patent Portfolio'!C6)),ISNUMBER(SEARCH("battery",'Patent Portfolio'!C6)),ISNUMBER(SEARCH("electrolyte",'Patent Portfolio'!C6)),ISNUMBER(SEARCH("polymer",'Patent Portfolio'!C6))),OR('Patent Portfolio'!K6="Apparatus",'Patent Portfolio'!K6="Method")),TRUE(),FALSE()),FALSE()) -> TRUE | J6: =IFERROR(IF(AND(OR('Patent Portfolio'!E6="App",'Patent Portfolio'!E6="Middleware",'Patent Portfolio'!E6="Cloud"),OR('Patent Portfolio'!K6="Method",'Patent Portfolio'!K6="CRM")),TRUE(),FALSE()),FALSE()) -> FALSE | K6: =IFERROR(IF(N('Patent Portfolio'!J6)>=2,TRUE(),FALSE()),FALSE()) -> FALSE | L6: =IFERROR(IF('Patent Portfolio'!AA6<>"",TRUE(),FALSE()),FALSE()) -> TRUE | M6: =IFERROR(IF('Patent Portfolio'!K6<>"",TRUE(),FALSE()),FALSE()) -> TRUE | N6: =IFERROR(IF(OR(N('Patent Portfolio'!O6)>=2,N('Patent Portfolio'!P6)>=2),TRUE(),FALSE()),FALSE()) -> TRUE | O6: =IFERROR(IF('Patent Portfolio'!X6="Yes",TRUE(),FALSE()),FALSE()) -> TRUE | P6: =IFERROR(IF(N('Patent Portfolio'!R6)>=2,TRUE(),FALSE()),FALSE()) -> TRUE | Q6: =IFERROR(IF(N('Patent Portfolio'!U6)>0,TRUE(),FALSE()),FALSE()) -> TRUE | R6: =IFERROR(IF(OR(N('Patent Portfolio'!L6)=3,N('Patent Portfolio'!L6)<=1),TRUE(),FALSE()),FALSE()) -> TRUE | S6: =IFERROR(IF(N('Patent Portfolio'!AB6)>=2,TRUE(),FALSE()),FALSE()) -> TRUE | T6: =IFERROR(IF('Patent Portfolio'!Z6<>"",TRUE(),FALSE()),FALSE()) -> FALSE | U6: =IFERROR(IF(N('Patent Portfolio'!Q6)>=2,TRUE(),FALSE()),FALSE()) -> TRUE | V6: =IFERROR(IF(AND(N('Patent Portfolio'!N6)>=2,'Patent Portfolio'!C6<>""),TRUE(),FALSE()),FALSE()) -> TRUE | W6: =IFERROR(IF(OR('Patent Portfolio'!S6="Pending",'Patent Portfolio'!T6="Yes"),TRUE(),FALSE()),FALSE()) -> TRUE | X6: =IFERROR(IF(AND(N('Patent Portfolio'!AC6)>=2,N('Patent Portfolio'!L6)>=1),TRUE(),FALSE()),FALSE()) -> TRUE | Y6: =IFERROR(IF(AND(N('Patent Portfolio'!N6)>=1,OR('Patent Portfolio'!C6<>"",'Patent Portfolio'!I6<>"")),TRUE(),FALSE()),FALSE()) -> TRUE | Z6: =IFERROR(IF('Patent Portfolio'!C6<>"",TRUE(),FALSE()),FALSE()) -> TRUE | AA6: =IFERROR(IF('Patent Portfolio'!T6="Yes",TRUE(),FALSE()),FALSE()) -> TRUE | AB6: =IFERROR(IF(OR('Patent Portfolio'!AK6="Partial",'Patent Portfolio'!AK6="Full"),TRUE(),FALSE()),FALSE()) -> TRUE | AC6: =IFERROR(IF('Patent Portfolio'!AI6="Survived",TRUE(),FALSE()),FALSE()) -> FALSE | AD6: =IFERROR(IF(AND('Patent Portfolio'!AJ6="Clean",'Patent Portfolio'!AL6="None"),TRUE(),FALSE()),FALSE()) -> TRUE | AE6: =IFERROR(IF(N('Patent Portfolio'!AG6)>=15,TRUE(),FALSE()),FALSE()) -> TRUE | AF6: =IFERROR(IF(AND(N('Patent Portfolio'!AO6)>=2,N('Patent Portfolio'!AB6)>=2),TRUE(),FALSE()),FALSE()) -> TRUE | AG6: =IFERROR(IF(OR(N('Patent Portfolio'!AC6)<=1,N('Patent Portfolio'!U6)<5,N('Patent Portfolio'!AD6)<=1),TRUE(),FALSE()),FALSE()) -> FALSE | AH6: =IFERROR(IF(AND(N('Patent Portfolio'!U6)>=1,N('Patent Portfolio'!U6)<=4),TRUE(),FALSE()),FALSE()) -> FALSE | AI6: =IFERROR(IF(AND('Patent Portfolio'!C6<>"",'Patent Portfolio'!F6<>""),TRUE(),FALSE()),FALSE()) -> TRUE | AJ6: =COUNTIF(C6:AI6,TRUE()) -> 25
A7: ='Patent Portfolio'!A7 -> P-005 | B7: ='Patent Portfolio'!B7 -> Battery thermal management with phase-change material | C7: =IFERROR(IF('Patent Portfolio'!C7<>"",TRUE(),FALSE()),FALSE()) -> TRUE | D7: =IFERROR(IF(AND(N('Patent Portfolio'!H7)>=2,'Patent Portfolio'!I7<>""),TRUE(),FALSE()),FALSE()) -> FALSE | E7: =IFERROR(IF('Patent Portfolio'!F7<>"",TRUE(),FALSE()),FALSE()) -> TRUE | F7: =IFERROR(IF('Patent Portfolio'!E7<>"",TRUE(),FALSE()),FALSE()) -> TRUE | G7: =IFERROR(IF('Patent Portfolio'!G7<>"",TRUE(),FALSE()),FALSE()) -> TRUE | H7: =IFERROR(IF(AND(OR(ISNUMBER(SEARCH("process",'Patent Portfolio'!C7)),ISNUMBER(SEARCH("fab",'Patent Portfolio'!C7)),ISNUMBER(SEARCH("manufac",'Patent Portfolio'!C7))),'Patent Portfolio'!K7="Method"),TRUE(),FALSE()),FALSE()) -> FALSE | I7: =IFERROR(IF(AND(OR(ISNUMBER(SEARCH("material",'Patent Portfolio'!C7)),ISNUMBER(SEARCH("chem",'Patent Portfolio'!C7)),ISNUMBER(SEARCH("battery",'Patent Portfolio'!C7)),ISNUMBER(SEARCH("electrolyte",'Patent Portfolio'!C7)),ISNUMBER(SEARCH("polymer",'Patent Portfolio'!C7))),OR('Patent Portfolio'!K7="Apparatus",'Patent Portfolio'!K7="Method")),TRUE(),FALSE()),FALSE()) -> FALSE | J7: =IFERROR(IF(AND(OR('Patent Portfolio'!E7="App",'Patent Portfolio'!E7="Middleware",'Patent Portfolio'!E7="Cloud"),OR('Patent Portfolio'!K7="Method",'Patent Portfolio'!K7="CRM")),TRUE(),FALSE()),FALSE()) -> FALSE | K7: =IFERROR(IF(N('Patent Portfolio'!J7)>=2,TRUE(),FALSE()),FALSE()) -> FALSE | L7: =IFERROR(IF('Patent Portfolio'!AA7<>"",TRUE(),FALSE()),FALSE()) -> TRUE | M7: =IFERROR(IF('Patent Portfolio'!K7<>"",TRUE(),FALSE()),FALSE()) -> TRUE | N7: =IFERROR(IF(OR(N('Patent Portfolio'!O7)>=2,N('Patent Portfolio'!P7)>=2),TRUE(),FALSE()),FALSE()) -> TRUE | O7: =IFERROR(IF('Patent Portfolio'!X7="Yes",TRUE(),FALSE()),FALSE()) -> TRUE | P7: =IFERROR(IF(N('Patent Portfolio'!R7)>=2,TRUE(),FALSE()),FALSE()) -> TRUE | Q7: =IFERROR(IF(N('Patent Portfolio'!U7)>0,TRUE(),FALSE()),FALSE()) -> TRUE | R7: =IFERROR(IF(OR(N('Patent Portfolio'!L7)=3,N('Patent Portfolio'!L7)<=1),TRUE(),FALSE()),FALSE()) -> FALSE | S7: =IFERROR(IF(N('Patent Portfolio'!AB7)>=2,TRUE(),FALSE()),FALSE()) -> TRUE | T7: =IFERROR(IF('Patent Portfolio'!Z7<>"",TRUE(),FALSE()),FALSE()) -> FALSE | U7: =IFERROR(IF(N('Patent Portfolio'!Q7)>=2,TRUE(),FALSE()),FALSE()) -> TRUE | V7: =IFERROR(IF(AND(N('Patent Portfolio'!N7)>=2,'Patent Portfolio'!C7<>""),TRUE(),FALSE()),FALSE()) -> TRUE | W7: =IFERROR(IF(OR('Patent Portfolio'!S7="Pending",'Patent Portfolio'!T7="Yes"),TRUE(),FALSE()),FALSE()) -> FALSE | X7: =IFERROR(IF(AND(N('Patent Portfolio'!AC7)>=2,N('Patent Portfolio'!L7)>=1),TRUE(),FALSE()),FALSE()) -> TRUE | Y7: =IFERROR(IF(AND(N('Patent Portfolio'!N7)>=1,OR('Patent Portfolio'!C7<>"",'Patent Portfolio'!I7<>"")),TRUE(),FALSE()),FALSE()) -> TRUE | Z7: =IFERROR(IF('Patent Portfolio'!C7<>"",TRUE(),FALSE()),FALSE()) -> TRUE | AA7: =IFERROR(IF('Patent Portfolio'!T7="Yes",TRUE(),FALSE()),FALSE()) -> FALSE | AB7: =IFERROR(IF(OR('Patent Portfolio'!AK7="Partial",'Patent Portfolio'!AK7="Full"),TRUE(),FALSE()),FALSE()) -> FALSE | AC7: =IFERROR(IF('Patent Portfolio'!AI7="Survived",TRUE(),FALSE()),FALSE()) -> FALSE | AD7: =IFERROR(IF(AND('Patent Portfolio'!AJ7="Clean",'Patent Portfolio'!AL7="None"),TRUE(),FALSE()),FALSE()) -> FALSE | AE7: =IFERROR(IF(N('Patent Portfolio'!AG7)>=15,TRUE(),FALSE()),FALSE()) -> FALSE | AF7: =IFERROR(IF(AND(N('Patent Portfolio'!AO7)>=2,N('Patent Portfolio'!AB7)>=2),TRUE(),FALSE()),FALSE()) -> TRUE | AG7: =IFERROR(IF(OR(N('Patent Portfolio'!AC7)<=1,N('Patent Portfolio'!U7)<5,N('Patent Portfolio'!AD7)<=1),TRUE(),FALSE()),FALSE()) -> FALSE | AH7: =IFERROR(IF(AND(N('Patent Portfolio'!U7)>=1,N('Patent Portfolio'!U7)<=4),TRUE(),FALSE()),FALSE()) -> FALSE | AI7: =IFERROR(IF(AND('Patent Portfolio'!C7<>"",'Patent Portfolio'!F7<>""),TRUE(),FALSE()),FALSE()) -> TRUE | AJ7: =COUNTIF(C7:AI7,TRUE()) -> 18
A8: ='Patent Portfolio'!A8 -> P-006 | B8: ='Patent Portfolio'!B8 -> SiC MOSFET inverter control method | C8: =IFERROR(IF('Patent Portfolio'!C8<>"",TRUE(),FALSE()),FALSE()) -> TRUE | D8: =IFERROR(IF(AND(N('Patent Portfolio'!H8)>=2,'Patent Portfolio'!I8<>""),TRUE(),FALSE()),FALSE()) -> FALSE | E8: =IFERROR(IF('Patent Portfolio'!F8<>"",TRUE(),FALSE()),FALSE()) -> TRUE | F8: =IFERROR(IF('Patent Portfolio'!E8<>"",TRUE(),FALSE()),FALSE()) -> TRUE | G8: =IFERROR(IF('Patent Portfolio'!G8<>"",TRUE(),FALSE()),FALSE()) -> TRUE | H8: =IFERROR(IF(AND(OR(ISNUMBER(SEARCH("process",'Patent Portfolio'!C8)),ISNUMBER(SEARCH("fab",'Patent Portfolio'!C8)),ISNUMBER(SEARCH("manufac",'Patent Portfolio'!C8))),'Patent Portfolio'!K8="Method"),TRUE(),FALSE()),FALSE()) -> FALSE | I8: =IFERROR(IF(AND(OR(ISNUMBER(SEARCH("material",'Patent Portfolio'!C8)),ISNUMBER(SEARCH("chem",'Patent Portfolio'!C8)),ISNUMBER(SEARCH("battery",'Patent Portfolio'!C8)),ISNUMBER(SEARCH("electrolyte",'Patent Portfolio'!C8)),ISNUMBER(SEARCH("polymer",'Patent Portfolio'!C8))),OR('Patent Portfolio'!K8="Apparatus",'Patent Portfolio'!K8="Method")),TRUE(),FALSE()),FALSE()) -> FALSE | J8: =IFERROR(IF(AND(OR('Patent Portfolio'!E8="App",'Patent Portfolio'!E8="Middleware",'Patent Portfolio'!E8="Cloud"),OR('Patent Portfolio'!K8="Method",'Patent Portfolio'!K8="CRM")),TRUE(),FALSE()),FALSE()) -> FALSE | K8: =IFERROR(IF(N('Patent Portfolio'!J8)>=2,TRUE(),FALSE()),FALSE()) -> FALSE | L8: =IFERROR(IF('Patent Portfolio'!AA8<>"",TRUE(),FALSE()),FALSE()) -> TRUE | M8: =IFERROR(IF('Patent Portfolio'!K8<>"",TRUE(),FALSE()),FALSE()) -> TRUE | N8: =IFERROR(IF(OR(N('Patent Portfolio'!O8)>=2,N('Patent Portfolio'!P8)>=2),TRUE(),FALSE()),FALSE()) -> TRUE | O8: =IFERROR(IF('Patent Portfolio'!X8="Yes",TRUE(),FALSE()),FALSE()) -> TRUE | P8: =IFERROR(IF(N('Patent Portfolio'!R8)>=2,TRUE(),FALSE()),FALSE()) -> TRUE | Q8: =IFERROR(IF(N('Patent Portfolio'!U8)>0,TRUE(),FALSE()),FALSE()) -> TRUE | R8: =IFERROR(IF(OR(N('Patent Portfolio'!L8)=3,N('Patent Portfolio'!L8)<=1),TRUE(),FALSE()),FALSE()) -> FALSE | S8: =IFERROR(IF(N('Patent Portfolio'!AB8)>=2,TRUE(),FALSE()),FALSE()) -> TRUE | T8: =IFERROR(IF('Patent Portfolio'!Z8<>"",TRUE(),FALSE()),FALSE()) -> FALSE | U8: =IFERROR(IF(N('Patent Portfolio'!Q8)>=2,TRUE(),FALSE()),FALSE()) -> TRUE | V8: =IFERROR(IF(AND(N('Patent Portfolio'!N8)>=2,'Patent Portfolio'!C8<>""),TRUE(),FALSE()),FALSE()) -> TRUE | W8: =IFERROR(IF(OR('Patent Portfolio'!S8="Pending",'Patent Portfolio'!T8="Yes"),TRUE(),FALSE()),FALSE()) -> FALSE | X8: =IFERROR(IF(AND(N('Patent Portfolio'!AC8)>=2,N('Patent Portfolio'!L8)>=1),TRUE(),FALSE()),FALSE()) -> TRUE | Y8: =IFERROR(IF(AND(N('Patent Portfolio'!N8)>=1,OR('Patent Portfolio'!C8<>"",'Patent Portfolio'!I8<>"")),TRUE(),FALSE()),FALSE()) -> TRUE | Z8: =IFERROR(IF('Patent Portfolio'!C8<>"",TRUE(),FALSE()),FALSE()) -> TRUE | AA8: =IFERROR(IF('Patent Portfolio'!T8="Yes",TRUE(),FALSE()),FALSE()) -> FALSE | AB8: =IFERROR(IF(OR('Patent Portfolio'!AK8="Partial",'Patent Portfolio'!AK8="Full"),TRUE(),FALSE()),FALSE()) -> TRUE | AC8: =IFERROR(IF('Patent Portfolio'!AI8="Survived",TRUE(),FALSE()),FALSE()) -> FALSE | AD8: =IFERROR(IF(AND('Patent Portfolio'!AJ8="Clean",'Patent Portfolio'!AL8="None"),TRUE(),FALSE()),FALSE()) -> FALSE | AE8: =IFERROR(IF(N('Patent Portfolio'!AG8)>=15,TRUE(),FALSE()),FALSE()) -> TRUE | AF8: =IFERROR(IF(AND(N('Patent Portfolio'!AO8)>=2,N('Patent Portfolio'!AB8)>=2),TRUE(),FALSE()),FALSE()) -> TRUE | AG8: =IFERROR(IF(OR(N('Patent Portfolio'!AC8)<=1,N('Patent Portfolio'!U8)<5,N('Patent Portfolio'!AD8)<=1),TRUE(),FALSE()),FALSE()) -> FALSE | AH8: =IFERROR(IF(AND(N('Patent Portfolio'!U8)>=1,N('Patent Portfolio'!U8)<=4),TRUE(),FALSE()),FALSE()) -> FALSE | AI8: =IFERROR(IF(AND('Patent Portfolio'!C8<>"",'Patent Portfolio'!F8<>""),TRUE(),FALSE()),FALSE()) -> TRUE | AJ8: =COUNTIF(C8:AI8,TRUE()) -> 20
A9: ='Patent Portfolio'!A9 -> P-007 | B9: ='Patent Portfolio'!B9 -> On-device CNN quantization for low-power inference | C9: =IFERROR(IF('Patent Portfolio'!C9<>"",TRUE(),FALSE()),FALSE()) -> TRUE | D9: =IFERROR(IF(AND(N('Patent Portfolio'!H9)>=2,'Patent Portfolio'!I9<>""),TRUE(),FALSE()),FALSE()) -> FALSE | E9: =IFERROR(IF('Patent Portfolio'!F9<>"",TRUE(),FALSE()),FALSE()) -> TRUE | F9: =IFERROR(IF('Patent Portfolio'!E9<>"",TRUE(),FALSE()),FALSE()) -> TRUE | G9: =IFERROR(IF('Patent Portfolio'!G9<>"",TRUE(),FALSE()),FALSE()) -> TRUE | H9: =IFERROR(IF(AND(OR(ISNUMBER(SEARCH("process",'Patent Portfolio'!C9)),ISNUMBER(SEARCH("fab",'Patent Portfolio'!C9)),ISNUMBER(SEARCH("manufac",'Patent Portfolio'!C9))),'Patent Portfolio'!K9="Method"),TRUE(),FALSE()),FALSE()) -> FALSE | I9: =IFERROR(IF(AND(OR(ISNUMBER(SEARCH("material",'Patent Portfolio'!C9)),ISNUMBER(SEARCH("chem",'Patent Portfolio'!C9)),ISNUMBER(SEARCH("battery",'Patent Portfolio'!C9)),ISNUMBER(SEARCH("electrolyte",'Patent Portfolio'!C9)),ISNUMBER(SEARCH("polymer",'Patent Portfolio'!C9))),OR('Patent Portfolio'!K9="Apparatus",'Patent Portfolio'!K9="Method")),TRUE(),FALSE()),FALSE()) -> FALSE | J9: =IFERROR(IF(AND(OR('Patent Portfolio'!E9="App",'Patent Portfolio'!E9="Middleware",'Patent Portfolio'!E9="Cloud"),OR('Patent Portfolio'!K9="Method",'Patent Portfolio'!K9="CRM")),TRUE(),FALSE()),FALSE()) -> TRUE | K9: =IFERROR(IF(N('Patent Portfolio'!J9)>=2,TRUE(),FALSE()),FALSE()) -> FALSE | L9: =IFERROR(IF('Patent Portfolio'!AA9<>"",TRUE(),FALSE()),FALSE()) -> TRUE | M9: =IFERROR(IF('Patent Portfolio'!K9<>"",TRUE(),FALSE()),FALSE()) -> TRUE | N9: =IFERROR(IF(OR(N('Patent Portfolio'!O9)>=2,N('Patent Portfolio'!P9)>=2),TRUE(),FALSE()),FALSE()) -> TRUE | O9: =IFERROR(IF('Patent Portfolio'!X9="Yes",TRUE(),FALSE()),FALSE()) -> TRUE | P9: =IFERROR(IF(N('Patent Portfolio'!R9)>=2,TRUE(),FALSE()),FALSE()) -> TRUE | Q9: =IFERROR(IF(N('Patent Portfolio'!U9)>0,TRUE(),FALSE()),FALSE()) -> TRUE | R9: =IFERROR(IF(OR(N('Patent Portfolio'!L9)=3,N('Patent Portfolio'!L9)<=1),TRUE(),FALSE()),FALSE()) -> FALSE | S9: =IFERROR(IF(N('Patent Portfolio'!AB9)>=2,TRUE(),FALSE()),FALSE()) -> TRUE | T9: =IFERROR(IF('Patent Portfolio'!Z9<>"",TRUE(),FALSE()),FALSE()) -> TRUE | U9: =IFERROR(IF(N('Patent Portfolio'!Q9)>=2,TRUE(),FALSE()),FALSE()) -> TRUE | V9: =IFERROR(IF(AND(N('Patent Portfolio'!N9)>=2,'Patent Portfolio'!C9<>""),TRUE(),FALSE()),FALSE()) -> TRUE | W9: =IFERROR(IF(OR('Patent Portfolio'!S9="Pending",'Patent Portfolio'!T9="Yes"),TRUE(),FALSE()),FALSE()) -> TRUE | X9: =IFERROR(IF(AND(N('Patent Portfolio'!AC9)>=2,N('Patent Portfolio'!L9)>=1),TRUE(),FALSE()),FALSE()) -> TRUE | Y9: =IFERROR(IF(AND(N('Patent Portfolio'!N9)>=1,OR('Patent Portfolio'!C9<>"",'Patent Portfolio'!I9<>"")),TRUE(),FALSE()),FALSE()) -> TRUE | Z9: =IFERROR(IF('Patent Portfolio'!C9<>"",TRUE(),FALSE()),FALSE()) -> TRUE | AA9: =IFERROR(IF('Patent Portfolio'!T9="Yes",TRUE(),FALSE()),FALSE()) -> TRUE | AB9: =IFERROR(IF(OR('Patent Portfolio'!AK9="Partial",'Patent Portfolio'!AK9="Full"),TRUE(),FALSE()),FALSE()) -> TRUE | AC9: =IFERROR(IF('Patent Portfolio'!AI9="Survived",TRUE(),FALSE()),FALSE()) -> FALSE | AD9: =IFERROR(IF(AND('Patent Portfolio'!AJ9="Clean",'Patent Portfolio'!AL9="None"),TRUE(),FALSE()),FALSE()) -> TRUE | AE9: =IFERROR(IF(N('Patent Portfolio'!AG9)>=15,TRUE(),FALSE()),FALSE()) -> TRUE | AF9: =IFERROR(IF(AND(N('Patent Portfolio'!AO9)>=2,N('Patent Portfolio'!AB9)>=2),TRUE(),FALSE()),FALSE()) -> TRUE | AG9: =IFERROR(IF(OR(N('Patent Portfolio'!AC9)<=1,N('Patent Portfolio'!U9)<5,N('Patent Portfolio'!AD9)<=1),TRUE(),FALSE()),FALSE()) -> TRUE | AH9: =IFERROR(IF(AND(N('Patent Portfolio'!U9)>=1,N('Patent Portfolio'!U9)<=4),TRUE(),FALSE()),FALSE()) -> FALSE | AI9: =IFERROR(IF(AND('Patent Portfolio'!C9<>"",'Patent Portfolio'!F9<>""),TRUE(),FALSE()),FALSE()) -> TRUE | AJ9: =COUNTIF(C9:AI9,TRUE()) -> 26
A10: ='Patent Portfolio'!A10 -> P-008 | B10: ='Patent Portfolio'!B10 -> Transformer attention pruning for vision models | C10: =IFERROR(IF('Patent Portfolio'!C10<>"",TRUE(),FALSE()),FALSE()) -> TRUE | D10: =IFERROR(IF(AND(N('Patent Portfolio'!H10)>=2,'Patent Portfolio'!I10<>""),TRUE(),FALSE()),FALSE()) -> FALSE | E10: =IFERROR(IF('Patent Portfolio'!F10<>"",TRUE(),FALSE()),FALSE()) -> TRUE | F10: =IFERROR(IF('Patent Portfolio'!E10<>"",TRUE(),FALSE()),FALSE()) -> TRUE | G10: =IFERROR(IF('Patent Portfolio'!G10<>"",TRUE(),FALSE()),FALSE()) -> TRUE | H10: =IFERROR(IF(AND(OR(ISNUMBER(SEARCH("process",'Patent Portfolio'!C10)),ISNUMBER(SEARCH("fab",'Patent Portfolio'!C10)),ISNUMBER(SEARCH("manufac",'Patent Portfolio'!C10))),'Patent Portfolio'!K10="Method"),TRUE(),FALSE()),FALSE()) -> FALSE | I10: =IFERROR(IF(AND(OR(ISNUMBER(SEARCH("material",'Patent Portfolio'!C10)),ISNUMBER(SEARCH("chem",'Patent Portfolio'!C10)),ISNUMBER(SEARCH("battery",'Patent Portfolio'!C10)),ISNUMBER(SEARCH("electrolyte",'Patent Portfolio'!C10)),ISNUMBER(SEARCH("polymer",'Patent Portfolio'!C10))),OR('Patent Portfolio'!K10="Apparatus",'Patent Portfolio'!K10="Method")),TRUE(),FALSE()),FALSE()) -> FALSE | J10: =IFERROR(IF(AND(OR('Patent Portfolio'!E10="App",'Patent Portfolio'!E10="Middleware",'Patent Portfolio'!E10="Cloud"),OR('Patent Portfolio'!K10="Method",'Patent Portfolio'!K10="CRM")),TRUE(),FALSE()),FALSE()) -> TRUE | K10: =IFERROR(IF(N('Patent Portfolio'!J10)>=2,TRUE(),FALSE()),FALSE()) -> FALSE | L10: =IFERROR(IF('Patent Portfolio'!AA10<>"",TRUE(),FALSE()),FALSE()) -> TRUE | M10: =IFERROR(IF('Patent Portfolio'!K10<>"",TRUE(),FALSE()),FALSE()) -> TRUE | N10: =IFERROR(IF(OR(N('Patent Portfolio'!O10)>=2,N('Patent Portfolio'!P10)>=2),TRUE(),FALSE()),FALSE()) -> TRUE | O10: =IFERROR(IF('Patent Portfolio'!X10="Yes",TRUE(),FALSE()),FALSE()) -> FALSE | P10: =IFERROR(IF(N('Patent Portfolio'!R10)>=2,TRUE(),FALSE()),FALSE()) -> TRUE | Q10: =IFERROR(IF(N('Patent Portfolio'!U10)>0,TRUE(),FALSE()),FALSE()) -> TRUE | R10: =IFERROR(IF(OR(N('Patent Portfolio'!L10)=3,N('Patent Portfolio'!L10)<=1),TRUE(),FALSE()),FALSE()) -> TRUE | S10: =IFERROR(IF(N('Patent Portfolio'!AB10)>=2,TRUE(),FALSE()),FALSE()) -> TRUE | T10: =IFERROR(IF('Patent Portfolio'!Z10<>"",TRUE(),FALSE()),FALSE()) -> TRUE | U10: =IFERROR(IF(N('Patent Portfolio'!Q10)>=2,TRUE(),FALSE()),FALSE()) -> TRUE | V10: =IFERROR(IF(AND(N('Patent Portfolio'!N10)>=2,'Patent Portfolio'!C10<>""),TRUE(),FALSE()),FALSE()) -> FALSE | W10: =IFERROR(IF(OR('Patent Portfolio'!S10="Pending",'Patent Portfolio'!T10="Yes"),TRUE(),FALSE()),FALSE()) -> TRUE | X10: =IFERROR(IF(AND(N('Patent Portfolio'!AC10)>=2,N('Patent Portfolio'!L10)>=1),TRUE(),FALSE()),FALSE()) -> FALSE | Y10: =IFERROR(IF(AND(N('Patent Portfolio'!N10)>=1,OR('Patent Portfolio'!C10<>"",'Patent Portfolio'!I10<>"")),TRUE(),FALSE()),FALSE()) -> TRUE | Z10: =IFERROR(IF('Patent Portfolio'!C10<>"",TRUE(),FALSE()),FALSE()) -> TRUE | AA10: =IFERROR(IF('Patent Portfolio'!T10="Yes",TRUE(),FALSE()),FALSE()) -> TRUE | AB10: =IFERROR(IF(OR('Patent Portfolio'!AK10="Partial",'Patent Portfolio'!AK10="Full"),TRUE(),FALSE()),FALSE()) -> FALSE | AC10: =IFERROR(IF('Patent Portfolio'!AI10="Survived",TRUE(),FALSE()),FALSE()) -> FALSE | AD10: =IFERROR(IF(AND('Patent Portfolio'!AJ10="Clean",'Patent Portfolio'!AL10="None"),TRUE(),FALSE()),FALSE()) -> TRUE | AE10: =IFERROR(IF(N('Patent Portfolio'!AG10)>=15,TRUE(),FALSE()),FALSE()) -> FALSE | AF10: =IFERROR(IF(AND(N('Patent Portfolio'!AO10)>=2,N('Patent Portfolio'!AB10)>=2),TRUE(),FALSE()),FALSE()) -> TRUE | AG10: =IFERROR(IF(OR(N('Patent Portfolio'!AC10)<=1,N('Patent Portfolio'!U10)<5,N('Patent Portfolio'!AD10)<=1),TRUE(),FALSE()),FALSE()) -> TRUE | AH10: =IFERROR(IF(AND(N('Patent Portfolio'!U10)>=1,N('Patent Portfolio'!U10)<=4),TRUE(),FALSE()),FALSE()) -> FALSE | AI10: =IFERROR(IF(AND('Patent Portfolio'!C10<>"",'Patent Portfolio'!F10<>""),TRUE(),FALSE()),FALSE()) -> TRUE | AJ10: =COUNTIF(C10:AI10,TRUE()) -> 22
A11: ='Patent Portfolio'!A11 -> P-009 | B11: ='Patent Portfolio'!B11 -> Visual SLAM for indoor robot navigation | C11: =IFERROR(IF('Patent Portfolio'!C11<>"",TRUE(),FALSE()),FALSE()) -> TRUE | D11: =IFERROR(IF(AND(N('Patent Portfolio'!H11)>=2,'Patent Portfolio'!I11<>""),TRUE(),FALSE()),FALSE()) -> FALSE | E11: =IFERROR(IF('Patent Portfolio'!F11<>"",TRUE(),FALSE()),FALSE()) -> TRUE | F11: =IFERROR(IF('Patent Portfolio'!E11<>"",TRUE(),FALSE()),FALSE()) -> TRUE | G11: =IFERROR(IF('Patent Portfolio'!G11<>"",TRUE(),FALSE()),FALSE()) -> TRUE | H11: =IFERROR(IF(AND(OR(ISNUMBER(SEARCH("process",'Patent Portfolio'!C11)),ISNUMBER(SEARCH("fab",'Patent Portfolio'!C11)),ISNUMBER(SEARCH("manufac",'Patent Portfolio'!C11))),'Patent Portfolio'!K11="Method"),TRUE(),FALSE()),FALSE()) -> FALSE | I11: =IFERROR(IF(AND(OR(ISNUMBER(SEARCH("material",'Patent Portfolio'!C11)),ISNUMBER(SEARCH("chem",'Patent Portfolio'!C11)),ISNUMBER(SEARCH("battery",'Patent Portfolio'!C11)),ISNUMBER(SEARCH("electrolyte",'Patent Portfolio'!C11)),ISNUMBER(SEARCH("polymer",'Patent Portfolio'!C11))),OR('Patent Portfolio'!K11="Apparatus",'Patent Portfolio'!K11="Method")),TRUE(),FALSE()),FALSE()) -> FALSE | J11: =IFERROR(IF(AND(OR('Patent Portfolio'!E11="App",'Patent Portfolio'!E11="Middleware",'Patent Portfolio'!E11="Cloud"),OR('Patent Portfolio'!K11="Method",'Patent Portfolio'!K11="CRM")),TRUE(),FALSE()),FALSE()) -> FALSE | K11: =IFERROR(IF(N('Patent Portfolio'!J11)>=2,TRUE(),FALSE()),FALSE()) -> FALSE | L11: =IFERROR(IF('Patent Portfolio'!AA11<>"",TRUE(),FALSE()),FALSE()) -> TRUE | M11: =IFERROR(IF('Patent Portfolio'!K11<>"",TRUE(),FALSE()),FALSE()) -> TRUE | N11: =IFERROR(IF(OR(N('Patent Portfolio'!O11)>=2,N('Patent Portfolio'!P11)>=2),TRUE(),FALSE()),FALSE()) -> TRUE | O11: =IFERROR(IF('Patent Portfolio'!X11="Yes",TRUE(),FALSE()),FALSE()) -> TRUE | P11: =IFERROR(IF(N('Patent Portfolio'!R11)>=2,TRUE(),FALSE()),FALSE()) -> TRUE | Q11: =IFERROR(IF(N('Patent Portfolio'!U11)>0,TRUE(),FALSE()),FALSE()) -> TRUE | R11: =IFERROR(IF(OR(N('Patent Portfolio'!L11)=3,N('Patent Portfolio'!L11)<=1),TRUE(),FALSE()),FALSE()) -> FALSE | S11: =IFERROR(IF(N('Patent Portfolio'!AB11)>=2,TRUE(),FALSE()),FALSE()) -> TRUE | T11: =IFERROR(IF('Patent Portfolio'!Z11<>"",TRUE(),FALSE()),FALSE()) -> TRUE | U11: =IFERROR(IF(N('Patent Portfolio'!Q11)>=2,TRUE(),FALSE()),FALSE()) -> TRUE | V11: =IFERROR(IF(AND(N('Patent Portfolio'!N11)>=2,'Patent Portfolio'!C11<>""),TRUE(),FALSE()),FALSE()) -> TRUE | W11: =IFERROR(IF(OR('Patent Portfolio'!S11="Pending",'Patent Portfolio'!T11="Yes"),TRUE(),FALSE()),FALSE()) -> FALSE | X11: =IFERROR(IF(AND(N('Patent Portfolio'!AC11)>=2,N('Patent Portfolio'!L11)>=1),TRUE(),FALSE()),FALSE()) -> TRUE | Y11: =IFERROR(IF(AND(N('Patent Portfolio'!N11)>=1,OR('Patent Portfolio'!C11<>"",'Patent Portfolio'!I11<>"")),TRUE(),FALSE()),FALSE()) -> TRUE | Z11: =IFERROR(IF('Patent Portfolio'!C11<>"",TRUE(),FALSE()),FALSE()) -> TRUE | AA11: =IFERROR(IF('Patent Portfolio'!T11="Yes",TRUE(),FALSE()),FALSE()) -> FALSE | AB11: =IFERROR(IF(OR('Patent Portfolio'!AK11="Partial",'Patent Portfolio'!AK11="Full"),TRUE(),FALSE()),FALSE()) -> TRUE | AC11: =IFERROR(IF('Patent Portfolio'!AI11="Survived",TRUE(),FALSE()),FALSE()) -> FALSE | AD11: =IFERROR(IF(AND('Patent Portfolio'!AJ11="Clean",'Patent Portfolio'!AL11="None"),TRUE(),FALSE()),FALSE()) -> TRUE | AE11: =IFERROR(IF(N('Patent Portfolio'!AG11)>=15,TRUE(),FALSE()),FALSE()) -> TRUE | AF11: =IFERROR(IF(AND(N('Patent Portfolio'!AO11)>=2,N('Patent Portfolio'!AB11)>=2),TRUE(),FALSE()),FALSE()) -> TRUE | AG11: =IFERROR(IF(OR(N('Patent Portfolio'!AC11)<=1,N('Patent Portfolio'!U11)<5,N('Patent Portfolio'!AD11)<=1),TRUE(),FALSE()),FALSE()) -> FALSE | AH11: =IFERROR(IF(AND(N('Patent Portfolio'!U11)>=1,N('Patent Portfolio'!U11)<=4),TRUE(),FALSE()),FALSE()) -> FALSE | AI11: =IFERROR(IF(AND('Patent Portfolio'!C11<>"",'Patent Portfolio'!F11<>""),TRUE(),FALSE()),FALSE()) -> TRUE | AJ11: =COUNTIF(C11:AI11,TRUE()) -> 22
A12: ='Patent Portfolio'!A12 -> P-010 | B12: ='Patent Portfolio'!B12 -> USB-C power delivery handshake extension | C12: =IFERROR(IF('Patent Portfolio'!C12<>"",TRUE(),FALSE()),FALSE()) -> TRUE | D12: =IFERROR(IF(AND(N('Patent Portfolio'!H12)>=2,'Patent Portfolio'!I12<>""),TRUE(),FALSE()),FALSE()) -> TRUE | E12: =IFERROR(IF('Patent Portfolio'!F12<>"",TRUE(),FALSE()),FALSE()) -> TRUE | F12: =IFERROR(IF('Patent Portfolio'!E12<>"",TRUE(),FALSE()),FALSE()) -> TRUE | G12: =IFERROR(IF('Patent Portfolio'!G12<>"",TRUE(),FALSE()),FALSE()) -> TRUE | H12: =IFERROR(IF(AND(OR(ISNUMBER(SEARCH("process",'Patent Portfolio'!C12)),ISNUMBER(SEARCH("fab",'Patent Portfolio'!C12)),ISNUMBER(SEARCH("manufac",'Patent Portfolio'!C12))),'Patent Portfolio'!K12="Method"),TRUE(),FALSE()),FALSE()) -> FALSE | I12: =IFERROR(IF(AND(OR(ISNUMBER(SEARCH("material",'Patent Portfolio'!C12)),ISNUMBER(SEARCH("chem",'Patent Portfolio'!C12)),ISNUMBER(SEARCH("battery",'Patent Portfolio'!C12)),ISNUMBER(SEARCH("electrolyte",'Patent Portfolio'!C12)),ISNUMBER(SEARCH("polymer",'Patent Portfolio'!C12))),OR('Patent Portfolio'!K12="Apparatus",'Patent Portfolio'!K12="Method")),TRUE(),FALSE()),FALSE()) -> FALSE | J12: =IFERROR(IF(AND(OR('Patent Portfolio'!E12="App",'Patent Portfolio'!E12="Middleware",'Patent Portfolio'!E12="Cloud"),OR('Patent Portfolio'!K12="Method",'Patent Portfolio'!K12="CRM")),TRUE(),FALSE()),FALSE()) -> FALSE | K12: =IFERROR(IF(N('Patent Portfolio'!J12)>=2,TRUE(),FALSE()),FALSE()) -> TRUE | L12: =IFERROR(IF('Patent Portfolio'!AA12<>"",TRUE(),FALSE()),FALSE()) -> TRUE | M12: =IFERROR(IF('Patent Portfolio'!K12<>"",TRUE(),FALSE()),FALSE()) -> TRUE | N12: =IFERROR(IF(OR(N('Patent Portfolio'!O12)>=2,N('Patent Portfolio'!P12)>=2),TRUE(),FALSE()),FALSE()) -> TRUE | O12: =IFERROR(IF('Patent Portfolio'!X12="Yes",TRUE(),FALSE()),FALSE()) -> TRUE | P12: =IFERROR(IF(N('Patent Portfolio'!R12)>=2,TRUE(),FALSE()),FALSE()) -> TRUE | Q12: =IFERROR(IF(N('Patent Portfolio'!U12)>0,TRUE(),FALSE()),FALSE()) -> TRUE | R12: =IFERROR(IF(OR(N('Patent Portfolio'!L12)=3,N('Patent Portfolio'!L12)<=1),TRUE(),FALSE()),FALSE()) -> TRUE | S12: =IFERROR(IF(N('Patent Portfolio'!AB12)>=2,TRUE(),FALSE()),FALSE()) -> TRUE | T12: =IFERROR(IF('Patent Portfolio'!Z12<>"",TRUE(),FALSE()),FALSE()) -> FALSE | U12: =IFERROR(IF(N('Patent Portfolio'!Q12)>=2,TRUE(),FALSE()),FALSE()) -> TRUE | V12: =IFERROR(IF(AND(N('Patent Portfolio'!N12)>=2,'Patent Portfolio'!C12<>""),TRUE(),FALSE()),FALSE()) -> TRUE | W12: =IFERROR(IF(OR('Patent Portfolio'!S12="Pending",'Patent Portfolio'!T12="Yes"),TRUE(),FALSE()),FALSE()) -> FALSE | X12: =IFERROR(IF(AND(N('Patent Portfolio'!AC12)>=2,N('Patent Portfolio'!L12)>=1),TRUE(),FALSE()),FALSE()) -> TRUE | Y12: =IFERROR(IF(AND(N('Patent Portfolio'!N12)>=1,OR('Patent Portfolio'!C12<>"",'Patent Portfolio'!I12<>"")),TRUE(),FALSE()),FALSE()) -> TRUE | Z12: =IFERROR(IF('Patent Portfolio'!C12<>"",TRUE(),FALSE()),FALSE()) -> TRUE | AA12: =IFERROR(IF('Patent Portfolio'!T12="Yes",TRUE(),FALSE()),FALSE()) -> FALSE | AB12: =IFERROR(IF(OR('Patent Portfolio'!AK12="Partial",'Patent Portfolio'!AK12="Full"),TRUE(),FALSE()),FALSE()) -> TRUE | AC12: =IFERROR(IF('Patent Portfolio'!AI12="Survived",TRUE(),FALSE()),FALSE()) -> TRUE | AD12: =IFERROR(IF(AND('Patent Portfolio'!AJ12="Clean",'Patent Portfolio'!AL12="None"),TRUE(),FALSE()),FALSE()) -> TRUE | AE12: =IFERROR(IF(N('Patent Portfolio'!AG12)>=15,TRUE(),FALSE()),FALSE()) -> TRUE | AF12: =IFERROR(IF(AND(N('Patent Portfolio'!AO12)>=2,N('Patent Portfolio'!AB12)>=2),TRUE(),FALSE()),FALSE()) -> TRUE | AG12: =IFERROR(IF(OR(N('Patent Portfolio'!AC12)<=1,N('Patent Portfolio'!U12)<5,N('Patent Portfolio'!AD12)<=1),TRUE(),FALSE()),FALSE()) -> FALSE | AH12: =IFERROR(IF(AND(N('Patent Portfolio'!U12)>=1,N('Patent Portfolio'!U12)<=4),TRUE(),FALSE()),FALSE()) -> FALSE | AI12: =IFERROR(IF(AND('Patent Portfolio'!C12<>"",'Patent Portfolio'!F12<>""),TRUE(),FALSE()),FALSE()) -> TRUE | AJ12: =COUNTIF(C12:AI12,TRUE()) -> 25
A13: ='Patent Portfolio'!A13 -> P-011 | B13: ='Patent Portfolio'!B13 -> Atomic layer deposition recipe for high-k dielectric | C13: =IFERROR(IF('Patent Portfolio'!C13<>"",TRUE(),FALSE()),FALSE()) -> TRUE | D13: =IFERROR(IF(AND(N('Patent Portfolio'!H13)>=2,'Patent Portfolio'!I13<>""),TRUE(),FALSE()),FALSE()) -> FALSE | E13: =IFERROR(IF('Patent Portfolio'!F13<>"",TRUE(),FALSE()),FALSE()) -> TRUE | F13: =IFERROR(IF('Patent Portfolio'!E13<>"",TRUE(),FALSE()),FALSE()) -> TRUE | G13: =IFERROR(IF('Patent Portfolio'!G13<>"",TRUE(),FALSE()),FALSE()) -> TRUE | H13: =IFERROR(IF(AND(OR(ISNUMBER(SEARCH("process",'Patent Portfolio'!C13)),ISNUMBER(SEARCH("fab",'Patent Portfolio'!C13)),ISNUMBER(SEARCH("manufac",'Patent Portfolio'!C13))),'Patent Portfolio'!K13="Method"),TRUE(),FALSE()),FALSE()) -> TRUE | I13: =IFERROR(IF(AND(OR(ISNUMBER(SEARCH("material",'Patent Portfolio'!C13)),ISNUMBER(SEARCH("chem",'Patent Portfolio'!C13)),ISNUMBER(SEARCH("battery",'Patent Portfolio'!C13)),ISNUMBER(SEARCH("electrolyte",'Patent Portfolio'!C13)),ISNUMBER(SEARCH("polymer",'Patent Portfolio'!C13))),OR('Patent Portfolio'!K13="Apparatus",'Patent Portfolio'!K13="Method")),TRUE(),FALSE()),FALSE()) -> FALSE | J13: =IFERROR(IF(AND(OR('Patent Portfolio'!E13="App",'Patent Portfolio'!E13="Middleware",'Patent Portfolio'!E13="Cloud"),OR('Patent Portfolio'!K13="Method",'Patent Portfolio'!K13="CRM")),TRUE(),FALSE()),FALSE()) -> FALSE | K13: =IFERROR(IF(N('Patent Portfolio'!J13)>=2,TRUE(),FALSE()),FALSE()) -> FALSE | L13: =IFERROR(IF('Patent Portfolio'!AA13<>"",TRUE(),FALSE()),FALSE()) -> TRUE | M13: =IFERROR(IF('Patent Portfolio'!K13<>"",TRUE(),FALSE()),FALSE()) -> TRUE | N13: =IFERROR(IF(OR(N('Patent Portfolio'!O13)>=2,N('Patent Portfolio'!P13)>=2),TRUE(),FALSE()),FALSE()) -> FALSE | O13: =IFERROR(IF('Patent Portfolio'!X13="Yes",TRUE(),FALSE()),FALSE()) -> TRUE | P13: =IFERROR(IF(N('Patent Portfolio'!R13)>=2,TRUE(),FALSE()),FALSE()) -> TRUE | Q13: =IFERROR(IF(N('Patent Portfolio'!U13)>0,TRUE(),FALSE()),FALSE()) -> TRUE | R13: =IFERROR(IF(OR(N('Patent Portfolio'!L13)=3,N('Patent Portfolio'!L13)<=1),TRUE(),FALSE()),FALSE()) -> FALSE | S13: =IFERROR(IF(N('Patent Portfolio'!AB13)>=2,TRUE(),FALSE()),FALSE()) -> FALSE | T13: =IFERROR(IF('Patent Portfolio'!Z13<>"",TRUE(),FALSE()),FALSE()) -> FALSE | U13: =IFERROR(IF(N('Patent Portfolio'!Q13)>=2,TRUE(),FALSE()),FALSE()) -> FALSE | V13: =IFERROR(IF(AND(N('Patent Portfolio'!N13)>=2,'Patent Portfolio'!C13<>""),TRUE(),FALSE()),FALSE()) -> TRUE | W13: =IFERROR(IF(OR('Patent Portfolio'!S13="Pending",'Patent Portfolio'!T13="Yes"),TRUE(),FALSE()),FALSE()) -> TRUE | X13: =IFERROR(IF(AND(N('Patent Portfolio'!AC13)>=2,N('Patent Portfolio'!L13)>=1),TRUE(),FALSE()),FALSE()) -> TRUE | Y13: =IFERROR(IF(AND(N('Patent Portfolio'!N13)>=1,OR('Patent Portfolio'!C13<>"",'Patent Portfolio'!I13<>"")),TRUE(),FALSE()),FALSE()) -> TRUE | Z13: =IFERROR(IF('Patent Portfolio'!C13<>"",TRUE(),FALSE()),FALSE()) -> TRUE | AA13: =IFERROR(IF('Patent Portfolio'!T13="Yes",TRUE(),FALSE()),FALSE()) -> TRUE | AB13: =IFERROR(IF(OR('Patent Portfolio'!AK13="Partial",'Patent Portfolio'!AK13="Full"),TRUE(),FALSE()),FALSE()) -> FALSE | AC13: =IFERROR(IF('Patent Portfolio'!AI13="Survived",TRUE(),FALSE()),FALSE()) -> FALSE | AD13: =IFERROR(IF(AND('Patent Portfolio'!AJ13="Clean",'Patent Portfolio'!AL13="None"),TRUE(),FALSE()),FALSE()) -> TRUE | AE13: =IFERROR(IF(N('Patent Portfolio'!AG13)>=15,TRUE(),FALSE()),FALSE()) -> TRUE | AF13: =IFERROR(IF(AND(N('Patent Portfolio'!AO13)>=2,N('Patent Portfolio'!AB13)>=2),TRUE(),FALSE()),FALSE()) -> FALSE | AG13: =IFERROR(IF(OR(N('Patent Portfolio'!AC13)<=1,N('Patent Portfolio'!U13)<5,N('Patent Portfolio'!AD13)<=1),TRUE(),FALSE()),FALSE()) -> FALSE | AH13: =IFERROR(IF(AND(N('Patent Portfolio'!U13)>=1,N('Patent Portfolio'!U13)<=4),TRUE(),FALSE()),FALSE()) -> FALSE | AI13: =IFERROR(IF(AND('Patent Portfolio'!C13<>"",'Patent Portfolio'!F13<>""),TRUE(),FALSE()),FALSE()) -> TRUE | AJ13: =COUNTIF(C13:AI13,TRUE()) -> 19
